{"type":"depthUpdate","symbol":"BTCUSDT","event_time_ms":1775758308914,"first_update_id":91718176613,"final_update_id":91718176634,"bids":[["71820.25000000","0.00000000"],["71773.62000000","0.02175000"],["71737.50000000","0.00000000"],["71710.22000000","0.02175000"],["64779.92000000","0.00459000"],["64779.91000000","0.00000000"],["57582.00000000","0.00000000"]],"asks":[["71977.69000000","0.43180000"],["71977.70000000","0.00040000"],["71978.94000000","0.00777000"],["71981.06000000","0.00008000"],["71981.07000000","0.03282000"],["71985.07000000","0.11988000"],["71985.91000000","0.16040000"],["71985.93000000","0.01787000"]]}
{"type":"depthUpdate","symbol":"BTCUSDT","event_time_ms":1775758309014,"first_update_id":91718176635,"final_update_id":91718176659,"bids":[["71962.93000000","0.00000000"],["71898.69000000","0.00000000"],["71853.53000000","0.00000000"],["71773.62000000","0.00000000"],["66222.98000000","0.00016000"],["64779.92000000","0.00459000"],["57582.15000000","0.00034000"],["57582.14000000","0.00010000"],["57582.00000000","0.00000000"]],"asks":[["71978.94000000","0.00777000"],["71981.06000000","0.00024000"],["71981.07000000","0.03290000"],["71985.07000000","0.11980000"],["71985.93000000","0.01779000"],["71997.68000000","0.00000000"],["72018.45000000","0.00000000"],["72018.46000000","0.00163000"]]}
{"type":"depthUpdate","symbol":"BTCUSDT","event_time_ms":1775758309114,"first_update_id":91718176660,"final_update_id":91718176670,"bids":[["71855.63000000","0.08195000"],["64779.92000000","0.00425000"],["57582.14000000","0.00000000"]],"asks":[["71977.69000000","0.43188000"],["71977.70000000","0.00048000"],["72018.46000000","0.00000000"]]}
{"type":"depthUpdate","symbol":"BTCUSDT","event_time_ms":1775758309214,"first_update_id":91718176671,"final_update_id":91718176728,"bids":[["71977.68000000","1.25389000"],["71970.48000000","0.00008000"],["71967.60000000","0.00308000"],["71965.21000000","0.11537000"],["71964.72000000","0.00008000"],["71963.93000000","0.00000000"],["71908.90000000","0.02000000"],["71907.82000000","0.02000000"],["71891.31000000","0.00050000"],["64779.92000000","0.00442000"],["57582.15000000","0.00000000"]],"asks":[["71977.69000000","0.19428000"],["71980.08000000","0.00000000"],["71980.53000000","0.00000000"],["71981.07000000","0.00016000"],["71981.08000000","0.00008000"],["71983.13000000","0.09221000"],["71984.89000000","0.00024000"],["71984.90000000","0.08331000"],["71985.07000000","0.00023000"],["71987.77000000","0.00008000"],["71987.87000000","0.00000000"],["71990.65000000","0.00008000"],["71991.98000000","0.00000000"],["71992.88000000","0.07000000"],["71997.36000000","0.00029000"],["71997.68000000","0.10749000"],["72000.06000000","0.00000000"],["72000.41000000","1.66272000"],["72001.98000000","0.00000000"],["72009.73000000","0.02000000"],["72010.45000000","0.02000000"],["72010.46000000","0.02000000"],["72013.24000000","0.02800000"],["72013.60000000","0.02400000"],["72013.96000000","0.02400000"],["72044.65000000","0.02400000"],["72047.06000000","0.50013000"],["72047.80000000","0.05557000"],["72051.34000000","0.02400000"],["72134.55000000","0.20771000"]]}
{"type":"depthUpdate","symbol":"BTCUSDT","event_time_ms":1775758309314,"first_update_id":91718176729,"final_update_id":91718176786,"bids":[["71977.68000000","1.29695000"],["71965.21000000","0.00000000"],["71961.80000000","0.00007000"],["71961.49000000","0.00000000"],["71952.60000000","0.00293000"],["64779.92000000","0.00493000"]],"asks":[["71977.69000000","0.24977000"],["71977.70000000","0.00056000"],["71978.93000000","0.00008000"],["71978.94000000","0.00777000"],["71981.06000000","0.00008000"],["71981.07000000","0.00000000"],["71981.08000000","0.00000000"],["71983.12000000","0.11283000"],["71983.13000000","0.09228000"],["71984.03000000","0.00016000"],["71984.04000000","0.01389000"],["71984.88000000","0.00016000"],["71984.89000000","0.11981000"],["71984.90000000","0.08339000"],["71985.06000000","0.00000000"],["71985.07000000","0.00015000"],["71985.90000000","0.00000000"],["71985.93000000","0.01787000"],["71987.27000000","0.01397000"],["71987.87000000","0.11359000"],["71988.14000000","0.12247000"],["71990.60000000","0.00007000"],["71997.36000000","0.00029000"],["71997.68000000","0.00000000"],["72000.12000000","0.00425000"],["72047.06000000","0.38899000"],["72047.80000000","0.16671000"],["72051.34000000","0.00000000"]]}
{"type":"depthUpdate","symbol":"BTCUSDT","event_time_ms":1775758309414,"first_update_id":91718176787,"final_update_id":91718176834,"bids":[["71952.60000000","0.00000000"],["64779.92000000","0.00493000"]],"asks":[["71977.69000000","0.48751000"],["71977.70000000","0.00056000"],["71981.06000000","0.00000000"],["71981.50000000","0.02511000"],["71983.10000000","0.00016000"],["71983.11000000","0.16323000"],["71983.12000000","0.00016000"],["71983.13000000","0.00022000"],["71984.04000000","0.00008000"],["71984.89000000","0.11981000"],["71985.91000000","0.16032000"],["71985.93000000","0.01779000"],["71987.27000000","0.01389000"],["71988.14000000","0.00112000"],["72000.12000000","0.00000000"],["72017.99000000","0.08782000"],["72031.45000000","0.00000000"],["72047.06000000","0.33342000"],["72048.20000000","0.02000000"],["72134.55000000","0.00000000"]]}
{"type":"depthUpdate","symbol":"BTCUSDT","event_time_ms":1775758309514,"first_update_id":91718176835,"final_update_id":91718176867,"bids":[["71962.93000000","0.00008000"],["64779.92000000","0.00476000"],["64779.00000000","0.00019000"],["57582.15000000","0.00034000"]],"asks":[["71977.69000000","0.48735000"],["71977.70000000","0.00040000"],["71981.50000000","0.02511000"],["71983.11000000","0.16331000"],["71983.12000000","0.00008000"],["71983.13000000","0.00014000"],["71984.03000000","0.00000000"],["71984.04000000","0.00000000"],["71984.89000000","0.11989000"],["71985.07000000","0.00023000"],["71985.91000000","0.16040000"],["71985.93000000","0.01787000"],["72047.47000000","0.00000000"],["72047.77000000","0.05557000"],["72048.20000000","0.00000000"],["77500.00000000","25.88138000"]]}
{"type":"depthUpdate","symbol":"BTCUSDT","event_time_ms":1775758309614,"first_update_id":91718176868,"final_update_id":91718176904,"bids":[["71977.68000000","1.23993000"],["71974.96000000","0.00014000"],["71963.28000000","0.01861000"],["71961.60000000","0.11703000"],["71948.88000000","0.03123000"],["66222.98000000","0.00000000"],["64779.92000000","0.00459000"],["64779.00000000","0.00019000"],["57582.15000000","0.00000000"]],"asks":[["71977.69000000","0.58865000"],["71980.02000000","0.00029000"],["71980.94000000","0.00000000"],["71987.31000000","0.00000000"],["71987.77000000","0.11815000"],["71997.36000000","0.11438000"],["71997.68000000","0.00000000"],["71999.75000000","0.13906000"],["72000.47000000","0.00000000"],["72031.77000000","0.10242000"],["72047.06000000","0.27785000"],["72050.98000000","0.00000000"],["72051.71000000","0.00000000"]]}
{"type":"depthUpdate","symbol":"BTCUSDT","event_time_ms":1775758309714,"first_update_id":91718176905,"final_update_id":91718176930,"bids":[["71977.68000000","1.23804000"],["71976.30000000","0.00016000"],["71976.29000000","0.06478000"],["71975.28000000","0.00016000"],["71973.07000000","0.00000000"],["71961.60000000","0.00000000"],["71919.09000000","0.00000000"],["64779.92000000","0.00476000"]],"asks":[["71977.83000000","0.01716000"],["71983.10000000","0.11996000"],["72033.66000000","0.00000000"],["72047.76000000","0.11114000"],["72047.77000000","0.00000000"],["72047.80000000","0.11114000"],["72118.05000000","0.00000000"],["72173.83000000","0.00000000"]]}
{"type":"depthUpdate","symbol":"BTCUSDT","event_time_ms":1775758309814,"first_update_id":91718176931,"final_update_id":91718176981,"bids":[["71974.96000000","0.00007000"],["71967.74000000","0.00192000"],["71952.96000000","0.84138000"],["71931.08000000","1.16745000"],["71899.27000000","0.05557000"],["71879.23000000","0.00000000"],["71855.82000000","0.00076000"],["64779.92000000","0.00476000"]],"asks":[["71977.69000000","0.58896000"],["71977.70000000","0.00056000"],["71977.82000000","0.00024000"],["71977.83000000","0.01724000"],["71981.50000000","0.02511000"],["71983.09000000","0.00016000"],["71983.10000000","0.12004000"],["71984.89000000","0.00016000"],["71985.07000000","0.00015000"],["71985.39000000","0.34728000"],["71985.91000000","0.16032000"],["71985.93000000","0.01779000"],["71987.87000000","0.00000000"],["71989.67000000","0.00000000"],["71997.35000000","1.58498000"],["72007.24000000","1.54087000"],["72007.29000000","0.00000000"],["72047.75000000","0.22228000"],["72047.76000000","0.00000000"],["72047.80000000","0.05557000"],["72070.07000000","1.22696000"],["72070.54000000","0.00000000"],["72076.74000000","0.00000000"],["72105.03000000","0.77027000"],["72106.39000000","0.00000000"],["72155.19000000","0.00000000"]]}
{"type":"depthUpdate","symbol":"BTCUSDT","event_time_ms":1775758309914,"first_update_id":91718176982,"final_update_id":91718177013,"bids":[["71977.68000000","1.19498000"],["71961.28000000","0.14276000"],["71935.78000000","0.01041000"],["71908.70000000","0.00000000"],["64779.92000000","0.00476000"]],"asks":[["71977.69000000","0.52146000"],["71983.11000000","0.16331000"],["71984.88000000","0.00000000"],["71984.89000000","0.00016000"],["71985.08000000","0.20597000"],["71985.39000000","0.34736000"],["71987.51000000","0.00240000"],["71989.25000000","0.11170000"],["71996.82000000","0.11168000"],["71997.34000000","0.11608000"],["71997.36000000","0.00029000"],["72011.14000000","0.00000000"],["72076.73000000","0.00000000"],["72143.10000000","0.00076000"]]}
{"type":"depthUpdate","symbol":"BTCUSDT","event_time_ms":1775758310014,"first_update_id":91718177014,"final_update_id":91718177018,"bids":[["64779.92000000","0.00459000"],["57582.15000000","0.00034000"]],"asks":[["71977.69000000","0.52876000"]]}
{"type":"depthUpdate","symbol":"BTCUSDT","event_time_ms":1775758310114,"first_update_id":91718177019,"final_update_id":91718177047,"bids":[["71963.28000000","0.00300000"],["71948.88000000","0.04684000"],["64779.92000000","0.00476000"],["57582.14000000","0.00000000"]],"asks":[["71977.69000000","0.52939000"],["71977.70000000","0.00064000"],["71980.94000000","0.00008000"],["71983.08000000","0.00016000"],["71983.09000000","0.10230000"],["71984.89000000","0.00008000"],["71986.57000000","0.00000000"],["71987.77000000","0.00008000"],["71998.37000000","0.13033000"],["71999.75000000","0.00000000"],["72012.60000000","0.00300000"],["72014.40000000","0.00000000"],["72047.06000000","0.22228000"],["72047.73000000","0.05557000"]]}
{"type":"depthUpdate","symbol":"BTCUSDT","event_time_ms":1775758310214,"first_update_id":91718177048,"final_update_id":91718177075,"bids":[["71976.29000000","0.09231000"],["71976.28000000","0.08345000"],["71975.29000000","0.00016000"],["71975.28000000","0.11973000"],["71975.27000000","0.00000000"],["71922.93000000","0.04751000"],["71909.70000000","1.66702000"],["64779.92000000","0.00476000"],["57582.15000000","0.00000000"],["57582.14000000","0.00000000"]],"asks":[["71981.50000000","0.02511000"],["71983.09000000","0.10238000"],["71985.39000000","0.34728000"],["72033.67000000","0.04782000"],["72047.73000000","0.05557000"],["72053.66000000","1.66702000"],["72118.06000000","0.00751000"],["72134.62000000","0.21041000"],["72173.84000000","0.01467000"]]}
{"type":"depthUpdate","symbol":"BTCUSDT","event_time_ms":1775758310314,"first_update_id":91718177076,"final_update_id":91718177101,"bids":[["71976.29000000","0.06478000"],["71976.28000000","0.08338000"],["71975.29000000","0.11923000"],["71975.28000000","0.11957000"],["71962.14000000","0.13720000"],["71961.80000000","0.00007000"],["71961.28000000","0.00000000"],["71949.38000000","0.00230000"],["71790.42000000","0.00000000"],["64779.92000000","0.00459000"],["57582.00000000","0.00000000"]],"asks":[["71983.10000000","0.00024000"],["71985.39000000","0.00000000"],["71985.67000000","0.01389000"],["71987.26000000","0.34727000"],["71990.60000000","0.00007000"],["72005.79000000","0.00334000"],["72047.75000000","0.16671000"],["72047.90000000","0.03200000"],["72141.99000000","0.00000000"]]}
{"type":"depthUpdate","symbol":"BTCUSDT","event_time_ms":1775758310414,"first_update_id":91718177102,"final_update_id":91718177140,"bids":[["71977.68000000","1.18993000"],["71976.29000000","0.09179000"],["71976.28000000","0.08345000"],["71975.29000000","0.11907000"],["71967.74000000","0.00000000"],["71801.02000000","0.00000000"],["71798.04000000","0.00825000"],["64779.92000000","0.00459000"],["64779.91000000","0.00009000"]],"asks":[["71977.69000000","0.57213000"],["71977.70000000","0.00056000"],["71977.82000000","0.00024000"],["71983.09000000","0.10222000"],["71983.10000000","0.00016000"],["71983.11000000","0.08967000"],["71984.89000000","0.00016000"],["71985.08000000","0.20590000"],["71985.67000000","0.01397000"],["71985.91000000","0.16039000"],["71998.37000000","0.00000000"],["72047.06000000","0.27507000"],["72047.74000000","0.05557000"],["72047.75000000","0.00000000"],["73400.00000000","2.37841000"],["79175.46000000","0.00007000"]]}
{"type":"depthUpdate","symbol":"BTCUSDT","event_time_ms":1775758310514,"first_update_id":91718177141,"final_update_id":91718177207,"bids":[["71977.68000000","1.32540000"],["71976.30000000","0.00000000"],["71976.29000000","0.09171000"],["71976.28000000","0.08353000"],["71975.29000000","0.11915000"],["71975.28000000","0.11965000"],["71973.06000000","0.71335000"],["71973.05000000","1.58506000"],["71973.00000000","0.02308000"],["71972.25000000","0.04042000"],["71959.72000000","0.02071000"],["69400.00000000","0.74153000"],["64779.92000000","0.00476000"],["64779.91000000","0.00000000"],["57582.15000000","0.00034000"]],"asks":[["71977.69000000","0.71196000"],["71977.70000000","0.00056000"],["71983.09000000","0.00008000"],["71986.91000000","0.00068000"],["71994.57000000","0.10357000"],["72047.06000000","0.32786000"],["72047.74000000","0.05557000"],["72047.80000000","0.00000000"],["79175.46000000","0.00000000"]]}
{"type":"depthUpdate","symbol":"BTCUSDT","event_time_ms":1775758310614,"first_update_id":91718177208,"final_update_id":91718177258,"bids":[["71977.68000000","1.18929000"],["71964.00000000","0.12374000"],["71963.08000000","0.00000000"],["71962.14000000","0.00000000"],["71959.72000000","0.00000000"],["71959.67000000","0.00920000"],["71949.38000000","0.00000000"],["71801.61000000","6.32670000"],["64779.92000000","0.00476000"],["57582.15000000","0.00000000"]],"asks":[["71977.69000000","0.32853000"],["71979.38000000","0.00024000"],["71980.02000000","0.00000000"],["71981.50000000","0.02511000"],["71983.08000000","0.00000000"],["71983.09000000","0.00000000"],["71984.89000000","0.00024000"],["71985.07000000","0.00023000"],["71985.91000000","0.25090000"],["71987.25000000","0.00000000"],["71987.26000000","0.00000000"],["71988.67000000","0.34726000"],["71992.98000000","0.12382000"],["71994.57000000","0.00000000"],["71996.82000000","0.00008000"],["71997.34000000","0.00000000"],["72001.95000000","0.12768000"],["72005.79000000","0.00000000"],["72047.06000000","0.22228000"],["72047.73000000","0.11114000"],["72047.74000000","0.00000000"],["72147.55000000","6.54798000"]]}
{"type":"depthUpdate","symbol":"BTCUSDT","event_time_ms":1775758310714,"first_update_id":91718177259,"final_update_id":91718177300,"bids":[["71977.68000000","1.26527000"],["71968.24000000","0.01389000"],["71966.44000000","0.06947000"],["71963.28000000","0.01861000"],["71962.93000000","0.00000000"],["71961.41000000","0.00000000"],["71959.67000000","0.00000000"],["71959.61000000","0.00000000"],["71948.88000000","0.03123000"],["71946.43000000","0.92564000"],["71939.82000000","0.00000000"],["64779.92000000","0.00442000"],["64779.00000000","0.00019000"]],"asks":[["71980.94000000","0.00000000"],["71984.88000000","0.00016000"],["71984.89000000","0.11981000"],["71985.07000000","0.00015000"],["71985.67000000","0.00008000"],["71985.91000000","0.25076000"],["71986.92000000","0.00047000"],["71988.14000000","0.11966000"],["71997.34000000","0.85875000"],["71997.69000000","0.00000000"],["72047.06000000","0.16671000"],["72047.73000000","0.22228000"]]}
{"type":"depthUpdate","symbol":"BTCUSDT","event_time_ms":1775758310814,"first_update_id":91718177301,"final_update_id":91718177333,"bids":[["71977.68000000","1.34267000"],["64779.92000000","0.00442000"],["43419.81000000","0.00000000"],["43386.00000000","0.00140000"],["43363.43000000","0.00000000"],["43362.75000000","0.00000000"],["43352.51000000","0.00000000"],["43336.23000000","0.00000000"],["43313.99000000","0.00000000"],["43287.16000000","0.00014000"],["43285.98000000","0.00000000"],["43273.44000000","0.00000000"],["43272.35000000","0.00000000"],["43251.23000000","0.00000000"],["43148.98000000","0.00014000"],["43133.87000000","0.00028000"],["43109.80000000","0.00014000"]],"asks":[["71977.69000000","0.32845000"],["71977.70000000","0.00048000"],["71983.11000000","0.08967000"],["71984.89000000","0.11989000"],["71985.08000000","0.20590000"],["71985.67000000","0.00000000"],["71988.14000000","0.00112000"],["72047.06000000","0.11114000"],["72047.73000000","0.16671000"],["79175.46000000","0.00007000"]]}
{"type":"depthUpdate","symbol":"BTCUSDT","event_time_ms":1775758310914,"first_update_id":91718177334,"final_update_id":91718177352,"bids":[["71941.50000000","1.15607000"],["64779.92000000","0.00442000"]],"asks":[["72003.64000000","1.09282000"],["72047.73000000","0.27090000"],["72051.15000000","0.05557000"],["72051.98000000","1.00038000"],["72076.75000000","0.79390000"],["72113.91000000","0.03956000"],["79175.46000000","0.00000000"]]}
{"type":"depthUpdate","symbol":"BTCUSDT","event_time_ms":1775758311014,"first_update_id":91718177353,"final_update_id":91718177360,"bids":[["64779.92000000","0.00459000"],["57582.15000000","0.00034000"]],"asks":[["72047.73000000","0.16532000"]]}
{"type":"depthUpdate","symbol":"BTCUSDT","event_time_ms":1775758311114,"first_update_id":91718177361,"final_update_id":91718177372,"bids":[["71977.68000000","1.34228000"],["64779.92000000","0.00459000"],["64779.00000000","0.00019000"],["57582.14000000","0.00000000"]],"asks":[["72013.28000000","0.00000000"],["72020.48000000","0.00000000"],["72047.73000000","0.11114000"]]}
{"type":"depthUpdate","symbol":"BTCUSDT","event_time_ms":1775758311214,"first_update_id":91718177373,"final_update_id":91718177390,"bids":[["71963.28000000","0.04984000"],["71948.88000000","0.00000000"],["71801.62000000","0.00825000"],["71798.04000000","0.00000000"],["64779.92000000","0.00459000"],["57582.15000000","0.00000000"],["57582.14000000","0.00000000"]],"asks":[["72004.60000000","0.00400000"],["72011.80000000","0.00400000"],["72047.73000000","0.27229000"],["73284.25000000","0.00000000"]]}
{"type":"depthUpdate","symbol":"BTCUSDT","event_time_ms":1775758311314,"first_update_id":91718177391,"final_update_id":91718177401,"bids":[["71961.80000000","0.00007000"],["71950.85000000","0.00258000"],["64779.92000000","0.00459000"]],"asks":[["71990.60000000","0.00007000"],["72002.60000000","0.00389000"]]}
{"type":"depthUpdate","symbol":"BTCUSDT","event_time_ms":1775758311414,"first_update_id":91718177402,"final_update_id":91718177411,"bids":[["64779.92000000","0.00442000"]],"asks":[["72047.72000000","0.05564000"],["72047.73000000","0.16393000"],["72081.89000000","0.02175000"],["72089.90000000","0.00000000"]]}
{"type":"depthUpdate","symbol":"BTCUSDT","event_time_ms":1775758311514,"first_update_id":91718177412,"final_update_id":91718177443,"bids":[["71977.68000000","1.30936000"],["71963.28000000","0.01861000"],["71948.88000000","0.03123000"],["71000.00000000","15.79274000"],["64779.92000000","0.00442000"],["57582.15000000","0.00034000"]],"asks":[["71977.69000000","0.32853000"],["71977.70000000","0.00056000"],["71983.11000000","0.14821000"],["71983.98000000","0.00016000"],["71983.99000000","0.11440000"],["71984.89000000","0.11973000"],["71986.92000000","0.00000000"],["71988.20000000","0.01389000"],["72000.29000000","0.10078000"],["72001.95000000","0.00000000"],["72047.06000000","0.11114000"],["72047.72000000","0.16261000"],["72047.73000000","0.05557000"],["72051.15000000","0.00000000"],["72081.89000000","0.00000000"]]}
{"type":"depthUpdate","symbol":"BTCUSDT","event_time_ms":1775758311614,"first_update_id":91718177444,"final_update_id":91718177477,"bids":[["71977.68000000","1.23196000"],["71830.11000000","1.01844000"],["71818.36000000","0.00000000"],["64779.92000000","0.00459000"],["57582.15000000","0.00000000"]],"asks":[["71977.69000000","0.32901000"],["71983.11000000","0.14821000"],["71983.99000000","0.11448000"],["71985.91000000","0.25068000"],["71996.84000000","0.49999000"],["71997.34000000","0.74515000"],["71999.53000000","0.11347000"],["72000.29000000","0.00000000"],["72017.54000000","0.00000000"],["72047.06000000","0.16532000"],["72047.72000000","0.15705000"]]}
{"type":"depthUpdate","symbol":"BTCUSDT","event_time_ms":1775758311714,"first_update_id":91718177478,"final_update_id":91718177497,"bids":[["71977.68000000","1.22813000"],["71963.28000000","0.00300000"],["64779.92000000","0.00493000"]],"asks":[["72047.06000000","0.27229000"],["72047.72000000","0.15844000"],["72062.63000000","0.01852000"],["72886.74000000","0.00034000"]]}
{"type":"depthUpdate","symbol":"BTCUSDT","event_time_ms":1775758311814,"first_update_id":91718177498,"final_update_id":91718177514,"bids":[["71977.68000000","1.18507000"],["71963.28000000","0.01861000"],["71948.88000000","0.03123000"],["64779.92000000","0.00442000"],["64779.00000000","0.00019000"],["57582.00000000","0.00000000"]],"asks":[]}
{"type":"depthUpdate","symbol":"BTCUSDT","event_time_ms":1775758311914,"first_update_id":91718177515,"final_update_id":91718177533,"bids":[["71963.28000000","0.00300000"],["71878.30000000","0.00277000"],["71868.40000000","0.00000000"],["64779.92000000","0.00442000"]],"asks":[["71977.69000000","0.32882000"],["71977.70000000","0.00064000"],["71983.11000000","0.14828000"],["71983.97000000","0.00016000"],["71983.98000000","0.11873000"],["71984.88000000","0.00000000"],["72011.80000000","0.98989000"],["72047.72000000","0.21123000"],["72109.26000000","0.03724000"]]}
{"type":"depthUpdate","symbol":"BTCUSDT","event_time_ms":1775758312014,"first_update_id":91718177534,"final_update_id":91718177551,"bids":[["71964.00000000","0.00420000"],["71773.62000000","0.02175000"],["64779.92000000","0.00459000"],["57582.15000000","0.00034000"]],"asks":[["71983.11000000","0.14835000"],["71983.96000000","0.00016000"],["71983.97000000","0.12372000"],["71983.98000000","0.11865000"],["71983.99000000","0.00016000"],["71984.89000000","0.00016000"],["71985.08000000","0.20582000"]]}
{"type":"depthUpdate","symbol":"BTCUSDT","event_time_ms":1775758312114,"first_update_id":91718177552,"final_update_id":91718177584,"bids":[["64779.92000000","0.00476000"],["57582.14000000","0.00000000"]],"asks":[["71977.69000000","0.32874000"],["71977.70000000","0.00056000"],["71983.11000000","0.14842000"],["71983.95000000","0.12272000"],["71983.96000000","0.12322000"],["71983.97000000","0.00008000"],["71983.98000000","0.00008000"],["71983.99000000","0.00008000"],["71984.89000000","0.00008000"],["71985.08000000","0.20590000"],["72047.72000000","0.15844000"],["72047.73000000","0.00000000"],["72417.79000000","0.00232000"]]}
{"type":"depthUpdate","symbol":"BTCUSDT","event_time_ms":1775758312214,"first_update_id":91718177585,"final_update_id":91718177616,"bids":[["71963.28000000","0.01861000"],["71943.92000000","0.00000000"],["71935.28000000","0.00000000"],["71855.63000000","0.00000000"],["64779.92000000","0.00476000"],["57582.15000000","0.00000000"],["57582.14000000","0.00000000"]],"asks":[["71977.69000000","0.32882000"],["71977.70000000","0.00064000"],["71983.11000000","0.14835000"],["71983.94000000","0.12223000"],["71983.95000000","0.12280000"],["71983.96000000","0.12314000"],["71983.97000000","0.00000000"],["71983.98000000","0.00000000"],["71997.70000000","0.00000000"],["72020.21000000","0.00000000"],["73791.99000000","0.00000000"]]}
{"type":"depthUpdate","symbol":"BTCUSDT","event_time_ms":1775758312314,"first_update_id":91718177617,"final_update_id":91718177641,"bids":[["71938.46000000","0.11493000"],["71846.64000000","0.12760000"],["64779.92000000","0.00476000"]],"asks":[["71977.69000000","0.32882000"],["71977.70000000","0.00064000"],["71983.11000000","0.14842000"],["71983.93000000","0.12173000"],["71983.94000000","0.12231000"],["71983.95000000","0.12264000"],["71983.96000000","0.00008000"],["71985.08000000","0.20582000"],["72047.06000000","0.32647000"]]}
{"type":"depthUpdate","symbol":"BTCUSDT","event_time_ms":1775758312415,"first_update_id":91718177642,"final_update_id":91718177676,"bids":[["71962.93000000","0.00008000"],["71961.80000000","0.00007000"],["64779.92000000","0.00459000"]],"asks":[["71977.69000000","0.32882000"],["71977.70000000","0.00064000"],["71983.11000000","0.14849000"],["71983.91000000","0.00016000"],["71983.92000000","0.12123000"],["71983.93000000","0.12165000"],["71983.94000000","0.00008000"],["71983.95000000","0.00008000"],["71983.96000000","0.00000000"],["71990.60000000","0.00007000"],["72047.06000000","0.37926000"],["72047.72000000","0.10565000"]]}
{"type":"depthUpdate","symbol":"BTCUSDT","event_time_ms":1775758312514,"first_update_id":91718177677,"final_update_id":91718177720,"bids":[["71977.68000000","1.18490000"],["71960.90000000","0.11963000"],["71943.91000000","0.39591000"],["71921.43000000","0.77056000"],["64779.92000000","0.00476000"],["64779.00000000","0.00019000"],["57582.15000000","0.00034000"]],"asks":[["71977.69000000","0.32874000"],["71977.70000000","0.00056000"],["71983.11000000","0.14842000"],["71983.90000000","0.10199000"],["71983.91000000","0.10190000"],["71983.92000000","0.00008000"],["71983.93000000","0.00008000"],["71983.94000000","0.00000000"],["71983.95000000","0.00000000"],["71985.08000000","0.20590000"],["72006.29000000","0.39269000"],["72028.79000000","0.74658000"],["72047.06000000","0.32647000"],["72047.72000000","0.00007000"],["72047.73000000","0.05140000"],["72190.75000000","0.00000000"]]}
{"type":"depthUpdate","symbol":"BTCUSDT","event_time_ms":1775758312615,"first_update_id":91718177721,"final_update_id":91718177747,"bids":[["64779.92000000","0.00459000"],["57582.15000000","0.00000000"]],"asks":[["71977.69000000","0.32882000"],["71977.70000000","0.00064000"],["71983.11000000","0.14835000"],["71983.89000000","0.11973000"],["71983.90000000","0.10207000"],["71983.91000000","0.10182000"],["71983.92000000","0.00000000"],["71983.93000000","0.00000000"],["71998.30000000","0.12943000"],["71999.53000000","0.00000000"],["72169.60000000","0.00000000"],["72201.53000000","0.00000000"]]}
{"type":"depthUpdate","symbol":"BTCUSDT","event_time_ms":1775758312714,"first_update_id":91718177748,"final_update_id":91718177795,"bids":[["71977.68000000","1.18514000"],["71977.67000000","0.00032000"],["71976.30000000","0.00016000"],["71976.29000000","0.09187000"],["71975.30000000","0.00016000"],["71975.29000000","0.11931000"],["71975.28000000","0.00008000"],["71963.28000000","0.00300000"],["71948.88000000","0.04684000"],["71946.59000000","0.02777000"],["71942.79000000","0.00000000"],["71508.02000000","0.00000000"],["64779.92000000","0.00476000"]],"asks":[["71977.69000000","0.32882000"],["71977.70000000","0.00064000"],["71977.82000000","0.01688000"],["71981.49000000","0.12157000"],["71983.11000000","0.14842000"],["71983.88000000","0.11924000"],["71983.89000000","0.11981000"],["71983.90000000","0.10191000"],["71983.91000000","0.00008000"],["71985.08000000","0.20582000"],["71996.83000000","0.12143000"],["71996.85000000","0.12125000"],["71997.33000000","0.41710000"],["71998.30000000","0.00000000"],["72047.06000000","0.37926000"],["74000.00000000","85.45070000"]]}
{"type":"depthUpdate","symbol":"BTCUSDT","event_time_ms":1775758312814,"first_update_id":91718177796,"final_update_id":91718177876,"bids":[["71977.68000000","1.18325000"],["71976.29000000","0.06486000"],["71976.28000000","0.08353000"],["71975.30000000","0.10344000"],["71975.29000000","0.11915000"],["71975.28000000","0.00000000"],["71971.62000000","0.41718000"],["71967.92000000","0.00188000"],["71963.28000000","0.01861000"],["71950.85000000","0.00000000"],["71950.66000000","0.00262000"],["71948.88000000","0.03123000"],["64779.92000000","0.00476000"]],"asks":[["71977.69000000","0.32896000"],["71977.70000000","0.00056000"],["71977.81000000","0.00016000"],["71977.82000000","0.05105000"],["71978.94000000","0.00777000"],["71981.48000000","0.00016000"],["71981.49000000","0.12165000"],["71983.11000000","0.14835000"],["71983.88000000","0.00008000"],["71983.89000000","0.00008000"],["71983.90000000","0.00000000"],["71983.91000000","0.00000000"],["71984.90000000","0.08331000"],["71986.51000000","0.00069000"],["71986.91000000","0.00000000"],["71988.14000000","0.11621000"],["72002.60000000","0.00000000"],["72003.24000000","0.00383000"],["72003.30000000","0.04170000"],["72025.66000000","0.00000000"],["72047.06000000","0.32647000"],["72047.73000000","0.00000000"],["72047.74000000","0.05140000"],["72100.34000000","1.89847000"],["72105.03000000","0.00000000"],["72105.04000000","0.00000000"]]}
{"type":"depthUpdate","symbol":"BTCUSDT","event_time_ms":1775758312914,"first_update_id":91718177877,"final_update_id":91718177905,"bids":[["71977.68000000","1.18501000"],["71977.67000000","0.00016000"],["71976.28000000","0.08353000"],["71975.30000000","0.10352000"],["71971.62000000","0.41710000"],["71967.92000000","0.00000000"],["64779.92000000","0.00476000"],["64779.00000000","0.00039000"]],"asks":[["71977.69000000","0.32876000"],["71983.11000000","0.08974000"],["71983.88000000","0.00000000"],["71983.89000000","0.00000000"],["71984.89000000","0.13111000"],["71984.90000000","0.08339000"],["71985.08000000","0.20590000"],["71996.85000000","0.00000000"],["72014.60000000","1.23101000"],["72047.06000000","0.43483000"],["72097.22000000","0.69757000"]]}
{"type":"depthUpdate","symbol":"BTCUSDT","event_time_ms":1775758313014,"first_update_id":91718177906,"final_update_id":91718177918,"bids":[["71846.64000000","0.00000000"],["64779.92000000","0.00442000"],["64779.00000000","0.00019000"],["57582.15000000","0.00034000"]],"asks":[["71983.11000000","0.08974000"],["71984.89000000","0.13119000"],["71985.08000000","0.20582000"]]}
{"type":"depthUpdate","symbol":"BTCUSDT","event_time_ms":1775758313114,"first_update_id":91718177919,"final_update_id":91718177940,"bids":[["71977.68000000","1.18309000"],["71975.31000000","0.11805000"],["71975.30000000","0.10336000"],["71975.29000000","0.00008000"],["71961.67000000","0.11709000"],["71960.90000000","0.00000000"],["71801.62000000","0.00000000"],["71801.02000000","0.00825000"],["71700.00000000","0.31592000"],["64779.92000000","0.00442000"],["57582.14000000","0.00000000"]],"asks":[["71977.69000000","0.32822000"],["71986.51000000","0.00000000"],["71999.49000000","0.11024000"],["72004.60000000","0.00000000"],["72011.80000000","0.98589000"]]}
{"type":"depthUpdate","symbol":"BTCUSDT","event_time_ms":1775758313214,"first_update_id":91718177941,"final_update_id":91718177969,"bids":[["71977.68000000","1.18499000"],["71976.28000000","0.08353000"],["71975.31000000","0.11813000"],["71975.30000000","0.10336000"],["71975.29000000","0.00000000"],["71967.94000000","0.00000000"],["64779.92000000","0.00459000"],["57582.15000000","0.00000000"],["57582.14000000","0.00000000"]],"asks":[["71977.82000000","0.01696000"],["71981.48000000","0.00000000"],["71981.49000000","0.00032000"],["71983.99000000","0.12313000"],["71984.88000000","0.00008000"],["71986.64000000","0.00070000"],["72003.02000000","0.00400000"],["72010.22000000","0.00400000"],["72010.23000000","0.02283000"]]}
{"type":"depthUpdate","symbol":"BTCUSDT","event_time_ms":1775758313315,"first_update_id":91718177970,"final_update_id":91718177999,"bids":[["71975.31000000","0.11797000"],["64779.92000000","0.00476000"]],"asks":[["71977.69000000","0.32830000"],["71977.81000000","0.00000000"],["71977.82000000","0.00032000"],["71978.94000000","0.00777000"],["71981.49000000","0.00024000"],["71983.11000000","0.15414000"],["71983.98000000","0.11587000"],["71983.99000000","0.12321000"],["71984.89000000","0.00016000"],["71988.14000000","0.00112000"],["71996.83000000","0.10688000"],["72047.06000000","0.32647000"],["72047.74000000","0.00000000"]]}
{"type":"depthUpdate","symbol":"BTCUSDT","event_time_ms":1775758313414,"first_update_id":91718178000,"final_update_id":91718178026,"bids":[["71961.80000000","0.00007000"],["64779.92000000","0.00459000"]],"asks":[["71977.69000000","0.32838000"],["71977.70000000","0.00064000"],["71977.82000000","0.00024000"],["71983.11000000","0.15421000"],["71983.97000000","0.10435000"],["71983.98000000","0.11595000"],["71983.99000000","0.12321000"],["71984.88000000","0.00000000"],["71984.89000000","0.00008000"],["71990.60000000","0.00007000"],["72047.06000000","0.37787000"]]}
{"type":"depthUpdate","symbol":"BTCUSDT","event_time_ms":1775758313514,"first_update_id":91718178027,"final_update_id":91718178049,"bids":[["71977.68000000","1.22616000"],["71972.25000000","0.00008000"],["71923.69000000","0.00000000"],["64779.92000000","0.00442000"],["57582.15000000","0.00034000"]],"asks":[["71977.69000000","0.32830000"],["71977.70000000","0.00056000"],["71977.82000000","0.01688000"],["71983.11000000","0.15428000"],["71983.96000000","0.12322000"],["71983.98000000","0.11579000"],["71983.99000000","0.00016000"],["72047.06000000","0.42927000"],["72047.75000000","0.05557000"]]}
{"type":"depthUpdate","symbol":"BTCUSDT","event_time_ms":1775758313614,"first_update_id":91718178050,"final_update_id":91718178083,"bids":[["71977.68000000","1.22578000"],["71973.00000000","0.02308000"],["71972.25000000","0.00000000"],["71971.62000000","0.41718000"],["71950.65000000","0.01041000"],["64779.92000000","0.00459000"],["64779.00000000","0.00019000"],["57582.15000000","0.00000000"]],"asks":[["71977.69000000","0.32822000"],["71977.81000000","0.00016000"],["71977.82000000","0.01696000"],["71983.11000000","0.15435000"],["71983.95000000","0.00008000"],["71983.96000000","0.12322000"],["71983.97000000","0.10427000"],["71983.98000000","0.00008000"],["71983.99000000","0.00008000"],["71984.90000000","0.08331000"],["72097.99000000","1.89103000"],["72100.34000000","0.00744000"]]}
{"type":"depthUpdate","symbol":"BTCUSDT","event_time_ms":1775758313714,"first_update_id":91718178084,"final_update_id":91718178105,"bids":[["64779.92000000","0.00442000"]],"asks":[["71977.69000000","0.32838000"],["71977.70000000","0.00072000"],["71983.11000000","0.15435000"],["71983.94000000","0.00008000"],["71983.95000000","0.10477000"],["71983.96000000","0.12314000"],["71983.97000000","0.00008000"],["71983.98000000","0.00000000"],["71984.90000000","0.08339000"],["72035.81000000","0.01668000"]]}
{"type":"depthUpdate","symbol":"BTCUSDT","event_time_ms":1775758313815,"first_update_id":91718178106,"final_update_id":91718178123,"bids":[["64779.92000000","0.00442000"]],"asks":[["71977.69000000","0.32846000"],["71977.70000000","0.00080000"],["71983.11000000","0.15435000"],["71983.93000000","0.00008000"],["71983.94000000","0.10206000"],["71983.95000000","0.10477000"],["71983.96000000","0.00008000"],["71983.97000000","0.00000000"]]}
{"type":"depthUpdate","symbol":"BTCUSDT","event_time_ms":1775758313914,"first_update_id":91718178124,"final_update_id":91718178158,"bids":[["71977.68000000","1.22570000"],["71977.67000000","0.00008000"],["71974.01000000","0.00694000"],["71972.17000000","0.00694000"],["71970.36000000","0.00694000"],["71965.45000000","0.00000000"],["71956.93000000","0.00000000"],["71923.99000000","0.97523000"],["71920.01000000","0.00000000"],["71916.19000000","0.00012000"],["71916.01000000","0.00000000"],["71912.67000000","0.00000000"],["71912.01000000","0.00346000"],["71909.00000000","0.00012000"],["71843.76000000","0.00000000"],["71840.22000000","0.00138000"],["64779.92000000","0.00459000"]],"asks":[["71977.69000000","0.32830000"],["71977.70000000","0.00064000"],["71983.11000000","0.15428000"],["71983.94000000","0.10206000"],["71983.95000000","0.00008000"],["71983.96000000","0.00000000"],["71985.39000000","0.00000000"],["71985.90000000","0.00694000"],["71989.24000000","0.00000000"],["72003.06000000","0.00012000"],["72007.19000000","0.00000000"],["72010.44000000","0.00012000"],["72014.46000000","0.00008000"],["72033.66000000","0.00346000"],["72037.33000000","0.00000000"],["72105.99000000","0.00138000"],["72106.39000000","0.20476000"],["72126.55000000","0.00000000"]]}
{"type":"depthUpdate","symbol":"BTCUSDT","event_time_ms":1775758314014,"first_update_id":91718178159,"final_update_id":91718178180,"bids":[["71975.30000000","0.10336000"],["71974.01000000","0.00702000"],["71973.00000000","0.02308000"],["71971.62000000","0.41710000"],["71963.28000000","0.04984000"],["71948.88000000","0.00000000"],["64779.92000000","0.00476000"],["64779.00000000","0.00039000"],["57582.15000000","0.00034000"],["57582.00000000","0.00000000"]],"asks":[["71983.11000000","0.15421000"],["71983.94000000","0.10206000"],["71983.95000000","0.00000000"],["71985.08000000","0.20590000"]]}
{"type":"depthUpdate","symbol":"BTCUSDT","event_time_ms":1775758314114,"first_update_id":91718178181,"final_update_id":91718178190,"bids":[["71963.15000000","0.11551000"],["71961.67000000","0.00000000"],["64779.92000000","0.00476000"],["64779.00000000","0.00019000"],["57582.14000000","0.00000000"]],"asks":[["72047.06000000","0.37787000"]]}
{"type":"depthUpdate","symbol":"BTCUSDT","event_time_ms":1775758314214,"first_update_id":91718178191,"final_update_id":91718178389,"bids":[["71977.68000000","1.78905000"],["71976.31000000","0.00000000"],["71976.30000000","0.00000000"],["71976.29000000","0.06470000"],["71975.32000000","0.00694000"],["71974.76000000","0.01743000"],["71974.50000000","0.05263000"],["71974.01000000","0.00008000"],["71973.00000000","0.00308000"],["71972.96000000","0.00767000"],["71972.18000000","0.00000000"],["71972.17000000","0.00000000"],["71971.21000000","0.00694000"],["71970.95000000","0.00694000"],["71970.36000000","0.00000000"],["71969.96000000","0.07000000"],["71962.85000000","0.00000000"],["71961.84000000","0.07007000"],["71960.97000000","0.50024000"],["71959.26000000","0.08000000"],["71957.92000000","0.00000000"],["71956.52000000","0.00000000"],["71955.39000000","0.00000000"],["71954.28000000","0.00000000"],["71952.49000000","0.00299000"],["71950.66000000","0.00000000"],["71947.00000000","0.00000000"],["71945.95000000","0.00000000"],["71945.45000000","0.02283000"],["71941.30000000","0.00000000"],["71938.12000000","0.10321000"],["71935.69000000","0.00000000"],["71928.92000000","0.04844000"],["71924.19000000","0.00435000"],["71922.93000000","0.00000000"],["71901.78000000","0.20996000"],["71888.62000000","0.00744000"],["71852.63000000","0.01492000"],["71834.71000000","0.00000000"],["71827.96000000","0.00000000"],["71778.93000000","0.00000000"],["64779.92000000","0.00459000"],["57582.15000000","0.00000000"],["57582.14000000","0.00000000"]],"asks":[["71977.69000000","0.01015000"],["71977.70000000","0.00056000"],["71977.81000000","0.00000000"],["71977.82000000","0.00032000"],["71977.83000000","0.00008000"],["71977.88000000","0.00000000"],["71978.94000000","0.00008000"],["71979.26000000","0.00000000"],["71981.50000000","0.02481000"],["71983.11000000","0.08981000"],["71983.93000000","0.00000000"],["71983.94000000","0.00008000"],["71984.34000000","0.00000000"],["71984.89000000","0.00024000"],["71984.90000000","0.00008000"],["71985.07000000","0.00023000"],["71985.08000000","0.00790000"],["71985.90000000","0.00000000"],["71986.63000000","0.00000000"],["71987.88000000","0.00000000"],["71988.13000000","0.08331000"],["71988.20000000","0.00000000"],["71988.29000000","0.00000000"],["71988.47000000","0.00000000"],["71988.66000000","0.00694000"],["71988.67000000","0.00000000"],["71989.52000000","0.00000000"],["71989.59000000","0.00000000"],["71990.59000000","0.00694000"],["71991.01000000","0.34726000"],["71991.92000000","0.00000000"],["71992.27000000","0.00000000"],["71992.68000000","0.00000000"],["71992.88000000","0.03000000"],["71992.97000000","0.00000000"],["71993.22000000","0.01389000"],["71993.84000000","0.00000000"],["71994.29000000","0.00038000"],["71995.64000000","0.00000000"],["71996.58000000","0.12000000"],["71996.83000000","0.00000000"],["71996.84000000","0.00000000"],["71997.33000000","0.00000000"],["71997.35000000","0.00000000"],["71999.49000000","0.00000000"],["71999.69000000","0.00830000"],["71999.99000000","0.00000000"],["72000.07000000","0.00000000"],["72000.39000000","0.00430000"],["72000.41000000","0.00000000"],["72000.42000000","0.00000000"],["72002.59000000","0.07000000"],["72003.02000000","0.00000000"],["72003.24000000","0.00000000"],["72003.65000000","0.00000000"],["72003.92000000","0.00000000"],["72007.10000000","0.02000000"],["72007.23000000","1.58498000"],["72007.25000000","0.00000000"],["72007.26000000","0.00000000"],["72008.17000000","0.41710000"],["72008.18000000","0.00000000"],["72010.22000000","0.00000000"],["72011.79000000","2.07982000"],["72011.81000000","0.00000000"],["72012.92000000","0.49988000"],["72014.59000000","1.58513000"],["72015.38000000","0.00000000"],["72015.39000000","0.00000000"],["72017.33000000","0.00000000"],["72018.82000000","1.66272000"],["72019.14000000","0.49984000"],["72019.70000000","2.00208000"],["72019.72000000","0.00000000"],["72022.68000000","0.00000000"],["72023.21000000","0.41710000"],["72027.77000000","1.66272000"],["72028.27000000","0.00000000"],["72028.82000000","0.00000000"],["72032.34000000","0.00020000"],["72033.67000000","0.00000000"],["72044.83000000","0.16682000"],["72047.06000000","0.10836000"],["72047.74000000","0.05140000"],["72051.97000000","1.58498000"],["72062.63000000","0.00000000"],["72063.73000000","0.00000000"],["72069.15000000","0.00762000"],["72076.74000000","1.58498000"],["72097.99000000","0.00000000"],["72105.13000000","0.01530000"],["72118.06000000","0.00000000"],["72119.46000000","0.00000000"],["72134.62000000","0.00000000"],["72144.91000000","2.22119000"],["72173.84000000","0.00000000"],["72195.25000000","0.19800000"],["72359.16000000","0.01194000"]]}
{"type":"depthUpdate","symbol":"BTCUSDT","event_time_ms":1775758314314,"first_update_id":91718178390,"final_update_id":91718178600,"bids":[["71977.68000000","1.74212000"],["71976.29000000","0.09085000"],["71976.28000000","0.08360000"],["71975.33000000","0.11758000"],["71975.32000000","0.00008000"],["71975.30000000","0.00015000"],["71974.76000000","0.01751000"],["71974.50000000","0.05271000"],["71974.01000000","0.00000000"],["71973.05000000","1.58498000"],["71973.00000000","0.00300000"],["71968.59000000","0.00400000"],["71964.44000000","0.00068000"],["71963.94000000","0.00068000"],["71963.90000000","0.03123000"],["71961.84000000","0.00007000"],["71961.53000000","0.02655000"],["71961.39000000","0.00400000"],["71960.99000000","1.58566000"],["71959.68000000","0.00136000"],["71959.26000000","0.00000000"],["71957.32000000","0.03128000"],["71954.19000000","0.00400000"],["71948.45000000","0.00000000"],["71941.18000000","0.00000000"],["71918.33000000","1.66707000"],["71914.34000000","0.00112000"],["71913.93000000","0.01081000"],["71909.70000000","0.00000000"],["71899.97000000","0.00000000"],["71899.45000000","0.00000000"],["64779.92000000","0.00459000"]],"asks":[["71977.69000000","0.00967000"],["71977.70000000","0.00016000"],["71977.82000000","0.00000000"],["71977.83000000","0.00000000"],["71978.93000000","0.00000000"],["71978.94000000","0.00000000"],["71978.99000000","0.00000000"],["71981.50000000","0.00015000"],["71981.63000000","0.01760000"],["71981.93000000","0.00008000"],["71981.94000000","0.00000000"],["71983.10000000","0.00000000"],["71983.11000000","0.00015000"],["71983.13000000","0.00007000"],["71983.26000000","0.00750000"],["71983.94000000","0.00000000"],["71984.89000000","0.00008000"],["71984.90000000","0.00000000"],["71985.07000000","0.00015000"],["71985.08000000","0.00790000"],["71985.40000000","0.00000000"],["71985.60000000","0.00000000"],["71985.90000000","0.00016000"],["71985.91000000","0.16057000"],["71985.92000000","0.00016000"],["71985.93000000","0.01787000"],["71986.51000000","0.00029000"],["71987.26000000","0.00016000"],["71987.27000000","0.01397000"],["71987.30000000","0.00000000"],["71987.40000000","0.00000000"],["71987.48000000","0.00444000"],["71987.99000000","0.00048000"],["71988.12000000","0.00000000"],["71988.13000000","0.00008000"],["71988.14000000","0.00120000"],["71989.25000000","0.17767000"],["71992.08000000","0.00000000"],["71992.66000000","0.00000000"],["71992.88000000","0.01000000"],["71992.98000000","0.07171000"],["71993.62000000","0.00444000"],["71994.68000000","0.02000000"],["71995.01000000","0.00000000"],["71995.92000000","0.10895000"],["71997.33000000","0.09985000"],["71997.34000000","0.13705000"],["71999.14000000","0.00000000"],["71999.27000000","0.08000000"],["72000.05000000","0.00000000"],["72000.39000000","0.00000000"],["72001.76000000","0.00000000"],["72002.59000000","0.00000000"],["72002.64000000","0.07000000"],["72003.30000000","0.00000000"],["72003.63000000","0.00000000"],["72003.64000000","0.00000000"],["72003.67000000","0.21739000"],["72003.99000000","0.27734000"],["72004.14000000","0.00000000"],["72004.83000000","0.00000000"],["72006.86000000","0.00400000"],["72007.24000000","0.00000000"],["72011.78000000","1.15831000"],["72011.80000000","0.00000000"],["72014.06000000","0.00400000"],["72014.60000000","0.00000000"],["72016.20000000","0.00300000"],["72017.29000000","0.02820000"],["72018.00000000","0.00420000"],["72018.93000000","0.00000000"],["72019.71000000","0.00000000"],["72022.92000000","0.00000000"],["72028.84000000","0.00425000"],["72029.44000000","0.00000000"],["72029.51000000","0.00000000"],["72030.30000000","0.02000000"],["72030.70000000","0.00000000"],["72042.90000000","0.01733000"],["72044.83000000","0.05568000"],["72047.06000000","0.05279000"],["72047.74000000","0.33342000"],["72051.15000000","0.27785000"],["72051.96000000","0.00000000"],["72051.98000000","0.00000000"],["72053.66000000","0.00000000"],["72056.55000000","0.00000000"],["72057.69000000","1.66707000"],["72069.15000000","0.00000000"],["72069.43000000","0.00000000"],["72070.61000000","0.00000000"],["72071.01000000","0.00738000"],["72076.73000000","1.26702000"],["72076.75000000","0.00000000"],["72097.22000000","0.15260000"],["72105.13000000","0.00000000"],["72106.60000000","0.00000000"],["72107.00000000","0.01503000"],["72119.45000000","0.00000000"],["72157.66000000","0.00000000"],["72202.06000000","0.00015000"],["72205.65000000","0.00015000"]]}
{"type":"depthUpdate","symbol":"BTCUSDT","event_time_ms":1775758314414,"first_update_id":91718178601,"final_update_id":91718178713,"bids":[["71976.28000000","0.08360000"],["71975.95000000","0.00756000"],["71975.33000000","0.11766000"],["71975.32000000","0.00000000"],["71975.31000000","0.11789000"],["71975.30000000","0.00007000"],["71970.48000000","0.01569000"],["71967.49000000","0.11673000"],["71963.28000000","0.03423000"],["71963.15000000","0.00000000"],["71961.80000000","0.00007000"],["71961.37000000","0.00352000"],["71957.88000000","0.00000000"],["64779.92000000","0.00476000"]],"asks":[["71977.69000000","0.00977000"],["71977.70000000","0.00024000"],["71977.95000000","0.00008000"],["71979.08000000","0.00015000"],["71981.49000000","0.00008000"],["71981.50000000","0.00007000"],["71981.62000000","0.00024000"],["71981.63000000","0.01768000"],["71981.93000000","0.00000000"],["71983.11000000","0.00007000"],["71983.26000000","0.00758000"],["71985.06000000","0.02256000"],["71985.07000000","0.00022000"],["71985.89000000","0.00016000"],["71985.90000000","0.00016000"],["71987.26000000","0.00000000"],["71987.27000000","0.01397000"],["71988.13000000","0.00000000"],["71988.14000000","0.12219000"],["71988.15000000","0.19121000"],["71988.66000000","0.00702000"],["71990.60000000","0.00007000"],["71990.99000000","0.12102000"],["71991.08000000","0.00008000"],["71992.98000000","0.10236000"],["71994.29000000","0.00000000"],["71995.91000000","0.00038000"],["71995.92000000","0.00000000"],["71997.32000000","0.00000000"],["71997.33000000","0.00000000"],["72000.42000000","0.50417000"],["72003.67000000","0.21739000"],["72003.72000000","0.00000000"],["72004.14000000","1.58498000"],["72004.74000000","0.00967000"],["72004.83000000","0.41710000"],["72006.37000000","0.13737000"],["72006.49000000","0.03123000"],["72020.88000000","0.01778000"],["72031.31000000","0.00000000"],["72031.76000000","0.04844000"],["72051.14000000","0.22228000"],["72051.15000000","0.05557000"],["72065.80000000","0.21323000"],["72071.01000000","0.00000000"],["72071.61000000","0.00000000"],["72072.06000000","0.00742000"],["72107.00000000","0.00000000"],["72107.60000000","0.00000000"],["72108.05000000","0.01529000"],["72205.65000000","0.00000000"]]}
{"type":"depthUpdate","symbol":"BTCUSDT","event_time_ms":1775758314514,"first_update_id":91718178714,"final_update_id":91718178768,"bids":[["71976.28000000","0.08360000"],["71967.49000000","0.00826000"],["71966.61000000","0.07000000"],["71965.20000000","0.08020000"],["64779.92000000","0.00476000"],["57582.15000000","0.00034000"]],"asks":[["71977.69000000","0.00977000"],["71977.70000000","0.00024000"],["71983.26000000","0.00758000"],["71984.89000000","0.19808000"],["71985.05000000","0.00000000"],["71985.06000000","0.00008000"],["71985.89000000","0.00000000"],["71985.90000000","0.12571000"],["71987.26000000","0.00016000"],["71987.27000000","0.01397000"],["71988.13000000","0.00008000"],["71988.14000000","0.12227000"],["71988.15000000","0.19113000"],["71988.66000000","0.00694000"],["71988.95000000","0.08331000"],["71997.33000000","0.11409000"],["72004.50000000","0.11805000"],["72004.72000000","0.00977000"],["72004.74000000","0.00000000"],["72004.75000000","0.00000000"],["72004.82000000","1.66272000"],["72006.37000000","0.00000000"],["72008.54000000","0.07000000"],["72051.14000000","0.27507000"],["72051.15000000","0.00000000"],["72080.89000000","0.02175000"]]}
{"type":"depthUpdate","symbol":"BTCUSDT","event_time_ms":1775758314614,"first_update_id":91718178769,"final_update_id":91718178817,"bids":[["71977.68000000","1.68518000"],["71976.09000000","0.00694000"],["71970.48000000","0.00008000"],["71967.06000000","0.02000000"],["66222.98000000","0.00016000"],["64779.92000000","0.00459000"],["57582.15000000","0.00000000"]],"asks":[["71977.69000000","0.08565000"],["71977.70000000","0.00032000"],["71983.26000000","0.00758000"],["71983.98000000","0.11546000"],["71983.99000000","0.11559000"],["71984.87000000","0.00016000"],["71984.88000000","0.00016000"],["71984.89000000","0.19816000"],["71985.06000000","0.00000000"],["71985.08000000","0.00790000"],["71985.89000000","0.00016000"],["71985.90000000","0.12563000"],["71985.92000000","0.00000000"],["71987.26000000","0.00000000"],["71988.13000000","0.00000000"],["71988.14000000","0.12219000"],["71990.99000000","0.00000000"],["71995.91000000","0.00038000"],["71997.33000000","0.00000000"],["72020.88000000","0.00217000"],["72025.84000000","0.00015000"],["72202.06000000","0.00000000"]]}
{"type":"depthUpdate","symbol":"BTCUSDT","event_time_ms":1775758314714,"first_update_id":91718178818,"final_update_id":91718178850,"bids":[["71976.28000000","0.08360000"],["71976.09000000","0.00702000"],["71973.06000000","0.71327000"],["71964.61000000","0.12861000"],["71938.09000000","0.00500000"],["71902.64000000","0.11114000"],["71801.62000000","0.00825000"],["71801.02000000","0.00000000"],["64779.92000000","0.00459000"]],"asks":[["71977.69000000","0.00992000"],["71983.26000000","0.00758000"],["71983.97000000","0.00016000"],["71983.98000000","0.11554000"],["71983.99000000","0.00023000"],["71984.87000000","0.00000000"],["71985.89000000","0.00000000"],["71985.90000000","0.00016000"],["71985.93000000","0.01779000"],["71987.27000000","0.01389000"],["71999.14000000","0.11061000"],["72003.49000000","0.12717000"],["72004.50000000","0.00000000"],["72102.69000000","2.01103000"]]}
{"type":"depthUpdate","symbol":"BTCUSDT","event_time_ms":1775758314814,"first_update_id":91718178851,"final_update_id":91718178913,"bids":[["71963.28000000","0.04984000"],["71956.99000000","0.00000000"],["64779.92000000","0.00476000"],["57582.00000000","0.00000000"],["43370.94000000","0.00000000"],["43310.81000000","0.00014000"],["43235.82000000","0.00000000"],["43215.99000000","0.00000000"],["43208.25000000","0.00014000"],["43187.21000000","0.00056000"],["43148.98000000","0.00000000"],["43130.99000000","0.00112000"]],"asks":[["71977.69000000","0.00991000"],["71977.70000000","0.00024000"],["71983.96000000","0.00016000"],["71983.97000000","0.06251000"],["71983.98000000","0.00008000"],["71983.99000000","0.00015000"],["71985.08000000","0.00790000"],["71985.90000000","0.00016000"],["71985.93000000","0.01787000"],["71987.27000000","0.01397000"],["71988.13000000","0.00008000"],["71997.32000000","0.22801000"],["71997.33000000","0.11409000"],["71997.34000000","0.00000000"],["72001.66000000","0.41710000"],["72006.49000000","0.04684000"],["72014.40000000","0.00300000"],["72018.00000000","0.00120000"],["72047.75000000","0.00000000"],["72051.14000000","0.33064000"]]}
{"type":"depthUpdate","symbol":"BTCUSDT","event_time_ms":1775758314914,"first_update_id":91718178914,"final_update_id":91718178937,"bids":[["71970.04000000","0.02000000"],["71967.86000000","0.02000000"],["71965.70000000","0.13232000"],["71964.61000000","0.00000000"],["71959.95000000","0.00000000"],["71914.51000000","0.00000000"],["71891.31000000","0.00000000"],["64779.92000000","0.00459000"],["64779.00000000","0.00019000"],["57582.00000000","0.00000000"]],"asks":[["71977.69000000","0.00966000"],["71983.26000000","0.00758000"],["71983.97000000","0.06259000"],["71983.98000000","0.00000000"],["72102.68000000","1.10436000"],["72103.04000000","0.00000000"]]}
{"type":"depthUpdate","symbol":"BTCUSDT","event_time_ms":1775758315014,"first_update_id":91718178938,"final_update_id":91718178946,"bids":[["71903.74000000","0.00000000"],["64779.92000000","0.00476000"],["57582.15000000","0.00034000"],["57582.00000000","0.00000000"]],"asks":[]}
{"type":"depthUpdate","symbol":"BTCUSDT","event_time_ms":1775758315114,"first_update_id":91718178947,"final_update_id":91718178971,"bids":[["71957.80000000","0.00000000"],["71891.31000000","0.00050000"],["64779.92000000","0.00476000"],["64779.00000000","0.00039000"],["57582.14000000","0.00000000"],["43494.99000000","0.00014000"],["43410.55000000","0.00252000"],["43364.68000000","0.00028000"],["43359.11000000","0.00000000"],["43348.40000000","0.00042000"],["43226.54000000","0.00042000"],["43207.67000000","0.00000000"],["43189.90000000","0.00014000"],["43142.88000000","0.00070000"]],"asks":[["71977.69000000","0.00948000"]]}
{"type":"depthUpdate","symbol":"BTCUSDT","event_time_ms":1775758315214,"first_update_id":91718178972,"final_update_id":91718178998,"bids":[["71973.75000000","0.00694000"],["71971.21000000","0.00000000"],["71970.67000000","0.02000000"],["71964.15000000","0.50022000"],["71962.93000000","0.00000000"],["71954.96000000","0.00341000"],["71952.49000000","0.00000000"],["66222.98000000","0.00000000"],["64779.92000000","0.00493000"],["64779.00000000","0.00019000"],["57582.15000000","0.00000000"],["57582.14000000","0.00000000"]],"asks":[["71977.69000000","0.08528000"],["71985.90000000","0.12721000"],["71986.75000000","0.00694000"],["71988.66000000","0.00000000"],["71988.94000000","0.13621000"],["71990.59000000","0.00000000"],["71992.79000000","0.00039000"],["71995.91000000","0.11409000"],["71995.92000000","0.00502000"],["71999.71000000","0.49997000"],["72006.86000000","0.00000000"],["72014.06000000","0.00000000"],["72019.14000000","0.00000000"]]}
{"type":"depthUpdate","symbol":"BTCUSDT","event_time_ms":1775758315315,"first_update_id":91718178999,"final_update_id":91718179023,"bids":[["71975.95000000","0.00764000"],["71974.50000000","0.05263000"],["71972.91000000","0.00008000"],["71960.72000000","0.00000000"],["64779.92000000","0.00442000"]],"asks":[["71985.08000000","0.00790000"],["71985.89000000","0.00016000"],["71985.90000000","0.12729000"],["71985.93000000","0.01787000"],["71987.27000000","0.01389000"],["71988.13000000","0.00000000"],["71997.32000000","0.34810000"],["71997.33000000","0.00000000"],["71999.14000000","0.00000000"],["72005.41000000","0.00400000"],["72012.61000000","0.00400000"],["72051.14000000","0.33203000"]]}
{"type":"depthUpdate","symbol":"BTCUSDT","event_time_ms":1775758315414,"first_update_id":91718179024,"final_update_id":91718179036,"bids":[["71961.80000000","0.00007000"],["71952.01000000","0.02300000"],["71914.51000000","0.00000000"],["64779.92000000","0.00442000"],["64779.91000000","0.00009000"]],"asks":[["71983.96000000","0.10088000"],["71990.60000000","0.00007000"],["79175.46000000","0.00007000"]]}
{"type":"depthUpdate","symbol":"BTCUSDT","event_time_ms":1775758315514,"first_update_id":91718179037,"final_update_id":91718179062,"bids":[["64779.92000000","0.00425000"],["64779.91000000","0.00000000"],["57582.15000000","0.00034000"]],"asks":[["71977.69000000","0.08542000"],["71977.95000000","0.00000000"],["71983.26000000","0.00758000"],["71983.94000000","0.12944000"],["71983.95000000","0.12272000"],["71983.96000000","0.10096000"],["71983.97000000","0.00008000"],["71985.89000000","0.00000000"],["71985.90000000","0.00008000"],["71985.93000000","0.01779000"],["71995.91000000","0.00000000"],["79175.46000000","0.00000000"]]}
{"type":"depthUpdate","symbol":"BTCUSDT","event_time_ms":1775758315615,"first_update_id":91718179063,"final_update_id":91718179101,"bids":[["64779.92000000","0.00476000"],["57582.15000000","0.00000000"]],"asks":[["71977.69000000","0.08524000"],["71983.26000000","0.00758000"],["71983.93000000","0.00016000"],["71983.94000000","0.12952000"],["71983.95000000","0.12264000"],["71983.96000000","0.00008000"],["71983.97000000","0.00000000"],["71984.88000000","0.00016000"],["71985.08000000","0.00790000"],["71985.90000000","0.00008000"],["71989.27000000","0.01389000"],["71993.22000000","0.00000000"],["72005.41000000","0.00000000"],["72012.61000000","0.00000000"],["72051.14000000","0.27507000"],["72201.53000000","0.02175000"]]}
{"type":"depthUpdate","symbol":"BTCUSDT","event_time_ms":1775758315714,"first_update_id":91718179102,"final_update_id":91718179136,"bids":[["71966.44000000","0.17581000"],["71965.70000000","0.00000000"],["71954.96000000","0.00000000"],["64779.92000000","0.00459000"]],"asks":[["71977.69000000","0.00953000"],["71977.70000000","0.00040000"],["71983.95000000","0.00008000"],["71983.96000000","0.00000000"],["71985.93000000","0.01787000"],["71992.98000000","0.07171000"],["71995.92000000","0.00000000"],["71997.31000000","0.11360000"],["72005.02000000","0.00400000"],["72012.22000000","0.00400000"],["72051.14000000","0.10975000"]]}
{"type":"depthUpdate","symbol":"BTCUSDT","event_time_ms":1775758315814,"first_update_id":91718179137,"final_update_id":91718179775,"bids":[["71977.68000000","0.22998000"],["71977.67000000","0.00064000"],["71977.43000000","0.00000000"],["71976.60000000","0.00000000"],["71976.30000000","0.00008000"],["71976.29000000","0.00016000"],["71976.28000000","0.00022000"],["71976.10000000","0.00008000"],["71976.09000000","0.00008000"],["71975.96000000","0.00008000"],["71975.95000000","0.00008000"],["71975.34000000","0.00000000"],["71975.33000000","0.00008000"],["71975.32000000","0.00000000"],["71975.31000000","0.00008000"],["71975.30000000","0.00000000"],["71974.97000000","0.00000000"],["71974.96000000","0.00000000"],["71974.87000000","0.00000000"],["71974.80000000","0.00000000"],["71974.77000000","0.00000000"],["71974.76000000","0.00008000"],["71974.51000000","0.00000000"],["71974.50000000","0.00008000"],["71974.00000000","0.00120000"],["71973.75000000","0.00000000"],["71973.07000000","0.00000000"],["71973.06000000","0.00000000"],["71973.05000000","0.00000000"],["71973.01000000","0.00000000"],["71973.00000000","0.00000000"],["71972.96000000","0.00000000"],["71972.72000000","0.00000000"],["71972.64000000","0.00000000"],["71972.55000000","0.00000000"],["71971.70000000","0.00000000"],["71971.63000000","0.00000000"],["71971.62000000","0.00000000"],["71971.20000000","0.00000000"],["71970.95000000","0.00008000"],["71970.94000000","0.00000000"],["71970.75000000","0.00016000"],["71970.74000000","0.00000000"],["71970.70000000","0.00000000"],["71970.68000000","0.00016000"],["71970.63000000","0.00000000"],["71970.62000000","0.00000000"],["71970.49000000","0.00000000"],["71970.47000000","0.00000000"],["71970.36000000","0.00000000"],["71970.05000000","0.00016000"],["71969.96000000","0.00000000"],["71969.85000000","0.00000000"],["71969.80000000","0.00000000"],["71969.31000000","0.00000000"],["71969.25000000","0.05000000"],["71968.61000000","0.00000000"],["71968.59000000","0.00000000"],["71968.53000000","0.00000000"],["71968.52000000","0.11068000"],["71968.51000000","0.00000000"],["71968.50000000","0.00000000"],["71967.61000000","0.00000000"],["71967.49000000","0.00000000"],["71967.41000000","0.00000000"],["71966.86000000","0.12256000"],["71966.85000000","0.00000000"],["71966.84000000","0.00000000"],["71966.80000000","0.00000000"],["71966.61000000","0.00000000"],["71966.45000000","0.00000000"],["71966.44000000","0.06947000"],["71965.90000000","0.00000000"],["71965.48000000","0.00000000"],["71965.41000000","0.00694000"],["71965.39000000","0.08000000"],["71965.23000000","0.00000000"],["71965.20000000","0.00000000"],["71964.90000000","0.00000000"],["71964.88000000","0.00000000"],["71964.65000000","0.00000000"],["71964.15000000","0.00000000"],["71963.93000000","0.00000000"],["71963.92000000","0.05086000"],["71963.91000000","0.00000000"],["71963.90000000","0.00000000"],["71963.60000000","0.02000000"],["71963.28000000","0.00300000"],["71962.98000000","0.00000000"],["71962.68000000","0.00000000"],["71962.63000000","0.00000000"],["71962.21000000","0.00000000"],["71961.88000000","0.00000000"],["71961.75000000","0.00000000"],["71961.39000000","0.00000000"],["71961.00000000","0.00000000"],["71960.99000000","0.00068000"],["71960.97000000","0.00000000"],["71960.89000000","0.00000000"],["71960.01000000","0.00694000"],["71959.13000000","0.00000000"],["71958.21000000","0.00000000"],["71958.06000000","0.00000000"],["71958.05000000","0.00000000"],["71957.90000000","0.00000000"],["71957.76000000","0.00000000"],["71957.60000000","0.11000000"],["71957.51000000","0.41710000"],["71957.32000000","0.00000000"],["71957.10000000","0.07000000"],["71956.74000000","3.24770000"],["71956.73000000","0.43471000"],["71956.72000000","0.00000000"],["71955.19000000","0.00000000"],["71955.08000000","0.00000000"],["71955.07000000","0.00000000"],["71955.00000000","0.00300000"],["71954.90000000","0.00000000"],["71954.58000000","0.41710000"],["71954.32000000","0.00000000"],["71954.19000000","0.00000000"],["71953.22000000","1.58498000"],["71952.97000000","0.34731000"],["71952.96000000","0.59127000"],["71952.32000000","0.00000000"],["71952.15000000","0.00112000"],["71952.11000000","0.00000000"],["71951.52000000","0.00000000"],["71950.93000000","0.00000000"],["71949.97000000","1.66272000"],["71949.81000000","0.08000000"],["71949.69000000","0.00000000"],["71949.43000000","1.06163000"],["71949.42000000","2.00208000"],["71949.19000000","0.00000000"],["71949.18000000","0.00000000"],["71949.11000000","0.00000000"],["71949.10000000","0.00138000"],["71948.88000000","0.04684000"],["71948.63000000","0.00000000"],["71948.49000000","0.03123000"],["71948.40000000","0.00000000"],["71946.59000000","0.00000000"],["71946.44000000","0.00000000"],["71946.39000000","0.00000000"],["71946.15000000","0.50034000"],["71946.00000000","0.00420000"],["71945.00000000","0.50035000"],["71944.20000000","0.00300000"],["71943.91000000","0.00000000"],["71942.23000000","0.00009000"],["71941.83000000","0.00000000"],["71941.05000000","0.00000000"],["71940.60000000","0.00300000"],["71939.89000000","1.66272000"],["71939.24000000","0.03128000"],["71938.80000000","0.00300000"],["71938.12000000","0.00000000"],["71938.09000000","0.00000000"],["71937.15000000","0.00000000"],["71936.01000000","0.00000000"],["71935.75000000","0.00000000"],["71934.81000000","0.00000000"],["71932.15000000","0.00000000"],["71931.09000000","1.66272000"],["71931.08000000","0.00000000"],["71931.07000000","0.00000000"],["71929.14000000","0.00020000"],["71928.92000000","0.00000000"],["71927.95000000","0.00000000"],["71927.68000000","0.00000000"],["71926.75000000","0.00000000"],["71921.43000000","0.00000000"],["71921.06000000","0.00020000"],["71918.33000000","0.00000000"],["71913.06000000","0.39380000"],["71913.05000000","0.69524000"],["71912.85000000","0.00555000"],["71911.17000000","0.00000000"],["71910.96000000","0.01110000"],["71910.46000000","0.00000000"],["71906.11000000","0.00000000"],["71904.15000000","0.69533000"],["71903.45000000","0.00000000"],["71902.66000000","0.00011000"],["71902.64000000","0.00000000"],["71901.78000000","0.00000000"],["71900.47000000","0.00000000"],["71899.27000000","0.00000000"],["71897.14000000","0.11114000"],["71896.50000000","0.05263000"],["71894.61000000","0.11114000"],["71888.62000000","0.00000000"],["71887.65000000","0.00000000"],["71887.38000000","0.00000000"],["71886.45000000","0.00000000"],["71867.50000000","0.91170000"],["71867.49000000","1.39138000"],["71867.44000000","0.00000000"],["71852.63000000","0.00000000"],["71851.66000000","0.00000000"],["71851.39000000","0.00000000"],["71850.46000000","0.00000000"],["71830.11000000","0.00000000"],["71784.78000000","0.00000000"],["64779.92000000","0.00442000"],["64779.91000000","0.00009000"]],"asks":[["71977.69000000","2.80681000"],["71977.70000000","0.00008000"],["71977.74000000","0.08331000"],["71978.40000000","0.00300000"],["71978.85000000","0.00029000"],["71979.37000000","0.00000000"],["71980.19000000","0.00000000"],["71980.20000000","0.00300000"],["71980.31000000","0.00020000"],["71980.50000000","0.00773000"],["71981.48000000","0.07418000"],["71981.49000000","0.14413000"],["71981.62000000","0.00000000"],["71981.66000000","0.00007000"],["71982.00000000","0.00340000"],["71982.01000000","0.05270000"],["71982.10000000","0.01389000"],["71983.10000000","0.00000000"],["71983.12000000","0.00000000"],["71983.25000000","0.00039000"],["71983.80000000","0.00300000"],["71983.92000000","0.12982000"],["71983.93000000","0.12157000"],["71983.94000000","0.00008000"],["71983.95000000","0.00000000"],["71983.99000000","0.00008000"],["71984.88000000","0.00000000"],["71985.07000000","0.00014000"],["71985.47000000","0.01000000"],["71985.60000000","0.00300000"],["71985.89000000","0.31928000"],["71985.90000000","0.00000000"],["71985.91000000","0.00008000"],["71986.30000000","0.00000000"],["71986.39000000","0.08000000"],["71986.50000000","0.00000000"],["71986.57000000","0.02000000"],["71986.64000000","0.00000000"],["71986.75000000","0.00008000"],["71987.40000000","0.00300000"],["71987.88000000","0.00020000"],["71987.99000000","0.00000000"],["71988.13000000","3.24770000"],["71988.14000000","0.00112000"],["71988.94000000","0.12927000"],["71988.95000000","0.00000000"],["71989.27000000","0.00000000"],["71990.61000000","0.05263000"],["71990.99000000","0.41710000"],["71991.01000000","0.00000000"],["71992.09000000","0.04984000"],["71992.79000000","0.00000000"],["71992.88000000","0.00000000"],["71992.98000000","0.53059000"],["71993.15000000","0.07000000"],["71993.42000000","0.69882000"],["71993.45000000","0.00000000"],["71993.54000000","0.00000000"],["71994.68000000","0.00000000"],["71995.62000000","0.02000000"],["71995.92000000","0.00000000"],["71996.19000000","0.50000000"],["71997.30000000","2.07982000"],["71997.31000000","1.58498000"],["71997.32000000","0.12009000"],["71998.53000000","0.00000000"],["71998.69000000","0.03128000"],["71999.27000000","0.00000000"],["71999.71000000","0.00000000"],["72000.41000000","1.58498000"],["72000.69000000","0.69440000"],["72001.88000000","0.02820000"],["72002.64000000","0.00000000"],["72003.93000000","0.00000000"],["72004.15000000","0.00000000"],["72006.45000000","0.00000000"],["72006.49000000","0.00000000"],["72007.10000000","0.00000000"],["72007.20000000","0.00000000"],["72008.36000000","0.00000000"],["72008.54000000","0.00000000"],["72009.00000000","0.00000000"],["72010.80000000","0.00000000"],["72010.91000000","0.08755000"],["72011.78000000","0.00000000"],["72012.53000000","0.00000000"],["72012.60000000","0.00000000"],["72012.92000000","0.00000000"],["72013.41000000","0.00000000"],["72014.00000000","0.02872000"],["72014.40000000","0.00000000"],["72016.20000000","0.00000000"],["72017.29000000","0.00000000"],["72017.99000000","0.06096000"],["72022.92000000","0.00230000"],["72024.29000000","0.00000000"],["72027.95000000","0.00000000"],["72028.29000000","3.39035000"],["72032.34000000","0.00000000"],["72036.40000000","0.00000000"],["72036.41000000","0.00000000"],["72041.91000000","0.11114000"],["72044.31000000","1.66703000"],["72051.14000000","0.05557000"],["72057.69000000","0.00000000"],["72070.07000000","0.00000000"],["72070.08000000","0.00000000"],["72071.26000000","0.00000000"],["72076.73000000","0.00000000"],["72076.74000000","0.00000000"],["72145.84000000","0.03497000"],["72169.75000000","0.03497000"],["72195.25000000","0.00000000"],["72226.51000000","0.00000000"]]}
{"type":"depthUpdate","symbol":"BTCUSDT","event_time_ms":1775758315914,"first_update_id":91718179776,"final_update_id":91718179978,"bids":[["71977.68000000","0.22360000"],["71977.67000000","0.00040000"],["71976.29000000","0.00008000"],["71976.28000000","0.00000000"],["71976.10000000","0.00000000"],["71976.09000000","0.00000000"],["71975.96000000","0.00000000"],["71975.95000000","0.00000000"],["71975.33000000","0.00000000"],["71975.31000000","0.00000000"],["71975.25000000","0.00000000"],["71974.76000000","0.00000000"],["71974.50000000","0.00000000"],["71970.95000000","0.00000000"],["71970.75000000","0.00000000"],["71970.68000000","0.00008000"],["71970.67000000","0.00008000"],["71970.05000000","0.00000000"],["71970.04000000","0.00008000"],["71969.45000000","0.00016000"],["71969.44000000","0.02141000"],["71969.40000000","0.00000000"],["71969.29000000","0.00029000"],["71969.26000000","0.05496000"],["71968.98000000","0.00444000"],["71968.53000000","0.00016000"],["71968.25000000","0.00016000"],["71967.86000000","0.00000000"],["71967.60000000","0.00378000"],["71967.19000000","0.00047000"],["71967.10000000","0.00048000"],["71967.09000000","0.08631000"],["71967.06000000","0.00000000"],["71966.87000000","0.17858000"],["71965.96000000","0.00048000"],["71965.93000000","0.00189000"],["71964.44000000","0.00000000"],["71964.08000000","0.11758000"],["71963.94000000","0.00000000"],["71962.63000000","0.00694000"],["71961.54000000","0.11090000"],["71961.53000000","0.02000000"],["71961.37000000","0.00000000"],["71961.23000000","0.00829000"],["71960.99000000","0.00000000"],["71960.51000000","0.41710000"],["71960.20000000","1.58498000"],["71960.17000000","0.11758000"],["71960.16000000","0.15219000"],["71960.06000000","0.02000000"],["71959.68000000","0.00000000"],["71958.82000000","0.13004000"],["71958.17000000","0.00000000"],["71957.61000000","0.41710000"],["71957.51000000","0.00000000"],["71957.10000000","0.00000000"],["71956.76000000","2.60050000"],["71956.75000000","3.24770000"],["71956.74000000","0.00000000"],["71956.73000000","0.00000000"],["71954.66000000","0.00400000"],["71950.75000000","0.20848000"],["71949.81000000","0.00000000"],["71947.47000000","0.00400000"],["71940.27000000","0.00400000"],["71937.00000000","0.08358000"],["71934.65000000","0.00000000"],["71926.58000000","0.00000000"],["71901.51000000","0.00000000"],["71898.92000000","1.66703000"],["71897.31000000","0.21150000"],["71894.61000000","0.22228000"],["71885.65000000","0.00761000"],["71850.30000000","0.00000000"],["71847.28000000","0.52833000"],["71788.75000000","0.00000000"],["64779.92000000","0.00442000"],["64779.91000000","0.00000000"]],"asks":[["71977.69000000","2.87559000"],["71977.73000000","0.03574000"],["71977.74000000","0.08346000"],["71980.50000000","0.00781000"],["71981.48000000","0.00008000"],["71981.49000000","0.00015000"],["71981.63000000","0.01768000"],["71982.01000000","0.05278000"],["71982.10000000","0.00008000"],["71983.11000000","0.00007000"],["71983.26000000","0.00758000"],["71983.92000000","0.52273000"],["71983.93000000","0.00000000"],["71983.94000000","0.00000000"],["71984.87000000","0.11758000"],["71984.88000000","0.00000000"],["71984.89000000","0.19808000"],["71985.07000000","0.00007000"],["71985.08000000","0.00775000"],["71985.88000000","0.00000000"],["71985.89000000","1.09327000"],["71985.91000000","0.00000000"],["71985.93000000","0.01779000"],["71986.39000000","0.00000000"],["71986.75000000","0.00000000"],["71987.51000000","0.00000000"],["71987.57000000","0.00000000"],["71988.13000000","1.58498000"],["71989.81000000","0.03127000"],["71992.96000000","0.90441000"],["71992.97000000","1.58498000"],["71992.98000000","0.00000000"],["71993.15000000","0.00000000"],["72004.13000000","1.38290000"],["72018.49000000","0.00428000"],["72023.23000000","0.00000000"],["72025.92000000","1.91538000"],["72028.84000000","0.00000000"],["72031.76000000","0.00000000"],["72037.08000000","1.66703000"],["72039.15000000","0.05557000"],["72041.91000000","0.22228000"],["72044.31000000","0.00000000"],["72051.96000000","1.05222000"],["72054.69000000","0.00000000"],["72055.72000000","0.00000000"],["72061.44000000","0.00000000"],["72076.75000000","0.79390000"],["72220.77000000","0.00000000"]]}
{"type":"depthUpdate","symbol":"BTCUSDT","event_time_ms":1775758316014,"first_update_id":91718179979,"final_update_id":91718180095,"bids":[["71977.68000000","0.22489000"],["71977.67000000","0.00048000"],["71976.51000000","0.00000000"],["71976.30000000","0.00000000"],["71976.29000000","0.00000000"],["71972.92000000","0.00024000"],["71972.91000000","0.11624000"],["71970.69000000","0.09773000"],["71970.68000000","0.11110000"],["71970.67000000","0.00000000"],["71970.04000000","0.00000000"],["71969.44000000","0.02141000"],["71969.27000000","0.00016000"],["71969.26000000","0.00031000"],["71969.25000000","0.05008000"],["71968.53000000","0.00000000"],["71968.52000000","0.11076000"],["71968.25000000","0.00000000"],["71963.92000000","0.19191000"],["71960.52000000","0.11758000"],["71960.21000000","0.82929000"],["71960.17000000","0.00000000"],["71960.16000000","0.00000000"],["71954.63000000","0.14372000"],["71953.29000000","0.07000000"],["71947.43000000","0.07000000"],["71946.02000000","0.08000000"],["71938.90000000","0.50039000"],["64779.92000000","0.00459000"],["64779.00000000","0.00019000"],["57582.15000000","0.00034000"]],"asks":[["71977.69000000","2.46303000"],["71977.72000000","0.00016000"],["71977.73000000","0.14232000"],["71977.74000000","0.08346000"],["71977.92000000","0.00016000"],["71977.93000000","0.01767000"],["71978.67000000","0.00008000"],["71978.85000000","0.00000000"],["71980.19000000","0.00694000"],["71980.48000000","0.00000000"],["71980.49000000","0.34731000"],["71980.50000000","0.00781000"],["71981.48000000","0.00000000"],["71981.49000000","0.00007000"],["71982.01000000","0.05278000"],["71982.10000000","0.00000000"],["71982.60000000","0.08000000"],["71983.92000000","0.06629000"],["71984.87000000","0.00008000"],["71985.82000000","0.50007000"],["71985.89000000","0.57214000"],["71985.97000000","0.07000000"],["71986.63000000","0.00824000"],["71989.25000000","0.69849000"],["71989.34000000","0.07000000"],["71990.98000000","1.66272000"],["71993.51000000","0.14140000"],["71994.30000000","0.00000000"],["71999.69000000","0.00000000"],["72001.01000000","0.49996000"],["72003.49000000","0.00000000"]]}
{"type":"depthUpdate","symbol":"BTCUSDT","event_time_ms":1775758316114,"first_update_id":91718180096,"final_update_id":91718180179,"bids":[["71977.68000000","0.22345000"],["71972.92000000","0.00008000"],["71972.91000000","0.00030000"],["71970.70000000","0.11069000"],["71970.69000000","0.00032000"],["71970.68000000","0.11118000"],["71969.47000000","0.08331000"],["71969.44000000","0.02133000"],["71969.27000000","0.00000000"],["71969.26000000","0.00023000"],["71969.25000000","0.05015000"],["71968.53000000","0.00016000"],["71967.10000000","0.10509000"],["71967.09000000","0.00300000"],["71966.86000000","0.00000000"],["71964.08000000","0.00000000"],["71963.92000000","0.64699000"],["71963.08000000","1.58498000"],["71961.54000000","0.00029000"],["71960.52000000","0.00000000"],["71932.18000000","0.00000000"],["71909.70000000","0.75194000"],["64779.92000000","0.00442000"],["43457.47000000","0.00014000"],["43370.06000000","0.00000000"],["43323.95000000","0.00000000"],["43318.32000000","0.00000000"],["43311.85000000","0.00000000"],["43283.17000000","0.00000000"],["43278.37000000","0.00000000"],["43274.37000000","0.00000000"],["43271.42000000","0.00014000"],["43269.91000000","0.00000000"],["43101.86000000","0.00000000"]],"asks":[["71977.69000000","2.46303000"],["71977.74000000","0.08346000"],["71977.92000000","0.00000000"],["71977.93000000","0.01775000"],["71980.19000000","0.00702000"],["71980.49000000","0.34739000"],["71982.01000000","0.05285000"],["71983.26000000","0.00750000"],["71983.92000000","0.09155000"],["71984.87000000","0.11310000"],["71988.13000000","0.00000000"],["71988.93000000","1.58498000"],["71990.97000000","1.66272000"],["71990.98000000","0.00000000"],["71992.00000000","0.14077000"],["71993.51000000","0.00000000"]]}
{"type":"depthUpdate","symbol":"BTCUSDT","event_time_ms":1775758316214,"first_update_id":91718180180,"final_update_id":91718180246,"bids":[["71977.68000000","0.22383000"],["71972.91000000","0.00022000"],["71970.72000000","0.00024000"],["71970.71000000","0.00024000"],["71970.70000000","0.00016000"],["71970.69000000","0.00024000"],["71970.68000000","0.00015000"],["71969.48000000","0.00016000"],["71969.26000000","0.00007000"],["71968.53000000","0.00000000"],["71967.10000000","0.10501000"],["71963.93000000","0.00000000"],["71963.09000000","1.58498000"],["71963.08000000","0.00000000"],["71962.93000000","0.00008000"],["71961.99000000","0.02000000"],["71956.77000000","1.66272000"],["71956.76000000","1.42633000"],["71956.75000000","1.58498000"],["71954.63000000","0.00000000"],["71897.05000000","0.02000000"],["64779.92000000","0.00459000"],["57582.15000000","0.00000000"],["57582.14000000","0.00000000"]],"asks":[["71977.69000000","2.46303000"],["71977.72000000","0.00000000"],["71977.73000000","0.14216000"],["71990.49000000","0.10102000"],["71990.65000000","0.66008000"],["71992.00000000","0.00120000"],["71995.47000000","0.00000000"],["72009.77000000","0.02731000"],["72014.00000000","0.00120000"],["72155.40000000","0.05996000"]]}
{"type":"depthUpdate","symbol":"BTCUSDT","event_time_ms":1775758316314,"first_update_id":91718180247,"final_update_id":91718180291,"bids":[["71977.68000000","0.22390000"],["71977.67000000","0.00040000"],["71970.72000000","0.00008000"],["71970.71000000","0.00008000"],["71970.70000000","0.11069000"],["71970.69000000","0.00008000"],["71970.68000000","0.00007000"],["71969.49000000","0.00016000"],["71969.48000000","0.08661000"],["71969.47000000","0.08339000"],["71969.26000000","0.00023000"],["71968.53000000","0.00016000"],["71967.60000000","0.00078000"],["71964.08000000","0.11758000"],["71956.88000000","0.00433000"],["71935.20000000","0.00300000"],["71894.61000000","0.27785000"],["64779.92000000","0.00476000"],["57582.00000000","0.00300000"]],"asks":[["71977.69000000","2.81480000"],["71977.72000000","0.07619000"],["71977.73000000","0.00008000"],["71978.97000000","0.00444000"],["71980.49000000","0.00008000"],["71980.94000000","0.00008000"],["71984.88000000","0.00000000"],["71987.48000000","0.00000000"],["71993.62000000","0.00000000"],["72004.85000000","0.00271000"],["72065.92000000","0.03200000"]]}
{"type":"depthUpdate","symbol":"BTCUSDT","event_time_ms":1775758316414,"first_update_id":91718180292,"final_update_id":91718180335,"bids":[["71970.71000000","0.00024000"],["71968.53000000","0.00000000"],["71961.80000000","0.00007000"],["71961.37000000","0.02000000"],["71951.41000000","0.11933000"],["71934.01000000","0.00000000"],["71933.90000000","0.10429000"],["71932.15000000","0.40123000"],["71925.95000000","0.04701000"],["71914.51000000","0.00000000"],["71897.31000000","0.00000000"],["71849.66000000","0.01512000"],["71834.81000000","1.01844000"],["64779.92000000","0.00442000"],["64779.00000000","0.00019000"],["57582.00000000","0.00000000"]],"asks":[["71977.69000000","2.81480000"],["71977.72000000","0.04450000"],["71977.73000000","0.00000000"],["71977.74000000","0.08339000"],["71978.60000000","0.04000000"],["71980.19000000","0.00702000"],["71980.49000000","0.00000000"],["71982.60000000","0.08008000"],["71990.60000000","0.00007000"],["72027.75000000","0.04822000"],["72028.79000000","0.00000000"]]}
{"type":"depthUpdate","symbol":"BTCUSDT","event_time_ms":1775758316515,"first_update_id":91718180336,"final_update_id":91718180354,"bids":[["71953.55000000","0.10291000"],["71952.36000000","0.00000000"],["71952.01000000","0.00300000"],["71951.41000000","0.00000000"],["71933.90000000","0.00000000"],["71931.90000000","0.10212000"],["71895.35000000","0.21253000"],["64779.92000000","0.00442000"],["57582.15000000","0.00034000"]],"asks":[["71977.69000000","2.81480000"],["71977.93000000","0.01775000"],["71978.60000000","0.04008000"],["71982.60000000","0.08000000"]]}
{"type":"depthUpdate","symbol":"BTCUSDT","event_time_ms":1775758316614,"first_update_id":91718180355,"final_update_id":91718180369,"bids":[["71977.23000000","0.00008000"],["71963.92000000","1.06408000"],["71963.10000000","1.66272000"],["71958.42000000","0.02000000"],["71903.04000000","0.02000000"],["71897.05000000","0.00000000"],["64779.92000000","0.00459000"],["57582.15000000","0.00000000"]],"asks":[["71977.69000000","2.82869000"]]}
{"type":"depthUpdate","symbol":"BTCUSDT","event_time_ms":1775758316714,"first_update_id":91718180370,"final_update_id":91718180386,"bids":[["71947.80000000","0.00300000"],["71935.20000000","0.00000000"],["71930.99000000","0.00500000"],["64779.92000000","0.00493000"]],"asks":[["71977.69000000","2.82884000"],["71983.92000000","0.06621000"],["71984.87000000","0.00000000"],["72089.20000000","0.00277000"],["72102.95000000","0.01298000"]]}
{"type":"depthUpdate","symbol":"BTCUSDT","event_time_ms":1775758316814,"first_update_id":91718180387,"final_update_id":91718180407,"bids":[["71977.68000000","0.22350000"],["71970.70000000","0.11077000"],["71969.48000000","0.08669000"],["71969.44000000","0.02141000"],["71968.67000000","0.00000000"],["64779.92000000","0.00493000"]],"asks":[["71977.69000000","2.81485000"],["71996.83000000","0.40750000"],["72005.02000000","0.00000000"],["72012.22000000","0.00000000"]]}
{"type":"depthUpdate","symbol":"BTCUSDT","event_time_ms":1775758316914,"first_update_id":91718180408,"final_update_id":91718180427,"bids":[["71941.21000000","0.02000000"],["71931.10000000","1.16911000"],["71914.51000000","0.02000000"],["71903.74000000","0.02000000"],["71903.04000000","0.00000000"],["71895.36000000","0.21805000"],["71894.60000000","0.00112000"],["64779.92000000","0.00476000"]],"asks":[["71977.69000000","2.81485000"],["71994.13000000","0.00400000"],["72000.40000000","1.44583000"],["72000.42000000","0.00000000"],["72001.33000000","0.00400000"],["72037.07000000","0.60226000"],["72070.54000000","0.33969000"]]}
{"type":"depthUpdate","symbol":"BTCUSDT","event_time_ms":1775758317014,"first_update_id":91718180428,"final_update_id":91718180452,"bids":[["71963.93000000","0.41710000"],["71963.10000000","0.00000000"],["71953.55000000","0.00000000"],["71903.74000000","0.00000000"],["71801.62000000","0.00000000"],["71789.81000000","0.00825000"],["64779.92000000","0.00459000"],["57582.15000000","0.00034000"],["43188.00000000","0.00000000"],["43177.22000000","0.00000000"],["43172.03000000","0.00042000"],["43170.59000000","0.00000000"],["43151.87000000","0.00000000"],["43110.00000000","0.00778000"],["43106.16000000","0.00000000"],["43076.40000000","0.00000000"],["43068.90000000","0.00000000"]],"asks":[["71977.69000000","2.81485000"],["71989.40000000","0.12046000"],["71990.49000000","0.00000000"]]}
{"type":"depthUpdate","symbol":"BTCUSDT","event_time_ms":1775758317114,"first_update_id":91718180453,"final_update_id":91718180562,"bids":[["71970.71000000","0.00008000"],["71970.70000000","0.00016000"],["71969.49000000","0.00000000"],["71969.48000000","0.00008000"],["71969.47000000","0.00008000"],["71969.26000000","0.00007000"],["71969.25000000","0.00015000"],["71968.52000000","0.00015000"],["71968.25000000","0.00016000"],["71966.87000000","0.26189000"],["71965.81000000","0.00000000"],["71965.40000000","0.05007000"],["71964.08000000","0.00000000"],["71963.93000000","0.00000000"],["71963.92000000","0.17736000"],["71963.10000000","3.24770000"],["71963.09000000","0.00000000"],["71962.94000000","0.00694000"],["71962.63000000","0.00000000"],["71960.52000000","0.41710000"],["71960.51000000","0.00000000"],["71956.78000000","1.66272000"],["71956.77000000","0.00000000"],["71934.64000000","0.50042000"],["71931.90000000","0.00000000"],["71930.99000000","0.00000000"],["71925.95000000","0.00000000"],["71924.76000000","0.00000000"],["71924.29000000","0.00000000"],["71923.99000000","0.63903000"],["71922.52000000","0.00000000"],["71914.57000000","0.58853000"],["71895.36000000","0.00000000"],["71895.35000000","0.00000000"],["71885.65000000","0.00000000"],["71885.17000000","0.00000000"],["71884.45000000","0.41040000"],["71883.99000000","0.00000000"],["71863.35000000","0.06296000"],["71849.66000000","0.00000000"],["71848.47000000","0.00000000"],["71848.00000000","0.00000000"],["71786.20000000","0.00000000"],["71676.12000000","0.00000000"],["64779.92000000","0.00476000"]],"asks":[["71977.69000000","2.90072000"],["71977.72000000","0.08458000"],["71977.74000000","0.08346000"],["71977.92000000","0.00000000"],["71978.96000000","0.00000000"],["71979.28000000","0.00029000"],["71980.19000000","0.00008000"],["71981.77000000","0.04000000"],["71981.87000000","0.08000000"],["71981.99000000","0.00000000"],["71982.01000000","0.05292000"],["71982.59000000","0.39678000"],["71982.60000000","0.08007000"],["71982.77000000","0.50009000"],["71983.10000000","0.00000000"],["71983.92000000","0.00000000"],["71984.88000000","0.00000000"],["71985.81000000","0.00000000"],["71985.87000000","1.23858000"],["71985.88000000","2.00208000"],["71985.89000000","0.00000000"],["71987.75000000","0.02000000"],["71992.09000000","0.04984000"],["71995.62000000","0.00000000"],["71996.58000000","0.00000000"],["72001.01000000","0.00000000"],["72010.88000000","0.30251000"],["72012.45000000","0.00619000"],["72015.88000000","0.00436000"],["72019.71000000","0.58767000"],["72021.12000000","0.00000000"],["72021.88000000","0.00000000"],["72025.64000000","0.00000000"],["72027.78000000","0.00000000"],["72042.90000000","0.00000000"],["72079.98000000","0.06387000"],["72145.16000000","0.00000000"],["72207.30000000","0.00000000"]]}
{"type":"depthUpdate","symbol":"BTCUSDT","event_time_ms":1775758317214,"first_update_id":91718180563,"final_update_id":91718180634,"bids":[["71977.68000000","0.22343000"],["71970.70000000","0.00008000"],["71970.68000000","0.00000000"],["71969.48000000","0.00000000"],["71969.47000000","0.00000000"],["71969.44000000","0.02141000"],["71969.25000000","0.00007000"],["71968.52000000","0.00007000"],["71968.36000000","0.00016000"],["71968.35000000","0.10011000"],["71966.87000000","0.00015000"],["71965.84000000","0.00000000"],["71965.08000000","0.00000000"],["71964.60000000","0.00008000"],["71964.08000000","0.00000000"],["71963.92000000","1.12412000"],["71963.10000000","0.00000000"],["71962.94000000","0.00000000"],["71960.52000000","0.00000000"],["71960.20000000","0.00000000"],["71956.79000000","1.66272000"],["71956.78000000","0.00000000"],["71950.75000000","0.00008000"],["71948.12000000","0.12497000"],["71834.81000000","0.00000000"],["71783.61000000","0.03397000"],["71668.15000000","0.00036000"],["64779.92000000","0.00476000"],["57582.15000000","0.00000000"],["57582.14000000","0.00000000"],["43528.78000000","0.00126000"],["43495.13000000","0.00014000"],["43336.94000000","0.00000000"],["43319.95000000","0.00000000"],["43287.16000000","0.00000000"],["43282.80000000","0.00000000"],["43144.80000000","0.00014000"],["43130.99000000","0.00098000"],["43098.08000000","0.00014000"],["43069.67000000","0.00028000"]],"asks":[["71978.60000000","0.04008000"],["71979.28000000","0.00000000"],["71980.19000000","0.00000000"],["71981.63000000","0.01768000"],["71981.77000000","0.04008000"],["71981.87000000","0.08008000"],["71982.01000000","0.05277000"],["71982.58000000","0.11908000"],["71982.59000000","0.27671000"],["71984.74000000","0.00000000"],["71986.99000000","0.10368000"],["71989.40000000","0.00000000"],["72011.81000000","0.00425000"],["72029.80000000","0.01707000"],["72032.38000000","0.01060000"],["72045.46000000","0.00000000"],["72199.27000000","0.00035000"]]}
{"type":"depthUpdate","symbol":"BTCUSDT","event_time_ms":1775758317314,"first_update_id":91718180635,"final_update_id":91718180746,"bids":[["71977.68000000","0.22327000"],["71972.91000000","0.00008000"],["71970.70000000","0.11061000"],["71970.69000000","0.00000000"],["71969.44000000","0.02141000"],["71968.38000000","0.08331000"],["71968.37000000","0.00016000"],["71968.36000000","0.11675000"],["71968.35000000","0.10019000"],["71968.25000000","0.00000000"],["71966.54000000","0.18764000"],["71964.57000000","0.01725000"],["71964.31000000","0.00694000"],["71964.08000000","0.11758000"],["71963.98000000","1.66272000"],["71963.92000000","0.05078000"],["71963.60000000","0.00000000"],["71961.60000000","0.11061000"],["71961.59000000","0.02000000"],["71960.49000000","0.41710000"],["71960.23000000","0.91903000"],["71960.22000000","1.58498000"],["71960.21000000","0.00000000"],["71952.32000000","0.20840000"],["71950.92000000","0.12327000"],["71948.12000000","0.00000000"],["71914.34000000","0.00000000"],["71913.93000000","0.00000000"],["71900.08000000","0.00111000"],["71899.60000000","0.01084000"],["64779.92000000","0.00476000"],["64779.00000000","0.00019000"],["57582.14000000","0.00000000"]],"asks":[["71977.69000000","3.31043000"],["71977.73000000","0.00000000"],["71977.92000000","0.00000000"],["71978.96000000","0.00694000"],["71981.62000000","0.00040000"],["71982.01000000","0.05277000"],["71982.58000000","0.00000000"],["71982.77000000","0.00000000"],["71983.25000000","0.00000000"],["71986.99000000","0.00000000"],["71987.26000000","0.27734000"],["71989.06000000","0.20839000"],["71989.07000000","0.56950000"],["71990.05000000","0.00000000"],["71992.26000000","0.00068000"],["71995.47000000","0.00008000"],["71997.32000000","0.00000000"],["71999.15000000","0.00000000"],["72003.99000000","0.00000000"],["73088.00000000","1.02736000"],["73888.00000000","8.23486000"]]}
{"type":"depthUpdate","symbol":"BTCUSDT","event_time_ms":1775758317414,"first_update_id":91718180747,"final_update_id":91718180784,"bids":[["71977.68000000","0.22327000"],["71970.71000000","0.00024000"],["71970.70000000","0.00008000"],["71969.44000000","0.02141000"],["71968.40000000","0.00016000"],["71968.39000000","0.11575000"],["71968.38000000","0.08339000"],["71968.36000000","0.00008000"],["71968.35000000","0.00016000"],["71967.10000000","0.00048000"],["71964.08000000","0.00000000"],["71963.99000000","0.71716000"],["71963.92000000","0.00000000"],["71963.17000000","0.00000000"],["71961.60000000","0.00000000"],["71960.23000000","0.80145000"],["71930.94000000","0.50045000"],["64779.92000000","0.00459000"]],"asks":[["71978.60000000","0.04008000"],["71978.96000000","0.00702000"],["71981.87000000","0.08000000"],["71982.59000000","0.09287000"],["71982.60000000","0.08000000"],["72002.94000000","0.49995000"]]}
{"type":"depthUpdate","symbol":"BTCUSDT","event_time_ms":1775758317514,"first_update_id":91718180785,"final_update_id":91718180828,"bids":[["71977.68000000","0.22312000"],["71972.16000000","0.00000000"],["71970.71000000","0.00000000"],["71970.70000000","0.00000000"],["71969.44000000","0.02141000"],["71968.41000000","0.11786000"],["71968.40000000","0.11475000"],["71968.39000000","0.00024000"],["71968.38000000","0.08339000"],["71968.37000000","0.00000000"],["71968.36000000","0.00000000"],["71968.35000000","0.00008000"],["71964.00000000","0.42130000"],["71961.80000000","0.00007000"],["71959.97000000","0.00000000"],["71956.88000000","0.00000000"],["71947.78000000","0.00326000"],["71935.60000000","0.00000000"],["71923.41000000","0.00000000"],["71911.23000000","0.00326000"],["71899.04000000","0.00000000"],["64779.92000000","0.00476000"],["57582.15000000","0.00034000"]],"asks":[["71977.69000000","4.21073000"],["71980.30000000","0.02200000"],["71988.27000000","0.12944000"],["71990.60000000","0.00007000"],["71996.52000000","0.00000000"],["72004.85000000","0.00000000"],["72008.71000000","0.00000000"],["72020.88000000","0.00000000"],["72033.09000000","0.00000000"],["72045.27000000","0.00000000"],["72057.46000000","0.00326000"],["72069.64000000","0.00000000"],["72081.83000000","0.00000000"],["72094.02000000","0.00325000"],["72106.20000000","0.00000000"],["72118.39000000","0.00000000"],["72130.57000000","0.00325000"],["72142.76000000","0.00029000"]]}
{"type":"depthUpdate","symbol":"BTCUSDT","event_time_ms":1775758317614,"first_update_id":91718180829,"final_update_id":91718180886,"bids":[["71977.68000000","0.22311000"],["71977.67000000","0.00032000"],["71970.72000000","0.00000000"],["71970.60000000","0.00024000"],["71970.59000000","0.11024000"],["71969.44000000","0.02141000"],["71968.43000000","0.00016000"],["71968.42000000","0.06403000"],["71968.41000000","0.00024000"],["71968.40000000","0.11467000"],["71968.39000000","0.00016000"],["71966.55000000","0.11409000"],["71966.54000000","0.73147000"],["71964.01000000","1.58498000"],["71961.22000000","0.00000000"],["71958.86000000","0.00461000"],["71951.64000000","0.12349000"],["71950.92000000","0.00000000"],["71931.81000000","0.10419000"],["71923.82000000","0.04729000"],["71883.52000000","0.00742000"],["71847.54000000","0.01513000"],["71789.81000000","0.00000000"],["71773.63000000","0.00825000"],["64779.92000000","0.00476000"],["64779.00000000","0.00019000"],["57582.15000000","0.00000000"]],"asks":[["71978.96000000","0.00702000"],["71980.30000000","0.02208000"],["71981.77000000","0.04000000"],["71984.68000000","0.01389000"],["71990.01000000","0.00000000"],["72002.52000000","0.00273000"],["72138.39000000","0.10000000"],["72210.74000000","0.00000000"]]}
{"type":"depthUpdate","symbol":"BTCUSDT","event_time_ms":1775758317714,"first_update_id":91718180887,"final_update_id":91718180916,"bids":[["71977.68000000","0.22304000"],["71970.60000000","0.00008000"],["71970.59000000","0.00024000"],["71969.44000000","0.02141000"],["71968.43000000","0.04905000"],["71968.42000000","0.00008000"],["71968.41000000","0.00000000"],["71968.40000000","0.00008000"],["71968.25000000","0.00016000"],["71957.60000000","0.03000000"],["71956.40000000","0.08000000"],["71946.15000000","0.00000000"],["64779.92000000","0.00459000"],["57582.00000000","0.00300000"]],"asks":[["71977.69000000","4.21073000"],["72809.55000000","0.00000000"]]}
{"type":"depthUpdate","symbol":"BTCUSDT","event_time_ms":1775758317814,"first_update_id":91718180917,"final_update_id":91718180958,"bids":[["71977.68000000","0.22311000"],["71970.59000000","0.00009000"],["71969.44000000","0.02141000"],["71968.45000000","0.00016000"],["71968.44000000","0.11077000"],["71968.43000000","0.00008000"],["71968.42000000","0.00000000"],["71968.40000000","0.00000000"],["71968.25000000","0.00000000"],["71962.81000000","0.00000000"],["71955.62000000","0.00139000"],["71931.42000000","0.50045000"],["64779.92000000","0.00442000"],["57582.00000000","0.00000000"]],"asks":[["71977.69000000","4.21906000"],["71978.96000000","0.00008000"],["71984.41000000","0.00139000"],["71986.92000000","0.11110000"],["71988.27000000","0.00000000"],["71989.25000000","0.99883000"],["71992.65000000","0.50002000"],["72809.55000000","0.00040000"]]}
{"type":"depthUpdate","symbol":"BTCUSDT","event_time_ms":1775758317914,"first_update_id":91718180959,"final_update_id":91718181868,"bids":[["71977.68000000","0.00000000"],["71977.67000000","0.00000000"],["71977.23000000","0.00000000"],["71976.46000000","0.00000000"],["71976.08000000","0.00000000"],["71976.00000000","0.00000000"],["71975.79000000","0.00000000"],["71975.68000000","0.00000000"],["71975.24000000","0.00000000"],["71975.20000000","0.00000000"],["71974.86000000","0.00000000"],["71974.73000000","0.00000000"],["71974.00000000","0.00000000"],["71973.86000000","0.00000000"],["71973.74000000","0.00000000"],["71973.67000000","0.00000000"],["71972.92000000","0.00000000"],["71972.91000000","0.00000000"],["71972.52000000","0.00000000"],["71972.00000000","0.00000000"],["71971.97000000","0.00000000"],["71971.94000000","0.00000000"],["71971.69000000","0.00000000"],["71970.60000000","0.16576000"],["71970.59000000","0.00064000"],["71970.48000000","0.00000000"],["71969.93000000","0.00000000"],["71969.45000000","0.00024000"],["71969.44000000","0.02141000"],["71969.40000000","0.00000000"],["71969.29000000","0.00000000"],["71968.98000000","0.00000000"],["71968.76000000","0.00000000"],["71968.52000000","0.00000000"],["71968.45000000","0.00024000"],["71968.44000000","0.00015000"],["71968.43000000","0.00000000"],["71968.38000000","0.00015000"],["71968.25000000","0.00016000"],["71967.60000000","0.00070000"],["71967.23000000","0.00000000"],["71967.05000000","0.00008000"],["71966.87000000","0.00000000"],["71966.55000000","0.00007000"],["71966.54000000","0.00119000"],["71966.53000000","0.00000000"],["71966.23000000","0.00000000"],["71966.06000000","0.00000000"],["71965.93000000","0.00000000"],["71965.80000000","0.00000000"],["71965.41000000","0.00000000"],["71965.40000000","0.00007000"],["71964.78000000","0.00015000"],["71964.69000000","0.00000000"],["71964.57000000","0.00000000"],["71964.52000000","0.00444000"],["71964.31000000","0.00000000"],["71964.30000000","0.00000000"],["71964.07000000","0.00000000"],["71964.06000000","0.00000000"],["71964.01000000","0.00000000"],["71964.00000000","0.00420000"],["71963.98000000","0.00000000"],["71963.97000000","0.00000000"],["71963.70000000","0.00000000"],["71963.60000000","0.00000000"],["71963.52000000","0.08331000"],["71963.40000000","0.01736000"],["71963.34000000","0.00000000"],["71961.59000000","0.00000000"],["71961.53000000","0.00000000"],["71961.23000000","0.00000000"],["71960.49000000","0.00000000"],["71960.36000000","0.00138000"],["71960.22000000","0.00000000"],["71960.01000000","0.00000000"],["71959.70000000","0.00694000"],["71959.69000000","0.00000000"],["71959.59000000","0.02000000"],["71959.12000000","0.00000000"],["71958.43000000","0.00694000"],["71957.98000000","0.00000000"],["71957.84000000","0.00000000"],["71957.61000000","0.00000000"],["71957.60000000","0.00000000"],["71956.92000000","0.00000000"],["71956.80000000","1.66572000"],["71956.79000000","0.00000000"],["71956.75000000","0.00000000"],["71956.58000000","0.00000000"],["71956.40000000","0.00000000"],["71955.55000000","0.00000000"],["71955.54000000","0.00000000"],["71954.87000000","0.00000000"],["71954.86000000","0.00000000"],["71954.66000000","0.00000000"],["71954.58000000","0.00000000"],["71953.95000000","0.00146000"],["71953.71000000","0.00000000"],["71953.65000000","1.58498000"],["71953.60000000","0.15000000"],["71953.54000000","0.41744000"],["71953.38000000","0.00694000"],["71953.37000000","0.00000000"],["71953.29000000","0.00000000"],["71953.22000000","0.00000000"],["71952.98000000","0.00000000"],["71952.97000000","0.00000000"],["71952.56000000","0.00000000"],["71952.32000000","0.00000000"],["71951.64000000","0.00000000"],["71951.16000000","0.00836000"],["71950.81000000","0.00000000"],["71950.63000000","1.58498000"],["71950.54000000","0.41710000"],["71950.46000000","0.00444000"],["71949.97000000","0.00000000"],["71949.62000000","0.00000000"],["71949.42000000","0.00000000"],["71949.10000000","0.00000000"],["71948.88000000","0.00000000"],["71948.50000000","0.34731000"],["71948.24000000","0.00400000"],["71947.90000000","1.66272000"],["71947.78000000","0.00000000"],["71947.64000000","0.00000000"],["71947.47000000","0.00000000"],["71947.43000000","0.00000000"],["71946.44000000","0.20841000"],["71946.02000000","0.00000000"],["71945.42000000","0.00138000"],["71945.30000000","0.00000000"],["71945.07000000","1.58498000"],["71945.01000000","0.00000000"],["71945.00000000","0.00000000"],["71944.59000000","0.02000000"],["71943.80000000","0.07000000"],["71943.04000000","0.00000000"],["71942.40000000","0.08000000"],["71941.91000000","0.00000000"],["71941.81000000","0.04684000"],["71941.71000000","0.00000000"],["71941.05000000","0.00400000"],["71940.98000000","0.41710000"],["71940.69000000","0.03127000"],["71940.58000000","0.00000000"],["71940.48000000","0.00007000"],["71939.90000000","1.66272000"],["71939.89000000","0.00000000"],["71939.70000000","0.00000000"],["71938.64000000","0.00000000"],["71938.22000000","0.00139000"],["71936.92000000","0.00007000"],["71935.95000000","1.58508000"],["71934.93000000","0.00000000"],["71934.65000000","0.93779000"],["71934.52000000","0.34041000"],["71934.51000000","0.00000000"],["71934.50000000","0.00000000"],["71933.40000000","0.00300000"],["71931.81000000","0.00000000"],["71931.43000000","1.66272000"],["71931.09000000","0.00000000"],["71930.54000000","0.00007000"],["71929.50000000","0.00000000"],["71928.09000000","0.00000000"],["71927.47000000","0.00000000"],["71927.33000000","0.10444000"],["71923.96000000","0.50063000"],["71923.82000000","0.00000000"],["71922.56000000","0.00000000"],["71921.01000000","1.66272000"],["71920.37000000","0.00000000"],["71919.71000000","0.00000000"],["71918.81000000","0.00000000"],["71918.65000000","0.01154000"],["71917.62000000","0.00000000"],["71916.19000000","0.00000000"],["71914.60000000","0.00020000"],["71913.87000000","0.00009000"],["71912.01000000","0.00000000"],["71911.23000000","0.00000000"],["71910.46000000","0.00012000"],["71910.01000000","0.00000000"],["71909.00000000","0.00000000"],["71906.31000000","0.00346000"],["71902.58000000","0.00355000"],["71902.09000000","0.00000000"],["71897.91000000","0.69539000"],["71894.62000000","0.15449000"],["71893.50000000","0.00008000"],["71892.95000000","0.00000000"],["71891.26000000","0.00000000"],["71883.81000000","0.00000000"],["71883.52000000","0.00000000"],["71882.25000000","0.00000000"],["71881.77000000","1.58498000"],["71879.41000000","0.00000000"],["71878.51000000","0.00000000"],["71878.45000000","0.00000000"],["71878.35000000","0.00000000"],["71873.15000000","0.41710000"],["71873.13000000","1.58498000"],["71864.31000000","0.00000000"],["71847.54000000","0.00000000"],["71846.75000000","0.00015000"],["71846.27000000","0.00000000"],["71843.03000000","0.00000000"],["71842.40000000","0.00000000"],["71841.15000000","0.00015000"],["71840.22000000","0.00000000"],["71837.20000000","0.00000000"],["71836.17000000","0.05911000"],["71834.52000000","0.00138000"],["71831.53000000","0.00138000"],["71824.85000000","0.00000000"],["71819.08000000","0.04029000"],["71817.03000000","1.66272000"],["71809.74000000","0.00000000"],["71801.61000000","0.00000000"],["71801.01000000","0.00000000"],["71798.03000000","0.00000000"],["71793.68000000","0.00000000"],["71792.03000000","0.00000000"],["71790.32000000","0.03418000"],["71789.51000000","0.21506000"],["71785.62000000","0.03397000"],["71781.29000000","0.06794000"],["71776.88000000","0.03397000"],["71775.84000000","0.00007000"],["71689.09000000","0.19800000"],["71665.44000000","0.00008000"],["71643.75000000","0.00000000"],["71574.96000000","0.00029000"],["64779.92000000","0.00000000"],["64778.82000000","0.00000000"]],"asks":[["71970.61000000","3.16438000"],["71971.20000000","0.00300000"],["71971.60000000","0.00000000"],["71971.69000000","0.85948000"],["71971.70000000","0.00015000"],["71971.77000000","0.00000000"],["71971.85000000","0.00000000"],["71971.94000000","0.00000000"],["71971.95000000","0.04015000"],["71971.96000000","0.00000000"],["71972.52000000","0.00007000"],["71972.82000000","0.00000000"],["71972.91000000","0.00020000"],["71972.92000000","0.04015000"],["71973.00000000","0.00300000"],["71973.75000000","0.00000000"],["71973.87000000","0.00000000"],["71974.01000000","0.00000000"],["71974.74000000","0.00000000"],["71974.80000000","0.00300000"],["71974.87000000","1.68764000"],["71975.06000000","0.00000000"],["71975.07000000","0.00015000"],["71975.19000000","0.00000000"],["71975.21000000","0.00000000"],["71975.25000000","0.00000000"],["71975.67000000","0.00000000"],["71975.69000000","0.00000000"],["71975.80000000","0.00000000"],["71976.00000000","0.00000000"],["71976.01000000","0.00000000"],["71976.04000000","0.00000000"],["71976.08000000","0.00007000"],["71976.09000000","0.00000000"],["71976.13000000","0.00000000"],["71976.37000000","0.00000000"],["71976.46000000","0.00000000"],["71976.47000000","0.20466000"],["71976.60000000","0.00300000"],["71976.70000000","0.00000000"],["71977.24000000","0.00000000"],["71977.58000000","0.00000000"],["71977.67000000","0.00000000"],["71977.68000000","0.00024000"],["71977.69000000","1.38905000"],["71977.70000000","0.00000000"],["71977.72000000","0.00008000"],["71977.74000000","0.00007000"],["71977.93000000","0.01767000"],["71978.01000000","0.00007000"],["71978.07000000","0.01000000"],["71978.60000000","0.04000000"],["71978.67000000","0.02008000"],["71978.96000000","0.00000000"],["71979.94000000","0.00011000"],["71980.30000000","0.02200000"],["71980.50000000","0.00773000"],["71980.93000000","0.00694000"],["71980.94000000","0.00120000"],["71981.18000000","0.00007000"],["71981.22000000","0.00008000"],["71981.63000000","0.01760000"],["71981.77000000","0.04000000"],["71982.34000000","0.50009000"],["71982.60000000","0.00000000"],["71982.74000000","0.00138000"],["71984.26000000","0.69456000"],["71984.33000000","0.00326000"],["71984.41000000","0.00000000"],["71984.68000000","0.00000000"],["71985.01000000","0.04684000"],["71985.07000000","0.00000000"],["71985.18000000","0.00068000"],["71985.34000000","0.00008000"],["71985.47000000","0.00000000"],["71985.72000000","0.07000000"],["71985.97000000","0.00000000"],["71986.57000000","0.00000000"],["71987.69000000","0.00000000"],["71987.77000000","0.00000000"],["71989.34000000","0.00000000"],["71990.06000000","0.00029000"],["71990.65000000","0.66000000"],["71991.50000000","0.00000000"],["71992.09000000","0.00300000"],["71992.22000000","0.00138000"],["71992.26000000","0.00000000"],["71992.29000000","0.00000000"],["71993.47000000","0.00000000"],["71995.07000000","0.00008000"],["71995.08000000","0.00000000"],["71996.19000000","0.00000000"],["71996.77000000","0.00000000"],["71997.14000000","0.00138000"],["71997.29000000","1.17566000"],["71997.89000000","0.00012000"],["72000.00000000","0.00128000"],["72001.80000000","0.00000000"],["72002.13000000","0.00000000"],["72002.62000000","0.00000000"],["72002.94000000","0.00000000"],["72003.06000000","0.00000000"],["72003.60000000","0.00000000"],["72004.94000000","0.00012000"],["72005.40000000","0.00000000"],["72005.87000000","0.02696000"],["72006.88000000","0.00000000"],["72008.12000000","0.00000000"],["72009.77000000","0.00000000"],["72010.07000000","0.00000000"],["72010.44000000","0.00000000"],["72011.68000000","0.00000000"],["72011.76000000","0.00000000"],["72012.90000000","0.00000000"],["72017.03000000","0.00000000"],["72018.81000000","1.37182000"],["72020.34000000","0.10537000"],["72020.90000000","0.00000000"],["72023.62000000","0.04734000"],["72023.98000000","0.00000000"],["72025.91000000","0.00344000"],["72027.75000000","0.00000000"],["72027.76000000","0.00347000"],["72031.35000000","0.00000000"],["72031.77000000","0.00000000"],["72033.66000000","0.00000000"],["72039.18000000","0.00000000"],["72048.32000000","0.00000000"],["72054.69000000","0.14626000"],["72057.46000000","0.00000000"],["72066.60000000","0.00000000"],["72067.76000000","0.00000000"],["72068.70000000","0.00000000"],["72075.62000000","0.00000000"],["72075.74000000","0.00000000"],["72084.88000000","0.00000000"],["72094.02000000","0.00000000"],["72097.07000000","0.00138000"],["72103.16000000","0.00000000"],["72103.41000000","0.00000000"],["72112.30000000","0.00000000"],["72121.43000000","0.00000000"],["72124.14000000","0.00000000"],["72130.57000000","0.00000000"],["72139.71000000","0.00000000"],["72147.55000000","0.00000000"],["72148.85000000","0.00000000"],["72157.99000000","0.00000000"],["72188.05000000","0.00000000"],["72352.40000000","0.00000000"],["73751.78000000","0.00619000"]]}
{"type":"depthUpdate","symbol":"BTCUSDT","event_time_ms":1775758318014,"first_update_id":91718181869,"final_update_id":91718182177,"bids":[["71970.60000000","0.56773000"],["71970.59000000","0.00064000"],["71969.44000000","0.02141000"],["71969.26000000","0.00000000"],["71969.25000000","0.00000000"],["71968.45000000","0.00008000"],["71968.44000000","0.00007000"],["71968.39000000","0.00000000"],["71968.38000000","0.00007000"],["71968.25000000","0.00008000"],["71968.24000000","0.00008000"],["71967.60000000","0.00000000"],["71967.19000000","0.00000000"],["71967.05000000","0.00016000"],["71967.04000000","0.02291000"],["71966.56000000","0.00000000"],["71966.55000000","0.00007000"],["71966.45000000","0.00000000"],["71966.44000000","0.00015000"],["71966.00000000","0.10720000"],["71965.96000000","0.00000000"],["71965.40000000","0.00030000"],["71965.39000000","0.08015000"],["71964.02000000","0.00016000"],["71964.01000000","0.17357000"],["71964.00000000","0.00120000"],["71963.99000000","0.00015000"],["71963.53000000","0.05420000"],["71963.52000000","0.08339000"],["71963.40000000","0.01744000"],["71961.33000000","0.00070000"],["71960.41000000","0.15546000"],["71960.24000000","0.53669000"],["71960.23000000","1.12572000"],["71959.36000000","0.00025000"],["71957.19000000","0.00048000"],["71957.07000000","0.00048000"],["71956.80000000","3.66780000"],["71956.76000000","0.99868000"],["71955.89000000","0.00189000"],["71955.13000000","0.00000000"],["71951.89000000","0.00138000"],["71951.57000000","0.04170000"],["71949.43000000","0.70856000"],["71947.35000000","0.07000000"],["71946.43000000","0.00000000"],["71945.08000000","0.61881000"],["71944.86000000","0.00000000"],["71944.68000000","0.14584000"],["71944.66000000","0.14751000"],["71941.50000000","0.80664000"],["71938.46000000","0.57254000"],["71934.66000000","0.66456000"],["71934.65000000","0.41710000"],["71931.60000000","0.00300000"],["71931.58000000","0.00029000"],["71931.44000000","1.46536000"],["71931.10000000","0.00011000"],["71929.37000000","0.00000000"],["71928.96000000","0.00000000"],["71924.62000000","0.00000000"],["71924.49000000","0.00000000"],["71923.99000000","1.20051000"],["71920.77000000","0.87145000"],["71918.30000000","0.00628000"],["71917.91000000","0.00424000"],["71913.80000000","0.00433000"],["71913.79000000","1.66272000"],["71913.63000000","0.00425000"],["71895.55000000","0.00011000"],["71894.62000000","0.08337000"],["71894.59000000","0.00000000"],["71884.70000000","0.23507000"],["71884.45000000","0.96343000"],["71873.73000000","1.18123000"],["71844.69000000","0.15945000"],["71760.59000000","0.00015000"],["71757.00000000","0.00015000"],["71740.30000000","0.00000000"],["71681.67000000","0.01885000"],["64773.54000000","0.00034000"],["57576.48000000","0.00034000"]],"asks":[["71970.61000000","3.19089000"],["71971.67000000","0.00016000"],["71971.68000000","0.02819000"],["71971.69000000","0.00028000"],["71971.95000000","0.00015000"],["71972.51000000","0.00000000"],["71972.91000000","0.00036000"],["71972.92000000","0.00015000"],["71973.03000000","0.00016000"],["71973.04000000","0.04000000"],["71974.79000000","0.01388000"],["71974.85000000","0.00016000"],["71974.86000000","0.81810000"],["71974.87000000","0.00008000"],["71975.07000000","0.00007000"],["71976.46000000","0.00041000"],["71976.47000000","0.20473000"],["71976.65000000","0.08007000"],["71977.68000000","0.00016000"],["71977.69000000","0.99162000"],["71977.72000000","0.00000000"],["71977.74000000","0.00000000"],["71977.93000000","0.01775000"],["71978.60000000","0.00000000"],["71978.66000000","0.09773000"],["71979.08000000","0.00000000"],["71979.09000000","0.00000000"],["71979.38000000","0.00000000"],["71979.57000000","0.01389000"],["71979.58000000","0.00015000"],["71980.02000000","0.07000000"],["71980.93000000","0.00000000"],["71981.37000000","0.06946000"],["71981.50000000","0.00000000"],["71981.62000000","0.00000000"],["71981.66000000","0.00000000"],["71982.01000000","0.05263000"],["71982.33000000","0.43816000"],["71982.59000000","0.00000000"],["71983.11000000","0.00000000"],["71983.13000000","0.00000000"],["71983.17000000","0.00015000"],["71985.01000000","0.00000000"],["71987.27000000","0.00000000"],["71989.07000000","0.50005000"],["71992.56000000","0.00121000"],["71993.82000000","0.92503000"],["71996.59000000","0.21805000"],["71996.79000000","0.08000000"],["71997.36000000","0.00000000"],["71998.16000000","0.49998000"],["72000.40000000","0.99568000"],["72001.67000000","0.00000000"],["72002.52000000","0.00000000"],["72003.67000000","0.00000000"],["72005.17000000","0.00000000"],["72007.22000000","0.89927000"],["72011.78000000","0.85271000"],["72014.58000000","0.71223000"],["72015.08000000","0.00218000"],["72023.20000000","0.63996000"],["72023.22000000","0.00000000"],["72084.03000000","0.00000000"],["72192.51000000","0.00000000"],["72195.78000000","0.00000000"],["72198.09000000","0.00000000"]]}
{"type":"depthUpdate","symbol":"BTCUSDT","event_time_ms":1775758318114,"first_update_id":91718182178,"final_update_id":91718182281,"bids":[["71970.60000000","0.47046000"],["71970.59000000","0.00080000"],["71969.44000000","0.02141000"],["71968.25000000","0.00000000"],["71968.24000000","0.00000000"],["71967.05000000","0.00024000"],["71967.04000000","0.02291000"],["71966.65000000","0.00000000"],["71966.44000000","0.00007000"],["71966.02000000","0.11826000"],["71966.01000000","0.10985000"],["71966.00000000","0.10728000"],["71965.39000000","0.08015000"],["71964.02000000","0.00000000"],["71964.01000000","0.17372000"],["71963.99000000","0.00007000"],["71963.53000000","0.09368000"],["71962.97000000","0.00015000"],["71960.06000000","0.00000000"],["71955.62000000","0.00000000"],["71953.51000000","0.00000000"],["71951.57000000","0.00000000"],["71951.48000000","0.00000000"],["71951.47000000","0.00000000"],["71951.46000000","0.04170000"],["71947.07000000","0.13352000"],["71941.22000000","0.00120000"],["71916.41000000","1.22020000"],["71858.04000000","0.00000000"],["71827.76000000","0.05896000"],["71783.62000000","0.00825000"],["71783.07000000","6.46471000"],["71773.63000000","0.00000000"],["71574.96000000","0.00000000"],["71337.24000000","0.00349000"],["71331.31000000","0.00349000"],["71273.81000000","0.00366000"],["69882.67000000","0.00000000"],["69878.17000000","0.00000000"],["69812.78000000","0.00357000"],["64773.54000000","0.00068000"]],"asks":[["71970.61000000","3.19143000"],["71971.68000000","0.01837000"],["71971.95000000","0.00007000"],["71972.91000000","0.00020000"],["71972.92000000","0.00007000"],["71973.04000000","0.04008000"],["71974.78000000","0.00016000"],["71974.79000000","0.01396000"],["71974.85000000","0.00016000"],["71974.86000000","0.67948000"],["71974.87000000","0.00000000"],["71976.47000000","0.00665000"],["71976.64000000","0.00008000"],["71977.69000000","0.99141000"],["71981.49000000","0.00000000"],["71985.18000000","0.00000000"],["71985.95000000","0.13017000"],["71986.92000000","0.00000000"],["72011.14000000","0.00240000"],["72136.92000000","6.52796000"]]}
{"type":"depthUpdate","symbol":"BTCUSDT","event_time_ms":1775758318214,"first_update_id":91718182282,"final_update_id":91718182346,"bids":[["71970.60000000","0.47076000"],["71970.59000000","0.00088000"],["71967.04000000","0.02283000"],["71966.04000000","0.11726000"],["71966.03000000","0.17796000"],["71966.02000000","0.11810000"],["71966.01000000","0.00016000"],["71966.00000000","0.00135000"],["71965.89000000","0.08331000"],["71965.40000000","0.00014000"],["71964.01000000","0.05015000"],["71963.99000000","0.00000000"],["71963.53000000","0.05420000"],["71963.52000000","0.00000000"],["71963.40000000","0.01736000"],["71955.13000000","0.02000000"],["71955.04000000","0.02000000"],["71954.42000000","0.02000000"],["71954.40000000","0.02000000"],["71954.32000000","0.04200000"],["71954.05000000","0.02000000"],["71953.69000000","0.02000000"],["71951.89000000","0.02138000"],["71890.88000000","0.02000000"],["71890.78000000","0.02000000"],["71890.16000000","0.04000000"],["71890.07000000","0.04200000"],["71889.80000000","0.02000000"],["71889.44000000","0.02000000"],["71887.63000000","0.02000000"],["71337.24000000","0.00000000"],["71273.81000000","0.00716000"],["71036.30000000","0.00351000"],["71034.98000000","0.00351000"],["70892.36000000","0.00704000"],["70891.04000000","0.00352000"],["64773.54000000","0.00102000"],["57576.48000000","0.00000000"]],"asks":[["71974.86000000","0.67956000"],["71976.47000000","0.00673000"],["71976.64000000","0.00000000"],["71976.65000000","0.08015000"],["76925.96000000","0.00000000"]]}
{"type":"depthUpdate","symbol":"BTCUSDT","event_time_ms":1775758318314,"first_update_id":91718182347,"final_update_id":91718182439,"bids":[["71970.60000000","0.47066000"],["71970.59000000","0.00080000"],["71969.28000000","0.00008000"],["71967.04000000","0.02291000"],["71966.06000000","0.26305000"],["71966.05000000","0.00016000"],["71966.04000000","0.11718000"],["71966.03000000","0.00008000"],["71966.02000000","0.00008000"],["71966.01000000","0.00000000"],["71966.00000000","0.00127000"],["71965.90000000","0.00008000"],["71965.89000000","0.08339000"],["71965.39000000","0.08008000"],["71963.53000000","0.05412000"],["71960.86000000","0.00000000"],["71954.77000000","0.02000000"],["71953.67000000","0.00139000"],["71948.92000000","0.11277000"],["71947.07000000","0.00000000"],["71934.66000000","0.38552000"],["71932.15000000","0.00000000"],["71909.70000000","0.00000000"],["71908.54000000","0.02000000"],["71889.80000000","0.00000000"],["71331.31000000","0.00000000"],["71272.48000000","0.01050000"],["71034.98000000","0.00702000"],["70891.04000000","0.01056000"],["70532.50000000","0.00413000"],["70531.19000000","0.00706000"],["70172.64000000","0.00355000"],["70171.33000000","0.00718000"],["69884.76000000","0.00000000"],["69812.78000000","0.00714000"],["69811.48000000","0.00714000"],["64773.54000000","0.00136000"],["57576.48000000","0.00000000"]],"asks":[["71970.61000000","3.19134000"],["71970.62000000","0.00008000"],["71971.69000000","0.00020000"],["71971.70000000","0.00007000"],["71975.26000000","0.00139000"],["71976.65000000","0.08022000"],["71976.96000000","0.12918000"],["71978.67000000","0.02000000"],["71979.39000000","0.00000000"],["71982.45000000","0.00139000"],["71984.88000000","1.66272000"],["71988.94000000","0.00000000"],["71990.65000000","0.00000000"],["71999.40000000","0.04684000"],["72025.45000000","0.03200000"],["76925.96000000","0.01327000"]]}
{"type":"depthUpdate","symbol":"BTCUSDT","event_time_ms":1775758318415,"first_update_id":91718182440,"final_update_id":91718182514,"bids":[["71970.60000000","0.47058000"],["71970.59000000","0.00072000"],["71968.35000000","0.00000000"],["71967.09000000","0.00000000"],["71967.04000000","0.02291000"],["71966.08000000","0.18288000"],["71966.07000000","0.10583000"],["71966.06000000","0.10525000"],["71966.05000000","0.00000000"],["71966.04000000","0.00008000"],["71966.03000000","0.00000000"],["71966.02000000","0.00000000"],["71963.53000000","0.05420000"],["71957.50000000","0.00008000"],["71956.20000000","0.00300000"],["71944.59000000","0.00000000"],["71918.55000000","0.04810000"],["71908.54000000","0.00000000"],["71890.88000000","0.00000000"],["71890.07000000","0.02000000"],["71878.25000000","0.00766000"],["71842.27000000","0.01478000"],["71818.36000000","1.01844000"],["71393.48000000","0.00027000"],["71034.98000000","0.01404000"],["70891.04000000","0.01760000"],["70531.19000000","0.01412000"],["70171.33000000","0.01073000"],["64773.54000000","0.00187000"]],"asks":[["71973.71000000","0.00008000"],["71976.65000000","0.08022000"],["71976.96000000","0.12926000"],["71977.81000000","0.00300000"],["71977.93000000","0.01767000"],["71980.94000000","0.00112000"],["71982.33000000","0.86470000"],["71985.01000000","0.00000000"],["71992.09000000","0.00000000"],["71999.40000000","0.01561000"],["72065.92000000","0.00000000"],["72566.73000000","0.00000000"]]}
{"type":"depthUpdate","symbol":"BTCUSDT","event_time_ms":1775758318514,"first_update_id":91718182515,"final_update_id":91718182771,"bids":[["71970.60000000","1.44640000"],["71970.59000000","0.00032000"],["71969.49000000","0.08331000"],["71968.97000000","0.00029000"],["71967.10000000","0.00000000"],["71967.04000000","0.02291000"],["71966.10000000","0.23774000"],["71966.09000000","0.11477000"],["71966.08000000","0.00008000"],["71966.07000000","0.00008000"],["71966.06000000","0.00008000"],["71966.04000000","0.00000000"],["71965.90000000","0.00008000"],["71965.89000000","0.00008000"],["71965.39000000","0.08015000"],["71964.01000000","0.00015000"],["71963.55000000","0.09985000"],["71963.54000000","0.10171000"],["71963.53000000","0.00000000"],["71963.43000000","0.41710000"],["71963.36000000","1.58498000"],["71961.80000000","0.00000000"],["71961.50000000","0.00020000"],["71961.33000000","0.00000000"],["71960.26000000","1.99357000"],["71960.25000000","1.58498000"],["71960.24000000","0.41710000"],["71960.23000000","0.00000000"],["71959.71000000","0.00694000"],["71958.86000000","0.00000000"],["71958.31000000","0.05263000"],["71954.72000000","0.00014000"],["71953.41000000","0.07000000"],["71953.38000000","0.00000000"],["71951.46000000","0.00000000"],["71949.65000000","0.10099000"],["71948.92000000","0.00000000"],["71947.56000000","0.07000000"],["71947.35000000","0.00000000"],["71946.16000000","0.08000000"],["71945.90000000","0.50035000"],["71945.09000000","0.41710000"],["71943.80000000","0.00000000"],["71942.40000000","0.00300000"],["71942.30000000","0.50037000"],["71935.20000000","0.00300000"],["71934.93000000","0.60410000"],["71934.92000000","0.69503000"],["71934.66000000","0.00000000"],["71933.95000000","0.02734000"],["71933.40000000","0.00000000"],["71931.60000000","0.00000000"],["71930.94000000","0.00000000"],["71923.96000000","0.00013000"],["71922.80000000","0.39853000"],["71914.60000000","0.00000000"],["71900.32000000","0.75649000"],["71897.91000000","0.00000000"],["71890.07000000","0.00000000"],["71846.31000000","0.00217000"],["71272.48000000","0.01400000"],["71034.98000000","0.01755000"],["70891.04000000","0.02112000"],["70531.19000000","0.01765000"],["70171.33000000","0.01783000"],["69811.48000000","0.01071000"],["64773.54000000","0.00221000"],["57576.48000000","0.00034000"]],"asks":[["71970.61000000","2.27185000"],["71971.67000000","0.00000000"],["71971.68000000","0.00015000"],["71971.69000000","0.00000000"],["71972.88000000","0.00000000"],["71972.91000000","0.00000000"],["71973.03000000","0.00016000"],["71974.78000000","0.00000000"],["71974.79000000","0.00008000"],["71974.85000000","0.00000000"],["71974.86000000","0.00008000"],["71975.87000000","0.08331000"],["71976.05000000","0.00826000"],["71976.07000000","0.00694000"],["71976.45000000","0.42998000"],["71976.46000000","0.34732000"],["71976.64000000","0.00000000"],["71976.65000000","0.00022000"],["71976.95000000","0.00016000"],["71977.67000000","0.00694000"],["71977.68000000","0.00032000"],["71977.69000000","0.91248000"],["71978.65000000","0.00048000"],["71978.66000000","0.09766000"],["71980.02000000","0.00000000"],["71980.32000000","0.00190000"],["71982.33000000","0.09167000"],["71982.34000000","0.00000000"],["71982.74000000","0.08138000"],["71983.52000000","0.00007000"],["71984.26000000","0.00000000"],["71984.88000000","0.00000000"],["71985.72000000","0.00000000"],["71985.82000000","0.00000000"],["71985.87000000","0.32797000"],["71985.88000000","0.00000000"],["71985.95000000","0.00000000"],["71986.10000000","0.07000000"],["71986.63000000","0.00000000"],["71988.14000000","0.20951000"],["71988.93000000","0.00000000"],["71989.06000000","0.00000000"],["71989.07000000","0.00000000"],["71989.25000000","0.30034000"],["71989.47000000","0.07000000"],["71990.60000000","0.00000000"],["71990.97000000","0.00000000"],["71990.99000000","0.00000000"],["71992.95000000","0.41710000"],["71992.97000000","0.00000000"],["71993.41000000","1.58498000"],["71997.28000000","3.66480000"],["71997.29000000","0.00000000"],["71997.30000000","0.00000000"],["71997.31000000","0.00000000"],["71997.62000000","0.49999000"],["72000.39000000","2.00208000"],["72000.40000000","0.00000000"],["72000.41000000","0.00000000"],["72001.66000000","0.00000000"],["72004.11000000","1.53736000"],["72004.12000000","3.66480000"],["72004.13000000","0.00000000"],["72004.14000000","0.00000000"],["72004.82000000","0.00000000"],["72004.83000000","0.00000000"],["72006.52000000","0.50000000"],["72007.22000000","1.28065000"],["72008.91000000","0.00010000"],["72010.02000000","1.66272000"],["72011.78000000","0.00000000"],["72011.79000000","0.41710000"],["72015.17000000","0.00020000"],["72016.21000000","0.00020000"],["72018.80000000","1.66272000"],["72018.82000000","0.00000000"],["72021.36000000","0.69420000"],["72037.08000000","0.00000000"],["72057.86000000","1.02055000"],["72060.61000000","1.58498000"],["72188.05000000","0.19800000"],["72566.73000000","0.00255000"]]}
{"type":"depthUpdate","symbol":"BTCUSDT","event_time_ms":1775758318614,"first_update_id":91718182772,"final_update_id":91718182932,"bids":[["71970.60000000","1.44745000"],["71970.59000000","0.00048000"],["71969.51000000","0.00024000"],["71969.50000000","0.03215000"],["71969.49000000","0.08353000"],["71968.97000000","0.00000000"],["71967.04000000","0.02291000"],["71966.12000000","0.09957000"],["71966.11000000","0.00008000"],["71966.10000000","0.00008000"],["71966.09000000","0.00008000"],["71966.08000000","0.00000000"],["71966.07000000","0.00000000"],["71966.06000000","0.00000000"],["71966.00000000","0.00120000"],["71965.90000000","0.00000000"],["71965.89000000","0.00000000"],["71965.40000000","0.00014000"],["71965.39000000","0.08015000"],["71964.01000000","0.00000000"],["71963.57000000","1.32417000"],["71963.56000000","1.66272000"],["71963.55000000","0.00015000"],["71963.54000000","0.00000000"],["71960.41000000","0.00000000"],["71960.26000000","1.87348000"],["71940.30000000","0.00202000"],["71906.43000000","0.00008000"],["71902.57000000","0.54620000"],["71890.78000000","0.00000000"],["71890.16000000","0.00000000"],["71889.44000000","0.00000000"],["71887.63000000","0.00000000"],["71272.49000000","0.01050000"],["71272.48000000","0.01750000"],["71034.98000000","0.03159000"],["70891.04000000","0.03872000"],["70531.19000000","0.02824000"],["70171.33000000","0.02848000"],["69811.48000000","0.01785000"],["64779.00000000","0.00009000"],["64773.54000000","0.00255000"],["64773.00000000","0.00010000"],["57576.48000000","0.00000000"]],"asks":[["71970.61000000","2.30688000"],["71971.68000000","0.00000000"],["71973.04000000","0.04008000"],["71974.79000000","0.00000000"],["71974.86000000","0.00000000"],["71975.86000000","0.00016000"],["71975.87000000","0.08346000"],["71976.05000000","0.00834000"],["71976.07000000","0.00702000"],["71976.44000000","0.00016000"],["71976.45000000","0.43006000"],["71976.46000000","0.34740000"],["71976.47000000","0.00673000"],["71976.65000000","0.00014000"],["71976.96000000","0.12926000"],["71977.68000000","0.00016000"],["71977.69000000","0.91240000"],["71978.45000000","0.00008000"],["71978.65000000","0.00040000"],["71981.35000000","0.01389000"],["71984.58000000","0.54096000"],["71985.87000000","0.24091000"],["71997.27000000","1.47786000"],["72000.38000000","0.99640000"],["72000.89000000","0.00241000"],["72010.90000000","0.41830000"],["72037.07000000","0.10458000"],["72061.55000000","0.00000000"],["72164.34000000","0.04197000"]]}
{"type":"depthUpdate","symbol":"BTCUSDT","event_time_ms":1775758318714,"first_update_id":91718182933,"final_update_id":91718182990,"bids":[["71970.60000000","1.44738000"],["71969.50000000","0.03223000"],["71969.49000000","0.08353000"],["71967.04000000","0.02291000"],["71966.14000000","0.07378000"],["71966.13000000","0.10022000"],["71966.12000000","0.00008000"],["71966.11000000","0.00000000"],["71966.10000000","0.00000000"],["71966.09000000","0.00000000"],["71965.39000000","0.08022000"],["71964.00000000","0.00420000"],["71963.58000000","0.10601000"],["71963.55000000","0.00007000"],["71953.01000000","0.11034000"],["71949.65000000","0.00000000"],["71935.20000000","0.00000000"],["71924.49000000","0.00500000"],["71858.53000000","0.00217000"],["71783.62000000","0.00000000"],["71776.89000000","0.00825000"],["71034.98000000","0.03510000"],["70891.04000000","0.04224000"],["70531.19000000","0.03177000"],["70171.33000000","0.03203000"],["69811.48000000","0.02142000"],["64773.54000000","0.00289000"]],"asks":[["71970.61000000","2.01233000"],["71971.20000000","0.00000000"],["71982.33000000","0.24145000"],["71987.75000000","0.00000000"],["71991.88000000","0.12350000"],["71993.08000000","0.02000000"],["72003.60000000","0.00300000"],["72053.27000000","0.01852000"],["72094.54000000","0.12000000"]]}
{"type":"depthUpdate","symbol":"BTCUSDT","event_time_ms":1775758318814,"first_update_id":91718182991,"final_update_id":91718183009,"bids":[["71969.49000000","0.08353000"],["71967.04000000","0.02291000"],["71966.15000000","0.00008000"],["71966.14000000","0.07386000"],["71966.13000000","0.10030000"],["71966.12000000","0.00000000"],["71965.39000000","0.08014000"],["71870.75000000","0.00217000"],["64773.54000000","0.00323000"]],"asks":[["71970.61000000","2.09858000"],["71991.11000000","0.13676000"],["71991.88000000","0.00000000"],["71999.40000000","0.04684000"],["72102.69000000","1.89103000"]]}
{"type":"depthUpdate","symbol":"BTCUSDT","event_time_ms":1775758318914,"first_update_id":91718183010,"final_update_id":91718183025,"bids":[["71902.57000000","0.38009000"],["71900.32000000","0.00000000"],["71882.97000000","0.00217000"],["71831.03000000","0.00326000"],["64773.54000000","0.00357000"],["64773.00000000","0.00010000"]],"asks":[["71970.61000000","2.30170000"],["71974.85000000","0.00007000"],["71981.35000000","0.00000000"],["71990.33000000","0.11509000"],["71991.11000000","0.00000000"],["72023.62000000","0.00000000"]]}
{"type":"depthUpdate","symbol":"BTCUSDT","event_time_ms":1775758319014,"first_update_id":91718183026,"final_update_id":91718183044,"bids":[["71970.60000000","1.41446000"],["71966.15000000","0.06240000"],["71966.14000000","0.00016000"],["71952.28000000","0.02000000"],["71903.74000000","0.00000000"],["71895.18000000","0.00217000"],["71879.92000000","0.00007000"],["71840.20000000","0.00326000"],["71734.99000000","0.02204000"],["71710.22000000","0.00000000"],["64773.54000000","0.00408000"],["57576.48000000","0.00034000"]],"asks":[["71979.20000000","0.00008000"],["71989.25000000","0.72469000"],["71990.32000000","1.58505000"],["71995.47000000","0.00000000"]]}
{"type":"depthUpdate","symbol":"BTCUSDT","event_time_ms":1775758319114,"first_update_id":91718183045,"final_update_id":91718183059,"bids":[["71970.60000000","1.24046000"],["71969.49000000","0.08360000"],["71967.04000000","0.02291000"],["71966.16000000","0.00008000"],["71966.15000000","0.06240000"],["71966.14000000","0.00008000"],["71941.21000000","0.00000000"],["71907.40000000","0.00217000"],["71849.36000000","0.00326000"],["64773.54000000","0.00459000"]],"asks":[]}
{"type":"depthUpdate","symbol":"BTCUSDT","event_time_ms":1775758319214,"first_update_id":91718183060,"final_update_id":91718183071,"bids":[["71944.04000000","0.00007000"],["71934.17000000","0.39879000"],["71919.62000000","0.00217000"],["71858.53000000","0.00543000"],["71790.33000000","0.00825000"],["71776.89000000","0.00000000"],["64773.54000000","0.00425000"],["57576.48000000","0.00000000"]],"asks":[]}
{"type":"depthUpdate","symbol":"BTCUSDT","event_time_ms":1775758319314,"first_update_id":91718183072,"final_update_id":91718183088,"bids":[["71953.01000000","0.00000000"],["71951.41000000","0.00694000"],["71931.84000000","0.00217000"],["71925.05000000","0.00255000"],["71903.66000000","0.00008000"],["71867.69000000","0.00326000"],["64773.54000000","0.00442000"],["57582.00000000","0.00000000"],["57576.48000000","0.00000000"]],"asks":[["71988.82000000","0.11600000"],["71990.33000000","0.00000000"],["72001.80000000","0.00300000"],["72003.60000000","0.00000000"]]}
{"type":"depthUpdate","symbol":"BTCUSDT","event_time_ms":1775758319414,"first_update_id":91718183089,"final_update_id":91718183116,"bids":[["71959.90000000","0.00000000"],["71949.01000000","0.00013000"],["71944.06000000","0.00217000"],["71938.30000000","0.00000000"],["71927.42000000","0.00013000"],["71916.71000000","0.00000000"],["71905.83000000","0.00013000"],["71895.11000000","0.00013000"],["71884.24000000","0.00013000"],["71876.86000000","0.00326000"],["71873.52000000","0.00000000"],["71862.64000000","0.00013000"],["64773.54000000","0.00442000"]],"asks":[["71992.20000000","0.00013000"],["72003.09000000","0.00000000"],["72010.23000000","0.52273000"],["72013.79000000","0.00013000"],["72018.63000000","0.04634000"],["72024.69000000","0.00000000"],["72035.38000000","0.00013000"],["72046.28000000","0.00000000"],["72056.97000000","0.00013000"],["72067.88000000","0.00000000"],["72078.57000000","0.00013000"],["72089.47000000","0.00000000"]]}
{"type":"depthUpdate","symbol":"BTCUSDT","event_time_ms":1775758319514,"first_update_id":91718183117,"final_update_id":91718183130,"bids":[["71963.41000000","0.00139000"],["71956.28000000","0.00217000"],["71952.07000000","0.00008000"],["71886.02000000","0.00326000"],["64773.54000000","0.00459000"],["57576.48000000","0.00034000"]],"asks":[["71970.61000000","2.16457000"]]}
{"type":"depthUpdate","symbol":"BTCUSDT","event_time_ms":1775758319614,"first_update_id":91718183131,"final_update_id":91718183144,"bids":[["71970.60000000","1.24074000"],["71954.72000000","0.00014000"],["71895.18000000","0.00543000"],["70712.42000000","0.00332000"],["70641.70000000","0.00000000"],["64773.54000000","0.00476000"],["57576.48000000","0.00000000"]],"asks":[["71976.13000000","0.01389000"],["71983.52000000","0.00007000"],["71992.94000000","0.00217000"]]}
{"type":"depthUpdate","symbol":"BTCUSDT","event_time_ms":1775758319714,"first_update_id":91718183145,"final_update_id":91718183164,"bids":[["71969.49000000","0.08367000"],["71966.17000000","0.00008000"],["71966.16000000","0.11070000"],["71966.14000000","0.00000000"],["71904.35000000","0.00326000"],["71111.00000000","0.06386000"],["64773.54000000","0.00476000"]],"asks":[["71976.07000000","0.00702000"],["71976.12000000","0.00016000"],["71976.13000000","0.01397000"],["71976.95000000","0.00000000"],["71976.96000000","0.12918000"],["71989.24000000","0.41710000"],["72005.16000000","0.00217000"]]}
{"type":"depthUpdate","symbol":"BTCUSDT","event_time_ms":1775758319814,"first_update_id":91718183165,"final_update_id":91718183181,"bids":[["71969.49000000","0.08360000"],["71967.04000000","0.02291000"],["71913.51000000","0.00326000"],["71790.33000000","0.00000000"],["71783.62000000","0.00825000"],["64773.54000000","0.00476000"]],"asks":[["71989.25000000","1.13244000"],["71990.31000000","1.66272000"],["72017.38000000","0.00217000"],["73791.99000000","0.00020000"]]}
{"type":"depthUpdate","symbol":"BTCUSDT","event_time_ms":1775758319914,"first_update_id":91718183182,"final_update_id":91718183204,"bids":[["71966.29000000","0.00444000"],["71966.17000000","0.06021000"],["71966.15000000","0.00008000"],["71966.13000000","0.00008000"],["71952.09000000","0.04170000"],["71950.46000000","0.00000000"],["71950.23000000","0.13019000"],["71927.33000000","0.00000000"],["71926.20000000","0.12575000"],["71922.68000000","0.00326000"],["71890.56000000","0.21171000"],["69500.00000000","12.92234000"],["64773.54000000","0.00476000"]],"asks":[["71987.94000000","0.11168000"],["71988.82000000","0.00000000"],["72020.34000000","0.00000000"],["72021.00000000","0.10429000"],["72029.60000000","0.03217000"]]}
{"type":"depthUpdate","symbol":"BTCUSDT","event_time_ms":1775758320014,"first_update_id":91718183205,"final_update_id":91718183236,"bids":[["71969.49000000","0.08353000"],["71967.04000000","0.02291000"],["71966.18000000","0.00008000"],["71966.17000000","0.06029000"],["71966.16000000","0.11070000"],["71966.15000000","0.00000000"],["71966.13000000","0.00000000"],["71959.72000000","0.01240000"],["71951.42000000","0.34733000"],["71951.41000000","0.14983000"],["71950.75000000","0.20847000"],["71950.23000000","0.00000000"],["71948.50000000","0.00000000"],["71946.44000000","0.00000000"],["71943.53000000","0.34037000"],["71934.52000000","0.00000000"],["71931.84000000","0.00543000"],["71903.74000000","0.02000000"],["64773.54000000","0.00459000"],["64773.00000000","0.00010000"],["57576.48000000","0.00034000"],["57576.00000000","0.00000000"]],"asks":[["71984.62000000","0.00008000"],["71987.26000000","0.00000000"],["71989.46000000","0.27734000"],["72041.82000000","0.00217000"]]}
{"type":"depthUpdate","symbol":"BTCUSDT","event_time_ms":1775758320114,"first_update_id":91718183237,"final_update_id":91718183263,"bids":[["71970.60000000","1.25168000"],["71965.39000000","0.08022000"],["71963.58000000","0.10609000"],["71952.96000000","0.87084000"],["71941.01000000","0.00326000"],["71845.64000000","0.08205000"],["64773.54000000","0.00442000"],["64773.00000000","0.00010000"]],"asks":[["71970.61000000","2.16454000"],["71970.62000000","0.00024000"],["71975.16000000","0.00016000"],["71975.17000000","0.01110000"],["71976.45000000","0.42990000"],["72054.03000000","0.00217000"],["72061.51000000","0.10670000"]]}
{"type":"depthUpdate","symbol":"BTCUSDT","event_time_ms":1775758320214,"first_update_id":91718183264,"final_update_id":91718183282,"bids":[["71970.60000000","1.25151000"],["71950.17000000","0.00326000"],["66222.98000000","0.00016000"],["64773.54000000","0.00476000"],["57576.48000000","0.00000000"]],"asks":[["71973.04000000","0.04008000"],["71975.17000000","0.01118000"],["71976.47000000","0.00665000"],["72037.07000000","0.58888000"],["72037.74000000","1.66726000"],["72066.25000000","0.00217000"],["72131.50000000","2.07853000"],["72211.60000000","0.00000000"],["72236.63000000","0.00000000"]]}
{"type":"depthUpdate","symbol":"BTCUSDT","event_time_ms":1775758320314,"first_update_id":91718183283,"final_update_id":91718183296,"bids":[["71959.34000000","0.00438000"],["71908.54000000","0.02000000"],["64773.54000000","0.00476000"],["57576.48000000","0.00000000"]],"asks":[["71970.61000000","2.28531000"],["72078.47000000","0.00217000"],["72182.35000000","0.00818000"]]}
{"type":"depthUpdate","symbol":"BTCUSDT","event_time_ms":1775758320414,"first_update_id":91718183297,"final_update_id":91718183316,"bids":[["71950.65000000","0.00000000"],["71938.60000000","0.01042000"],["71830.12000000","0.00000000"],["71825.07000000","0.50000000"],["71662.26000000","0.00000000"],["71610.75000000","0.00014000"],["71550.00000000","0.92454000"],["71302.15000000","0.00000000"],["71250.89000000","0.00014000"],["70942.03000000","0.00000000"],["70891.04000000","0.04238000"],["70581.92000000","0.00000000"],["70531.19000000","0.03191000"],["70221.81000000","0.00000000"],["70171.33000000","0.03217000"],["64773.54000000","0.00451000"]],"asks":[["72090.69000000","0.00217000"],["79167.67000000","0.00007000"]]}
{"type":"depthUpdate","symbol":"BTCUSDT","event_time_ms":1775758320514,"first_update_id":91718183317,"final_update_id":91718183324,"bids":[["64773.54000000","0.00442000"],["57576.48000000","0.00034000"]],"asks":[["71977.66000000","0.00326000"],["79167.67000000","0.00000000"]]}
{"type":"depthUpdate","symbol":"BTCUSDT","event_time_ms":1775758320614,"first_update_id":91718183325,"final_update_id":91718183338,"bids":[["71934.17000000","0.00000000"],["71922.80000000","0.00000000"],["70000.00000000","47.41776000"],["64773.54000000","0.00459000"],["57576.48000000","0.00000000"]],"asks":[["71986.83000000","0.00325000"],["71996.83000000","0.00000000"],["72006.29000000","0.00000000"],["72097.99000000","1.89103000"],["72102.69000000","0.00000000"]]}
{"type":"depthUpdate","symbol":"BTCUSDT","event_time_ms":1775758320714,"first_update_id":91718183339,"final_update_id":91718183355,"bids":[["71954.72000000","0.00014000"],["71952.34000000","0.12839000"],["71952.02000000","0.00694000"],["71951.41000000","0.00000000"],["66222.98000000","0.00000000"],["64773.54000000","0.00476000"]],"asks":[["71983.52000000","0.00007000"],["71995.99000000","0.00325000"],["72093.94000000","0.12000000"],["72097.22000000","0.69757000"],["72102.68000000","0.00000000"],["72103.04000000","0.49786000"]]}
{"type":"depthUpdate","symbol":"BTCUSDT","event_time_ms":1775758320814,"first_update_id":91718183356,"final_update_id":91718183376,"bids":[["71952.02000000","0.00000000"],["71951.43000000","0.00694000"],["64773.54000000","0.00459000"],["57582.00000000","0.00000000"]],"asks":[["71970.61000000","2.28511000"],["71973.03000000","0.03791000"],["71973.50000000","0.00016000"],["71973.51000000","0.08331000"],["71975.86000000","0.00000000"],["71975.87000000","0.00015000"],["72005.16000000","0.00542000"],["72097.30000000","0.00000000"],["73250.00000000","2.60771000"],["79167.67000000","0.00007000"]]}
{"type":"depthUpdate","symbol":"BTCUSDT","event_time_ms":1775758320914,"first_update_id":91718183377,"final_update_id":91718183398,"bids":[["64773.54000000","0.00459000"],["57576.00000000","0.00000000"]],"asks":[["71970.61000000","2.28527000"],["71970.62000000","0.00032000"],["71973.02000000","0.00016000"],["71973.03000000","0.03799000"],["71973.04000000","0.04008000"],["71973.51000000","0.08339000"],["71975.16000000","0.00000000"],["71975.17000000","0.01110000"],["71975.87000000","0.00007000"],["71976.46000000","0.34732000"],["72014.32000000","0.00325000"],["79167.67000000","0.00000000"]]}
{"type":"depthUpdate","symbol":"BTCUSDT","event_time_ms":1775758321014,"first_update_id":91718183399,"final_update_id":91718183574,"bids":[["71970.60000000","0.23733000"],["71970.59000000","0.00064000"],["71969.51000000","0.00008000"],["71969.50000000","0.00032000"],["71969.49000000","0.00022000"],["71967.86000000","0.00000000"],["71967.50000000","0.00016000"],["71967.49000000","0.00000000"],["71966.18000000","0.00000000"],["71966.17000000","0.00008000"],["71966.16000000","0.00008000"],["71965.83000000","0.00008000"],["71965.82000000","0.05000000"],["71965.76000000","0.08331000"],["71964.89000000","0.01110000"],["71963.57000000","0.00000000"],["71963.56000000","0.00000000"],["71963.55000000","0.00000000"],["71963.43000000","0.00000000"],["71963.36000000","0.00000000"],["71961.50000000","0.00000000"],["71960.41000000","0.15834000"],["71960.27000000","0.11950000"],["71960.26000000","0.13170000"],["71960.25000000","0.00000000"],["71960.24000000","0.00000000"],["71959.71000000","0.00000000"],["71959.37000000","0.00694000"],["71958.43000000","0.00000000"],["71958.31000000","0.00000000"],["71957.29000000","0.41710000"],["71956.81000000","1.59192000"],["71956.80000000","0.00300000"],["71956.76000000","0.46354000"],["71953.66000000","1.58498000"],["71953.65000000","0.00000000"],["71953.54000000","0.00034000"],["71953.12000000","0.41710000"],["71952.34000000","0.00000000"],["71952.09000000","0.00000000"],["71951.43000000","0.00000000"],["71951.42000000","0.00000000"],["71950.91000000","1.66272000"],["71950.75000000","0.00008000"],["71950.64000000","1.58498000"],["71950.63000000","0.00000000"],["71950.54000000","0.00000000"],["71950.19000000","0.41710000"],["71950.01000000","0.00000000"],["71949.61000000","0.00000000"],["71949.38000000","0.00428000"],["71948.50000000","0.34734000"],["71948.01000000","0.00694000"],["71947.90000000","0.00000000"],["71947.57000000","0.20840000"],["71947.13000000","0.41710000"],["71946.94000000","1.58498000"],["71945.90000000","0.00000000"],["71945.11000000","0.68029000"],["71945.10000000","1.66272000"],["71945.09000000","0.00000000"],["71945.08000000","0.00000000"],["71945.07000000","0.00000000"],["71943.53000000","0.00000000"],["71942.30000000","0.00000000"],["71941.23000000","0.34038000"],["71940.30000000","0.00000000"],["71939.90000000","0.00000000"],["71939.04000000","1.66272000"],["71938.91000000","1.58498000"],["71934.92000000","0.00000000"],["71934.26000000","0.40390000"],["71931.46000000","1.31286000"],["71931.45000000","1.66272000"],["71931.44000000","0.00000000"],["71931.43000000","0.00000000"],["71925.21000000","0.50049000"],["71918.30000000","0.00648000"],["71911.78000000","0.75590000"],["71898.82000000","0.69538000"],["71891.31000000","0.00000000"],["71858.19000000","0.00000000"],["71845.64000000","0.12980000"],["71834.88000000","0.00000000"],["71826.90000000","0.05896000"],["71826.53000000","0.05896000"],["64773.54000000","0.00442000"],["57576.48000000","0.00034000"]],"asks":[["71970.61000000","2.36686000"],["71970.62000000","0.00008000"],["71971.39000000","0.01110000"],["71972.28000000","0.00020000"],["71973.02000000","0.00000000"],["71973.03000000","0.15242000"],["71973.50000000","0.34734000"],["71973.51000000","0.00015000"],["71974.34000000","0.05270000"],["71975.16000000","0.00000000"],["71975.17000000","0.00000000"],["71976.12000000","0.00000000"],["71976.44000000","0.12398000"],["71976.46000000","0.00000000"],["71980.32000000","0.00000000"],["71984.57000000","1.58498000"],["71985.01000000","0.01561000"],["71985.85000000","0.46023000"],["71985.86000000","0.41710000"],["71985.87000000","0.00000000"],["71988.05000000","0.50005000"],["71995.51000000","0.39284000"],["71998.09000000","0.00273000"],["71998.16000000","0.00000000"],["71999.40000000","0.03123000"],["72000.00000000","0.00428000"],["72000.89000000","0.00000000"],["72001.80000000","0.00000000"],["72006.52000000","0.00007000"],["72010.23000000","0.02283000"],["72016.21000000","0.00000000"],["72018.02000000","0.73028000"],["72023.49000000","0.00325000"],["72060.61000000","0.00000000"],["73500.00000000","52.85596000"]]}
{"type":"depthUpdate","symbol":"BTCUSDT","event_time_ms":1775758321114,"first_update_id":91718183575,"final_update_id":91718183748,"bids":[["71970.60000000","0.23106000"],["71970.59000000","0.00064000"],["71969.50000000","0.00008000"],["71969.49000000","0.00000000"],["71967.50000000","0.00000000"],["71967.04000000","0.02291000"],["71966.17000000","0.00000000"],["71966.16000000","0.00000000"],["71965.83000000","0.00016000"],["71965.82000000","0.05008000"],["71965.77000000","0.00000000"],["71965.76000000","0.00008000"],["71965.40000000","0.00014000"],["71965.39000000","0.00015000"],["71964.89000000","0.00008000"],["71964.30000000","0.09441000"],["71963.59000000","0.00016000"],["71963.58000000","0.10601000"],["71963.41000000","0.00008000"],["71963.13000000","0.00000000"],["71961.71000000","0.00070000"],["71961.18000000","0.11998000"],["71960.27000000","0.00000000"],["71960.26000000","0.00000000"],["71959.72000000","0.00000000"],["71958.17000000","0.08000000"],["71957.29000000","0.00000000"],["71956.82000000","2.00208000"],["71956.81000000","0.00694000"],["71956.76000000","0.00000000"],["71956.50000000","0.11601000"],["71956.01000000","0.01240000"],["71955.00000000","0.76009000"],["71953.84000000","1.58498000"],["71953.66000000","0.00000000"],["71953.12000000","0.00000000"],["71952.51000000","0.41710000"],["71950.92000000","3.24770000"],["71950.91000000","0.00000000"],["71950.64000000","0.00000000"],["71950.19000000","0.00000000"],["71949.43000000","0.31925000"],["71948.63000000","0.41710000"],["71947.56000000","0.00000000"],["71947.13000000","0.00000000"],["71946.94000000","0.00000000"],["71946.16000000","0.00000000"],["71945.13000000","1.15341000"],["71945.12000000","3.24770000"],["71945.11000000","0.00000000"],["71945.10000000","0.00000000"],["71942.25000000","0.07000000"],["71941.50000000","1.19473000"],["71941.23000000","0.00000000"],["71940.98000000","0.00000000"],["71940.85000000","0.08000000"],["71939.99000000","0.41710000"],["71939.05000000","1.66272000"],["71939.04000000","0.00000000"],["71938.45000000","0.34040000"],["71934.93000000","0.00000000"],["71934.26000000","0.00000000"],["71931.47000000","1.66272000"],["71931.46000000","0.00000000"],["71931.45000000","0.00000000"],["71928.68000000","0.00000000"],["71916.90000000","0.00240000"],["71911.78000000","0.00000000"],["71908.19000000","0.00000000"],["71859.43000000","1.06597000"],["71858.43000000","0.00000000"],["64773.54000000","0.00442000"],["64773.00000000","0.00010000"]],"asks":[["71970.61000000","2.38499000"],["71971.20000000","0.00300000"],["71971.39000000","0.00008000"],["71973.04000000","0.04008000"],["71973.50000000","0.34742000"],["71973.51000000","0.00007000"],["71974.34000000","0.05271000"],["71976.13000000","0.01397000"],["71976.44000000","0.00000000"],["71976.45000000","0.42982000"],["71982.33000000","0.70010000"],["71984.17000000","0.07000000"],["71985.01000000","0.04684000"],["71985.40000000","0.02000000"],["71988.68000000","0.00000000"],["71989.47000000","0.00000000"],["71991.93000000","0.00000000"],["71993.08000000","0.00000000"],["71999.40000000","0.00000000"],["72000.00000000","0.00128000"],["72032.65000000","0.00325000"],["72057.86000000","0.53149000"],["72136.53000000","0.21754000"],["72155.00000000","0.00000000"],["73036.92000000","1.85430000"],["73051.00000000","0.00000000"]]}
{"type":"depthUpdate","symbol":"BTCUSDT","event_time_ms":1775758321214,"first_update_id":91718183749,"final_update_id":91718183840,"bids":[["71970.60000000","0.23052000"],["71970.59000000","0.00064000"],["71969.51000000","0.00000000"],["71969.50000000","0.00000000"],["71965.83000000","0.00000000"],["71965.82000000","0.00015000"],["71965.76000000","0.00000000"],["71965.39000000","0.00007000"],["71964.89000000","0.00000000"],["71964.39000000","0.00016000"],["71964.38000000","0.05000000"],["71964.31000000","0.00000000"],["71964.30000000","0.00008000"],["71964.00000000","0.00120000"],["71963.59000000","0.11169000"],["71963.58000000","0.10609000"],["71963.41000000","0.00008000"],["71962.49000000","0.01110000"],["71958.18000000","0.62518000"],["71956.50000000","0.00000000"],["71953.41000000","0.00000000"],["71947.50000000","0.07000000"],["71943.08000000","0.12256000"],["71931.60000000","0.00300000"],["71907.34000000","0.00000000"],["71892.83000000","0.01732000"],["71884.24000000","0.00063000"],["71879.60000000","0.00000000"],["71845.64000000","0.00010000"],["71836.15000000","0.00000000"],["71826.27000000","0.00725000"],["64773.54000000","0.00442000"],["64773.00000000","0.00010000"],["57576.48000000","0.00000000"]],"asks":[["71970.61000000","2.38483000"],["71971.39000000","0.00000000"],["71972.26000000","0.01389000"],["71976.13000000","0.00008000"],["71976.45000000","0.42997000"],["71976.81000000","0.08000000"],["71980.18000000","0.07000000"],["71981.96000000","0.12630000"],["71982.31000000","1.50101000"],["71982.32000000","2.07982000"],["71982.33000000","0.00000000"],["71982.74000000","0.00138000"],["71986.10000000","0.00000000"],["71987.94000000","0.00000000"],["72041.82000000","0.00542000"],["72061.51000000","0.00000000"],["72067.59000000","0.00000000"]]}
