{"type":"depthUpdate","symbol":"BNBUSDT","event_time_ms":1775758308907,"first_update_id":19151923043,"final_update_id":19151923043,"bids":[],"asks":[["606.52000000","14.68400000"]]}
{"type":"depthUpdate","symbol":"BNBUSDT","event_time_ms":1775758309106,"first_update_id":19151923044,"final_update_id":19151923047,"bids":[],"asks":[["606.52000000","14.66400000"],["608.19000000","9.99000000"],["608.26000000","12.18800000"]]}
{"type":"depthUpdate","symbol":"BNBUSDT","event_time_ms":1775758309206,"first_update_id":19151923048,"final_update_id":19151923065,"bids":[],"asks":[["606.52000000","9.66500000"],["606.53000000","0.14300000"],["606.54000000","5.03500000"],["606.55000000","0.00900000"],["606.56000000","7.93700000"],["606.57000000","3.04200000"],["606.58000000","10.10100000"],["606.62000000","0.01000000"],["606.64000000","3.35100000"],["606.65000000","4.94400000"],["606.66000000","5.08400000"],["608.21000000","7.47200000"],["608.24000000","0.00000000"],["608.26000000","4.74200000"]]}
{"type":"depthUpdate","symbol":"BNBUSDT","event_time_ms":1775758309406,"first_update_id":19151923069,"final_update_id":19151923073,"bids":[],"asks":[["606.61000000","2.01300000"],["606.62000000","4.95500000"],["606.65000000","0.00000000"],["608.20000000","12.25300000"],["608.21000000","0.00900000"]]}
{"type":"depthUpdate","symbol":"BNBUSDT","event_time_ms":1775758309606,"first_update_id":19151923079,"final_update_id":19151923082,"bids":[],"asks":[["606.58000000","12.10100000"],["606.66000000","3.08400000"],["608.19000000","9.99000000"]]}
{"type":"depthUpdate","symbol":"BNBUSDT","event_time_ms":1775758309806,"first_update_id":19151923105,"final_update_id":19151923111,"bids":[],"asks":[["606.52000000","20.21100000"],["606.54000000","5.03500000"],["606.55000000","0.17500000"],["606.61000000","1.48800000"],["606.70000000","2.70800000"],["608.18000000","7.45500000"]]}
{"type":"depthUpdate","symbol":"BNBUSDT","event_time_ms":1775758309906,"first_update_id":19151923112,"final_update_id":19151923118,"bids":[],"asks":[["608.18000000","0.00900000"],["608.19000000","2.52700000"]]}
{"type":"depthUpdate","symbol":"BNBUSDT","event_time_ms":1775758310307,"first_update_id":19151923136,"final_update_id":19151923141,"bids":[],"asks":[["606.52000000","19.78200000"],["606.53000000","0.00900000"],["608.16000000","4.72900000"]]}
{"type":"depthUpdate","symbol":"BNBUSDT","event_time_ms":1775758310506,"first_update_id":19151923150,"final_update_id":19151923156,"bids":[],"asks":[["606.52000000","22.36200000"],["608.18000000","0.00900000"],["608.19000000","9.99000000"],["608.20000000","12.23600000"],["608.21000000","0.00900000"]]}
{"type":"depthUpdate","symbol":"BNBUSDT","event_time_ms":1775758310706,"first_update_id":19151923194,"final_update_id":19151923202,"bids":[],"asks":[["606.58000000","10.10100000"],["606.60000000","8.31000000"],["606.61000000","0.00900000"],["606.63000000","3.75900000"],["608.15000000","72.28100000"],["608.17000000","8.33100000"]]}
{"type":"depthUpdate","symbol":"BNBUSDT","event_time_ms":1775758310806,"first_update_id":19151923203,"final_update_id":19151923203,"bids":[],"asks":[["608.21000000","7.47200000"]]}
{"type":"depthUpdate","symbol":"BNBUSDT","event_time_ms":1775758310907,"first_update_id":19151923204,"final_update_id":19151923207,"bids":[],"asks":[["606.57000000","5.12600000"],["606.60000000","8.30100000"]]}
{"type":"depthUpdate","symbol":"BNBUSDT","event_time_ms":1775758311406,"first_update_id":19151923208,"final_update_id":19151923209,"bids":[],"asks":[["608.18000000","7.47200000"],["608.24000000","7.44600000"]]}
{"type":"depthUpdate","symbol":"BNBUSDT","event_time_ms":1775758311506,"first_update_id":19151923210,"final_update_id":19151923218,"bids":[],"asks":[["606.52000000","16.86300000"],["608.15000000","72.28100000"],["608.18000000","0.00900000"],["608.20000000","12.23600000"],["608.21000000","0.00900000"],["608.24000000","0.00000000"]]}
{"type":"depthUpdate","symbol":"BNBUSDT","event_time_ms":1775758311706,"first_update_id":19151923252,"final_update_id":19151923253,"bids":[],"asks":[["608.15000000","79.74400000"]]}
{"type":"depthUpdate","symbol":"BNBUSDT","event_time_ms":1775758311906,"first_update_id":19151923254,"final_update_id":19151923254,"bids":[],"asks":[["608.18000000","7.45500000"]]}
{"type":"depthUpdate","symbol":"BNBUSDT","event_time_ms":1775758312007,"first_update_id":19151923255,"final_update_id":19151923255,"bids":[["606.32000000","0.18600000"]],"asks":[]}
{"type":"depthUpdate","symbol":"BNBUSDT","event_time_ms":1775758312106,"first_update_id":19151923256,"final_update_id":19151923256,"bids":[],"asks":[["608.21000000","7.45500000"]]}
{"type":"depthUpdate","symbol":"BNBUSDT","event_time_ms":1775758312406,"first_update_id":19151923257,"final_update_id":19151923259,"bids":[],"asks":[["608.17000000","8.33100000"],["608.21000000","0.00900000"]]}
{"type":"depthUpdate","symbol":"BNBUSDT","event_time_ms":1775758312806,"first_update_id":19151923267,"final_update_id":19151923269,"bids":[],"asks":[["606.52000000","19.63600000"],["606.53000000","3.88900000"],["608.19000000","9.99000000"]]}
{"type":"depthUpdate","symbol":"BNBUSDT","event_time_ms":1775758312907,"first_update_id":19151923270,"final_update_id":19151923282,"bids":[["606.51000000","22.35800000"],["606.25000000","3.31500000"],["606.03000000","0.01300000"]],"asks":[["606.58000000","10.10100000"],["606.62000000","2.61700000"],["606.63000000","3.75900000"],["606.78000000","0.05900000"],["606.79000000","0.00000000"],["607.07000000","18.79400000"],["608.19000000","2.52700000"]]}
{"type":"depthUpdate","symbol":"BNBUSDT","event_time_ms":1775758313006,"first_update_id":19151923283,"final_update_id":19151923283,"bids":[],"asks":[["606.62000000","0.01900000"]]}
{"type":"depthUpdate","symbol":"BNBUSDT","event_time_ms":1775758313106,"first_update_id":19151923284,"final_update_id":19151923292,"bids":[],"asks":[["606.52000000","19.63600000"],["606.53000000","0.00900000"],["606.57000000","3.10300000"],["606.58000000","10.09200000"],["606.59000000","0.17500000"],["606.60000000","0.05900000"],["606.61000000","3.30600000"]]}
{"type":"depthUpdate","symbol":"BNBUSDT","event_time_ms":1775758313606,"first_update_id":19151923293,"final_update_id":19151923293,"bids":[],"asks":[["608.18000000","0.00900000"]]}
{"type":"depthUpdate","symbol":"BNBUSDT","event_time_ms":1775758313707,"first_update_id":19151923294,"final_update_id":19151923295,"bids":[],"asks":[["606.60000000","2.17400000"],["608.18000000","7.45500000"]]}
{"type":"depthUpdate","symbol":"BNBUSDT","event_time_ms":1775758313806,"first_update_id":19151923296,"final_update_id":19151923300,"bids":[],"asks":[["606.52000000","19.62700000"],["607.74000000","0.01800000"],["607.82000000","29.09300000"],["615.62000000","1.18900000"]]}
{"type":"depthUpdate","symbol":"BNBUSDT","event_time_ms":1775758314006,"first_update_id":19151923301,"final_update_id":19151923308,"bids":[],"asks":[["606.60000000","7.11900000"],["608.15000000","79.76000000"],["608.16000000","4.72900000"],["608.18000000","0.00900000"],["608.21000000","0.00900000"],["608.24000000","7.46300000"]]}
{"type":"depthUpdate","symbol":"BNBUSDT","event_time_ms":1775758314106,"first_update_id":19151923309,"final_update_id":19151923313,"bids":[],"asks":[["606.99000000","3.30600000"],["607.02000000","7.40800000"],["607.09000000","3.09400000"],["607.10000000","5.03700000"],["608.16000000","12.19200000"]]}
{"type":"depthUpdate","symbol":"BNBUSDT","event_time_ms":1775758314206,"first_update_id":19151923314,"final_update_id":19151923334,"bids":[["606.51000000","24.35800000"],["606.50000000","5.14000000"],["606.49000000","0.01800000"],["606.41000000","20.84800000"],["606.38000000","0.01900000"]],"asks":[["606.52000000","14.26300000"],["606.55000000","0.00900000"],["606.56000000","7.93700000"],["606.61000000","0.00900000"],["606.63000000","5.05600000"],["606.64000000","2.03600000"],["606.79000000","4.94300000"],["607.07000000","15.50000000"],["608.16000000","4.72900000"],["608.24000000","0.00000000"]]}
{"type":"depthUpdate","symbol":"BNBUSDT","event_time_ms":1775758314306,"first_update_id":19151923335,"final_update_id":19151923367,"bids":[["606.51000000","27.11300000"],["606.50000000","4.97400000"],["606.39000000","2.19700000"],["606.38000000","0.01000000"],["606.33000000","9.73900000"],["606.25000000","0.01700000"]],"asks":[["606.52000000","9.24600000"],["606.57000000","0.01800000"],["606.58000000","10.10100000"],["606.59000000","0.00900000"],["606.60000000","1.58600000"],["606.62000000","0.01000000"],["606.63000000","6.58500000"],["606.64000000","2.04500000"],["606.79000000","0.00000000"],["606.80000000","0.01900000"],["607.07000000","18.79400000"],["608.15000000","64.81800000"],["608.18000000","7.47200000"],["608.21000000","7.47200000"],["608.24000000","0.00000000"]]}
{"type":"depthUpdate","symbol":"BNBUSDT","event_time_ms":1775758314506,"first_update_id":19151923380,"final_update_id":19151923384,"bids":[],"asks":[["606.70000000","2.90800000"],["608.21000000","14.93500000"],["608.24000000","0.00000000"]]}
{"type":"depthUpdate","symbol":"BNBUSDT","event_time_ms":1775758314806,"first_update_id":19151923402,"final_update_id":19151923409,"bids":[],"asks":[["608.16000000","4.72900000"],["608.19000000","9.99000000"],["608.21000000","7.47200000"],["608.24000000","0.00000000"]]}
{"type":"depthUpdate","symbol":"BNBUSDT","event_time_ms":1775758315007,"first_update_id":19151923414,"final_update_id":19151923415,"bids":[],"asks":[["606.52000000","16.99700000"],["608.21000000","0.00900000"]]}
{"type":"depthUpdate","symbol":"BNBUSDT","event_time_ms":1775758315206,"first_update_id":19151923416,"final_update_id":19151923429,"bids":[],"asks":[["606.52000000","16.23700000"],["608.19000000","9.99000000"],["608.21000000","14.93500000"],["608.24000000","14.92600000"]]}
{"type":"depthUpdate","symbol":"BNBUSDT","event_time_ms":1775758315306,"first_update_id":19151923430,"final_update_id":19151923437,"bids":[],"asks":[["606.65000000","0.00900000"],["606.66000000","5.08400000"],["608.21000000","22.39800000"],["608.23000000","7.57300000"],["608.24000000","0.00000000"]]}
{"type":"depthUpdate","symbol":"BNBUSDT","event_time_ms":1775758315606,"first_update_id":19151923441,"final_update_id":19151923442,"bids":[["604.81000000","12.80200000"],["604.77000000","0.00000000"]],"asks":[["608.23000000","0.11000000"]]}
{"type":"depthUpdate","symbol":"BNBUSDT","event_time_ms":1775758315806,"first_update_id":19151923446,"final_update_id":19151923532,"bids":[["606.51000000","13.31300000"],["606.50000000","0.01900000"],["606.49000000","0.01800000"],["606.47000000","0.18400000"],["606.46000000","4.96500000"],["606.45000000","1.79800000"],["606.44000000","1.61300000"],["606.42000000","6.55800000"],["606.41000000","0.03500000"],["606.40000000","0.03700000"],["606.39000000","0.19700000"],["606.37000000","6.53300000"],["606.35000000","20.93600000"],["606.33000000","4.79200000"],["606.31000000","1.33900000"],["606.30000000","18.08800000"],["606.24000000","8.29800000"],["606.20000000","16.79400000"],["606.13000000","27.91500000"],["606.03000000","2.89900000"],["606.02000000","3.31700000"],["606.01000000","0.00000000"],["604.89000000","0.03400000"],["604.88000000","1.59200000"],["604.48000000","29.89600000"]],"asks":[["606.52000000","18.77900000"],["606.53000000","5.43600000"],["606.54000000","5.03500000"],["606.55000000","0.00900000"],["606.56000000","7.93700000"],["606.57000000","6.33300000"],["606.58000000","13.49700000"],["606.59000000","0.00900000"],["606.60000000","1.75200000"],["606.61000000","0.00900000"],["606.63000000","3.28800000"],["606.64000000","2.04500000"],["606.65000000","0.00000000"],["606.73000000","10.83200000"],["606.74000000","17.53700000"],["606.76000000","5.85800000"],["606.77000000","4.74800000"],["606.78000000","5.00200000"],["606.80000000","8.37500000"],["607.07000000","15.50000000"],["608.01000000","6.50000000"],["608.16000000","4.72900000"],["608.21000000","0.00900000"]]}
{"type":"depthUpdate","symbol":"BNBUSDT","event_time_ms":1775758316406,"first_update_id":19151923615,"final_update_id":19151923616,"bids":[["606.51000000","10.74300000"],["604.68000000","4.48500000"]],"asks":[]}
{"type":"depthUpdate","symbol":"BNBUSDT","event_time_ms":1775758316506,"first_update_id":19151923617,"final_update_id":19151923617,"bids":[["606.51000000","8.09300000"]],"asks":[]}
{"type":"depthUpdate","symbol":"BNBUSDT","event_time_ms":1775758316606,"first_update_id":19151923618,"final_update_id":19151923618,"bids":[["604.85000000","1.30400000"],["604.81000000","11.61800000"]],"asks":[]}
{"type":"depthUpdate","symbol":"BNBUSDT","event_time_ms":1775758316707,"first_update_id":19151923619,"final_update_id":19151923619,"bids":[["606.30000000","17.92500000"]],"asks":[]}
{"type":"depthUpdate","symbol":"BNBUSDT","event_time_ms":1775758316806,"first_update_id":19151923620,"final_update_id":19151923620,"bids":[["606.15000000","9.90200000"],["605.71000000","1.33900000"],["604.62000000","0.05400000"],["601.53000000","0.77800000"]],"asks":[["607.01000000","0.00000000"],["607.73000000","13.67200000"],["609.35000000","0.05100000"],["611.36000000","0.02200000"]]}
{"type":"depthUpdate","symbol":"BNBUSDT","event_time_ms":1775758316906,"first_update_id":19151923621,"final_update_id":19151923621,"bids":[],"asks":[["606.79000000","2.74100000"]]}
{"type":"depthUpdate","symbol":"BNBUSDT","event_time_ms":1775758317206,"first_update_id":19151923756,"final_update_id":19151923797,"bids":[["606.51000000","0.14700000"],["606.45000000","0.03000000"],["606.43000000","0.00000000"],["606.40000000","1.54400000"],["606.37000000","1.60100000"],["606.36000000","3.40400000"],["606.35000000","1.81700000"],["606.32000000","2.25600000"],["606.31000000","0.00900000"],["606.28000000","17.89000000"],["606.26000000","14.72800000"],["606.25000000","2.01700000"],["606.18000000","8.34500000"],["606.16000000","0.03700000"],["606.08000000","1.78300000"],["606.06000000","21.82700000"],["605.80000000","92.46000000"],["605.29000000","5.98600000"],["605.26000000","8.60800000"],["604.54000000","0.03700000"],["604.10000000","1.04400000"]],"asks":[["606.68000000","4.20600000"],["606.69000000","23.94900000"],["607.11000000","8.94000000"],["607.14000000","29.32600000"],["607.64000000","0.07200000"],["607.75000000","0.00000000"],["608.07000000","7.46300000"],["608.08000000","1.62400000"]]}
{"type":"depthUpdate","symbol":"BNBUSDT","event_time_ms":1775758317306,"first_update_id":19151923798,"final_update_id":19151924002,"bids":[["606.51000000","0.00000000"],["606.50000000","0.00000000"],["606.49000000","0.00000000"],["606.48000000","0.00000000"],["606.47000000","0.00000000"],["606.46000000","0.00000000"],["606.45000000","0.00000000"],["606.44000000","7.83400000"],["606.42000000","0.03800000"],["606.41000000","0.00900000"],["606.40000000","0.02800000"],["606.39000000","1.98100000"],["606.38000000","0.01900000"],["606.37000000","1.76700000"],["606.36000000","3.40400000"],["606.35000000","0.00000000"],["606.33000000","0.03000000"],["606.32000000","1.73500000"],["606.31000000","0.00900000"],["606.30000000","17.92500000"],["606.29000000","32.01700000"],["606.28000000","19.88200000"],["606.27000000","8.18300000"],["606.26000000","14.73700000"],["606.25000000","2.02600000"],["606.24000000","8.27300000"],["606.19000000","8.19100000"],["606.18000000","8.35400000"],["606.17000000","0.18800000"],["606.11000000","4.71900000"],["605.71000000","1.33000000"],["605.36000000","9.36700000"],["605.26000000","8.59100000"],["605.06000000","15.54500000"],["605.04000000","95.69200000"],["604.54000000","0.02000000"],["603.39000000","0.00000000"],["603.30000000","0.65800000"],["597.41000000","0.00000000"],["597.21000000","0.60200000"],["597.16000000","0.07900000"],["585.60000000","2.47100000"]],"asks":[["606.45000000","33.29900000"],["606.46000000","0.00000000"],["606.47000000","1.54900000"],["606.48000000","0.17500000"],["606.49000000","5.00800000"],["606.50000000","5.01800000"],["606.51000000","17.37100000"],["606.52000000","24.33400000"],["606.53000000","0.04400000"],["606.54000000","5.05800000"],["606.55000000","0.02600000"],["606.56000000","2.93000000"],["606.58000000","2.01900000"],["606.60000000","0.24400000"],["606.67000000","2.99300000"],["606.68000000","4.19600000"],["606.69000000","23.95800000"],["606.70000000","7.85200000"],["606.71000000","0.00000000"],["606.76000000","3.41900000"],["606.78000000","5.00600000"],["606.81000000","9.62800000"],["606.86000000","0.00000000"],["607.29000000","29.40600000"],["607.32000000","1.35300000"],["607.50000000","1.53800000"],["607.59000000","41.37100000"],["607.84000000","4.13300000"],["608.07000000","14.90900000"],["608.08000000","9.10300000"],["608.11000000","7.46300000"],["608.43000000","16.64100000"],["608.46000000","0.00000000"],["609.93000000","0.11500000"],["615.62000000","1.16500000"]]}
{"type":"depthUpdate","symbol":"BNBUSDT","event_time_ms":1775758318406,"first_update_id":19151924236,"final_update_id":19151924236,"bids":[["605.66000000","27.97200000"]],"asks":[]}
{"type":"depthUpdate","symbol":"BNBUSDT","event_time_ms":1775758319006,"first_update_id":19151924280,"final_update_id":19151924280,"bids":[],"asks":[["608.07000000","22.38900000"]]}
{"type":"depthUpdate","symbol":"BNBUSDT","event_time_ms":1775758319306,"first_update_id":19151924293,"final_update_id":19151924295,"bids":[],"asks":[["608.09000000","3.83800000"]]}
{"type":"depthUpdate","symbol":"BNBUSDT","event_time_ms":1775758319506,"first_update_id":19151924303,"final_update_id":19151924308,"bids":[],"asks":[["606.49000000","9.96300000"],["606.54000000","9.99400000"],["606.59000000","0.00900000"],["608.05000000","15.78600000"],["608.15000000","64.81800000"]]}
{"type":"depthUpdate","symbol":"BNBUSDT","event_time_ms":1775758319606,"first_update_id":19151924309,"final_update_id":19151924317,"bids":[["606.22000000","6.55000000"],["604.77000000","0.00000000"],["604.69000000","14.49200000"]],"asks":[["606.52000000","12.05700000"],["606.57000000","0.01800000"],["606.84000000","0.02300000"],["608.05000000","23.24900000"],["608.07000000","14.92600000"],["608.13000000","0.00000000"]]}
{"type":"depthUpdate","symbol":"BNBUSDT","event_time_ms":1775758319706,"first_update_id":19151924318,"final_update_id":19151924319,"bids":[["603.90000000","0.09100000"],["603.49000000","0.62700000"]],"asks":[]}
{"type":"depthUpdate","symbol":"BNBUSDT","event_time_ms":1775758320106,"first_update_id":19151924322,"final_update_id":19151924323,"bids":[],"asks":[["607.24000000","30.11900000"],["607.48000000","0.00000000"],["608.05000000","30.71200000"]]}
{"type":"depthUpdate","symbol":"BNBUSDT","event_time_ms":1775758320206,"first_update_id":19151924324,"final_update_id":19151924334,"bids":[["605.75000000","10.07200000"],["605.31000000","15.00100000"],["603.95000000","0.00000000"]],"asks":[["606.45000000","34.45700000"],["607.23000000","12.04100000"],["607.25000000","0.00000000"],["607.47000000","0.08900000"],["607.48000000","4.07700000"],["607.78000000","4.89000000"]]}
{"type":"depthUpdate","symbol":"BNBUSDT","event_time_ms":1775758320806,"first_update_id":19151924349,"final_update_id":19151924349,"bids":[],"asks":[["608.11000000","0.01700000"]]}
{"type":"depthUpdate","symbol":"BNBUSDT","event_time_ms":1775758320906,"first_update_id":19151924350,"final_update_id":19151924351,"bids":[],"asks":[["608.07000000","14.92600000"]]}
{"type":"depthUpdate","symbol":"BNBUSDT","event_time_ms":1775758321006,"first_update_id":19151924352,"final_update_id":19151924422,"bids":[["606.44000000","0.04400000"],["606.40000000","0.01900000"],["606.39000000","0.03100000"],["606.38000000","0.01900000"],["606.37000000","1.60100000"],["606.36000000","5.16000000"],["606.29000000","32.07600000"],["606.28000000","17.88200000"],["606.27000000","13.48100000"],["606.26000000","14.89400000"],["606.25000000","0.02600000"],["606.24000000","10.27300000"],["606.21000000","6.37300000"],["606.19000000","4.89200000"],["606.17000000","0.18800000"],["606.14000000","19.69600000"],["606.11000000","8.01800000"],["606.03000000","4.04100000"],["606.02000000","0.01700000"],["605.92000000","13.22500000"],["605.31000000","12.41900000"],["605.26000000","8.59100000"],["604.88000000","19.11200000"],["604.54000000","0.02000000"],["603.28000000","0.00000000"],["603.19000000","0.00000000"],["597.21000000","0.60200000"],["597.11000000","0.03500000"]],"asks":[["606.45000000","38.19000000"],["606.46000000","2.00800000"],["606.47000000","1.55800000"],["606.48000000","5.04700000"],["606.49000000","8.31500000"],["606.52000000","8.75900000"],["606.55000000","1.42300000"],["606.56000000","4.69200000"],["606.69000000","35.59400000"],["606.72000000","8.08500000"],["606.74000000","42.26800000"],["606.75000000","22.43200000"],["606.98000000","0.02600000"],["607.08000000","27.18800000"],["607.65000000","9.97400000"]]}
{"type":"depthUpdate","symbol":"BNBUSDT","event_time_ms":1775758321106,"first_update_id":19151924423,"final_update_id":19151924521,"bids":[["606.42000000","0.02800000"],["606.39000000","0.01800000"],["606.38000000","0.01000000"],["606.37000000","0.01700000"],["606.36000000","0.20300000"],["606.34000000","0.03600000"],["606.33000000","0.03000000"],["606.32000000","0.17600000"],["606.31000000","1.52000000"],["606.30000000","11.42800000"],["606.29000000","0.02600000"],["606.28000000","17.55300000"],["606.27000000","8.18300000"],["606.26000000","0.18500000"],["606.25000000","1.79700000"],["606.24000000","8.80900000"],["606.23000000","4.94100000"],["606.21000000","6.70200000"],["606.20000000","16.51400000"],["606.19000000","4.89200000"],["606.18000000","3.98200000"],["606.17000000","2.18800000"],["606.13000000","23.95700000"],["606.12000000","23.43100000"],["606.11000000","4.71900000"],["606.10000000","1.68500000"],["606.08000000","0.18300000"],["606.04000000","24.81900000"],["605.94000000","15.18400000"],["605.93000000","0.00000000"],["605.87000000","11.91900000"],["605.85000000","4.85200000"],["605.84000000","6.23100000"],["605.83000000","8.47200000"],["605.81000000","1.58400000"],["605.75000000","9.49800000"],["605.65000000","0.00900000"],["605.64000000","21.42400000"],["605.17000000","35.43700000"],["604.43000000","0.02800000"],["604.40000000","4.06300000"],["604.13000000","4.80100000"],["604.07000000","0.10500000"],["603.90000000","1.66600000"]],"asks":[["606.45000000","42.19000000"],["606.46000000","3.30700000"],["606.48000000","5.05700000"],["606.49000000","5.01700000"],["606.50000000","11.96400000"],["606.51000000","9.76300000"],["606.52000000","6.76900000"],["606.53000000","0.11700000"],["606.54000000","5.04900000"],["606.57000000","0.00900000"],["606.58000000","0.01900000"],["606.60000000","0.23400000"],["606.63000000","6.69500000"],["606.64000000","1.76900000"],["606.72000000","4.78900000"],["606.82000000","25.55000000"],["606.93000000","39.47000000"],["606.96000000","6.59500000"],["607.56000000","0.88200000"],["607.82000000","226.51200000"],["607.97000000","31.44400000"],["608.55000000","1.57500000"],["609.07000000","0.14800000"]]}
{"type":"depthUpdate","symbol":"BNBUSDT","event_time_ms":1775758321206,"first_update_id":19151924522,"final_update_id":19151924550,"bids":[["606.30000000","7.39100000"],["606.27000000","3.40800000"],["606.26000000","1.73400000"],["606.24000000","5.51100000"],["606.22000000","9.84800000"],["606.18000000","18.70000000"],["606.09000000","0.03000000"],["605.96000000","1.61800000"],["605.94000000","7.99900000"],["604.86000000","1.72500000"],["604.37000000","0.03000000"],["604.34000000","0.00000000"],["604.08000000","5.08900000"],["604.02000000","0.12400000"]],"asks":[["606.45000000","45.48800000"],["606.46000000","0.00900000"],["606.62000000","2.00800000"],["607.36000000","30.41600000"]]}
