{"type":"depthUpdate","symbol":"ETHUSDT","event_time_ms":1775758308915,"first_update_id":74488285795,"final_update_id":74488285827,"bids":[["2208.26000000","73.03190000"],["2208.25000000","42.43120000"],["2208.24000000","18.02990000"],["2208.20000000","8.45970000"],["2208.14000000","0.02940000"],["2208.03000000","0.76830000"],["2208.00000000","16.62980000"],["2207.91000000","8.09830000"],["2207.17000000","0.96240000"],["2206.31000000","0.83700000"],["1987.44000000","0.11010000"]],"asks":[["2208.27000000","6.04480000"],["2208.29000000","0.01200000"],["2208.42000000","0.04140000"],["2208.57000000","0.04770000"],["2208.64000000","0.00530000"],["2208.75000000","0.00000000"],["2209.17000000","0.09500000"],["2209.46000000","11.80040000"],["2210.76000000","0.00000000"],["2211.31000000","0.00230000"]]}
{"type":"depthUpdate","symbol":"ETHUSDT","event_time_ms":1775758309115,"first_update_id":74488285834,"final_update_id":74488285851,"bids":[["2208.26000000","73.21330000"],["2208.21000000","5.04930000"],["2208.03000000","0.58690000"],["2207.59000000","0.52200000"],["2206.79000000","0.17860000"],["2205.63000000","0.00000000"],["1987.44000000","0.14380000"]],"asks":[["2208.27000000","0.02380000"],["2208.36000000","0.00470000"],["2208.37000000","0.00480000"],["2208.40000000","0.00300000"],["2208.54000000","0.00470000"],["2208.64000000","0.00770000"],["2208.69000000","0.04900000"],["2208.94000000","0.06000000"]]}
{"type":"depthUpdate","symbol":"ETHUSDT","event_time_ms":1775758309215,"first_update_id":74488285852,"final_update_id":74488285907,"bids":[["2208.26000000","84.65420000"],["2208.25000000","42.43120000"],["2208.24000000","8.50110000"],["2208.04000000","2.52400000"],["2207.95000000","1.62660000"],["2207.86000000","0.00460000"],["2207.50000000","0.15160000"],["2207.36000000","12.45690000"],["2206.31000000","1.10700000"],["2206.30000000","4.35840000"],["2204.86000000","0.00000000"],["2142.29000000","0.00610000"],["1987.44000000","0.15500000"]],"asks":[["2208.47000000","0.00700000"],["2208.49000000","0.00470000"],["2208.58000000","2.44060000"],["2208.59000000","0.00920000"],["2208.67000000","0.00460000"],["2208.70000000","1.55790000"],["2208.71000000","0.00240000"],["2208.75000000","0.00000000"],["2208.84000000","12.81080000"],["2208.85000000","26.03630000"],["2208.86000000","0.96130000"],["2208.87000000","9.68150000"],["2208.88000000","0.62400000"],["2209.03000000","0.72370000"],["2209.14000000","0.03250000"],["2209.18000000","0.00670000"],["2209.19000000","12.05100000"],["2209.22000000","0.11550000"],["2209.29000000","13.92840000"],["2209.33000000","0.02240000"],["2209.36000000","0.00300000"],["2209.40000000","1.40000000"],["2209.76000000","0.00300000"],["2209.90000000","7.97980000"],["2211.19000000","8.45250000"]]}
{"type":"depthUpdate","symbol":"ETHUSDT","event_time_ms":1775758309315,"first_update_id":74488285908,"final_update_id":74488285933,"bids":[["2208.26000000","84.65420000"],["2208.03000000","0.05500000"],["2207.24000000","0.00000000"],["2206.62000000","2.85920000"],["2205.92000000","17.37290000"],["2205.22000000","14.79590000"],["2204.87000000","0.00000000"],["1987.44000000","0.15490000"]],"asks":[["2208.58000000","2.43820000"],["2208.69000000","0.04660000"],["2208.70000000","1.15730000"],["2208.71000000","1.14770000"],["2208.83000000","11.88190000"],["2208.85000000","14.81930000"],["2209.71000000","0.00000000"],["2210.11000000","28.37580000"],["2211.19000000","8.45250000"],["2211.23000000","6.93400000"],["2244.28000000","0.00640000"]]}
{"type":"depthUpdate","symbol":"ETHUSDT","event_time_ms":1775758309415,"first_update_id":74488285934,"final_update_id":74488285964,"bids":[["2208.23000000","5.54640000"],["2207.98000000","0.27380000"],["2207.74000000","0.00230000"],["2207.70000000","0.08370000"],["2207.60000000","0.50220000"],["2205.27000000","16.71520000"],["1987.44000000","0.15490000"],["1337.05000000","0.00000000"],["1336.95000000","0.00000000"],["1333.02000000","0.06440000"],["1332.95000000","0.00460000"],["1332.63000000","0.00410000"],["1332.41000000","0.00000000"],["1332.15000000","0.00460000"],["1331.10000000","0.00920000"],["1330.24000000","0.00000000"],["1329.89000000","0.01380000"],["1329.34000000","0.00000000"],["1322.97000000","0.04360000"],["1321.14000000","0.00000000"]],"asks":[["2208.63000000","0.04160000"],["2208.80000000","1.02020000"],["2208.82000000","4.15180000"],["2208.84000000","11.79760000"],["2209.37000000","10.18360000"],["2211.23000000","6.93400000"]]}
{"type":"depthUpdate","symbol":"ETHUSDT","event_time_ms":1775758309515,"first_update_id":74488285965,"final_update_id":74488286005,"bids":[["2208.26000000","75.12540000"],["2208.25000000","22.46600000"],["2208.24000000","8.50110000"],["2208.14000000","0.02940000"],["2208.00000000","16.62980000"],["2199.11000000","0.52440000"],["2199.01000000","0.00000000"],["1987.44000000","0.15490000"]],"asks":[["2208.27000000","0.02380000"],["2208.29000000","0.01200000"],["2208.41000000","0.02100000"],["2208.42000000","0.02270000"],["2208.48000000","5.16960000"],["2208.54000000","0.00880000"],["2208.56000000","0.16160000"],["2208.57000000","0.00470000"],["2208.64000000","0.00770000"],["2208.70000000","1.65970000"],["2209.03000000","17.02460000"],["2209.21000000","14.71010000"],["2210.01000000","19.91890000"],["2211.19000000","6.46000000"],["2211.23000000","4.92790000"]]}
{"type":"depthUpdate","symbol":"ETHUSDT","event_time_ms":1775758309615,"first_update_id":74488286006,"final_update_id":74488286128,"bids":[["2208.26000000","57.62690000"],["2208.25000000","6.57370000"],["2208.23000000","0.04750000"],["2208.22000000","0.00000000"],["2208.21000000","0.95650000"],["2208.13000000","12.80470000"],["2208.12000000","0.00000000"],["2208.11000000","9.54270000"],["2208.10000000","0.11330000"],["2208.07000000","4.09510000"],["2208.03000000","0.05500000"],["2207.95000000","40.64940000"],["2207.94000000","0.04750000"],["2207.93000000","0.00460000"],["2207.90000000","0.27000000"],["2207.83000000","0.55290000"],["2207.81000000","15.49760000"],["2207.68000000","0.00300000"],["2207.37000000","0.68350000"],["2203.53000000","1.00000000"],["1987.44000000","0.16060000"]],"asks":[["2208.27000000","8.97210000"],["2208.46000000","1.85590000"],["2208.47000000","1.81180000"],["2208.51000000","4.17270000"],["2208.53000000","0.05690000"],["2208.55000000","0.00240000"],["2208.57000000","1.14760000"],["2208.62000000","0.10000000"],["2208.64000000","0.54110000"],["2208.65000000","1.17020000"],["2208.79000000","0.67500000"],["2208.87000000","9.58150000"],["2208.88000000","2.09900000"],["2209.06000000","9.62880000"],["2209.17000000","0.04980000"],["2209.29000000","12.43740000"],["2209.32000000","0.03000000"],["2209.40000000","1.44520000"],["2209.86000000","4.08380000"],["2209.95000000","0.00000000"],["2211.19000000","8.46150000"],["2211.23000000","6.92940000"],["2211.91000000","1.33020000"],["2294.25000000","0.00670000"]]}
{"type":"depthUpdate","symbol":"ETHUSDT","event_time_ms":1775758309715,"first_update_id":74488286129,"final_update_id":74488286163,"bids":[["2208.26000000","57.60320000"],["2208.25000000","6.57130000"],["2208.13000000","2.37390000"],["2208.03000000","16.31060000"],["2208.00000000","0.32890000"],["2207.92000000","0.01840000"],["2207.91000000","0.27230000"],["2207.89000000","0.07140000"],["2207.83000000","5.53500000"],["2207.10000000","0.01990000"],["2203.04000000","0.01800000"],["1987.44000000","0.16620000"]],"asks":[["2208.44000000","0.87380000"],["2208.45000000","0.00000000"],["2208.46000000","0.00240000"],["2208.50000000","0.00710000"],["2208.53000000","0.01160000"],["2208.57000000","0.00230000"],["2208.58000000","1.13350000"],["2208.64000000","0.00530000"],["2208.76000000","0.00460000"],["2208.81000000","2.05170000"],["2209.28000000","0.08300000"],["2209.73000000","2.04110000"],["2212.80000000","44.18490000"]]}
{"type":"depthUpdate","symbol":"ETHUSDT","event_time_ms":1775758309915,"first_update_id":74488286180,"final_update_id":74488286199,"bids":[["2208.26000000","57.93620000"],["2208.24000000","8.50350000"],["2206.23000000","0.28960000"],["2141.95000000","0.11650000"],["1987.44000000","0.16610000"]],"asks":[["2208.44000000","0.00230000"],["2208.67000000","12.72570000"],["2208.68000000","27.23700000"],["2208.71000000","0.00240000"],["2208.78000000","0.14320000"],["2208.80000000","0.00810000"],["2209.47000000","0.00000000"]]}
{"type":"depthUpdate","symbol":"ETHUSDT","event_time_ms":1775758310015,"first_update_id":74488286200,"final_update_id":74488286206,"bids":[["1987.44000000","0.16610000"]],"asks":[["2208.43000000","0.00000000"],["2208.70000000","0.00460000"]]}
{"type":"depthUpdate","symbol":"ETHUSDT","event_time_ms":1775758310515,"first_update_id":74488286273,"final_update_id":74488286287,"bids":[["2208.26000000","56.96010000"],["2208.21000000","0.00700000"],["2208.12000000","0.52370000"],["2207.74000000","0.00230000"],["2199.11000000","0.00000000"],["2198.61000000","0.52450000"],["1987.44000000","0.14930000"],["1987.43000000","0.01220000"]],"asks":[["2208.43000000","0.50000000"],["2208.63000000","0.04160000"],["2208.64000000","1.11570000"],["2237.47000000","0.06730000"],["2429.10000000","0.00000000"]]}
{"type":"depthUpdate","symbol":"ETHUSDT","event_time_ms":1775758310615,"first_update_id":74488286288,"final_update_id":74488286326,"bids":[["2208.26000000","56.95770000"],["2208.14000000","11.82700000"],["2207.10000000","0.00000000"],["1987.44000000","0.15490000"]],"asks":[["2208.27000000","6.16640000"],["2208.28000000","0.01180000"],["2208.42000000","0.02510000"],["2208.47000000","0.00940000"],["2208.57000000","0.00470000"],["2208.62000000","0.00000000"],["2208.63000000","9.54740000"],["2208.64000000","12.91330000"],["2208.65000000","0.02500000"],["2208.66000000","17.69870000"],["2208.67000000","0.00460000"],["2208.72000000","0.10300000"],["2209.06000000","9.52880000"],["2209.11000000","0.00000000"],["2209.16000000","2.45200000"],["2209.28000000","0.00300000"]]}
{"type":"depthUpdate","symbol":"ETHUSDT","event_time_ms":1775758310715,"first_update_id":74488286327,"final_update_id":74488286358,"bids":[["2208.26000000","58.79930000"],["2208.24000000","8.50350000"],["2208.16000000","0.00470000"],["2208.15000000","11.83220000"],["2208.14000000","0.02940000"],["2208.01000000","0.59820000"],["2208.00000000","0.27300000"],["2207.09000000","9.54670000"],["1987.44000000","0.16050000"]],"asks":[["2208.29000000","0.01200000"],["2208.41000000","0.02100000"],["2208.46000000","0.00000000"],["2208.47000000","3.19780000"],["2208.55000000","0.04540000"],["2208.57000000","0.00470000"],["2208.62000000","1.14520000"],["2208.63000000","0.04160000"],["2208.64000000","0.00530000"],["2208.65000000","11.82260000"],["2208.81000000","2.05170000"],["2209.02000000","16.24740000"],["2209.25000000","0.08450000"]]}
{"type":"depthUpdate","symbol":"ETHUSDT","event_time_ms":1775758310815,"first_update_id":74488286359,"final_update_id":74488286381,"bids":[["2208.25000000","9.17780000"],["2208.16000000","13.61730000"],["2208.14000000","4.11320000"],["2207.81000000","16.17600000"],["2207.37000000","0.00510000"],["2207.09000000","9.52880000"],["2205.21000000","29.53220000"],["1987.44000000","0.16620000"]],"asks":[["2208.27000000","0.14540000"],["2208.46000000","0.00240000"],["2208.61000000","0.00230000"],["2208.62000000","0.00000000"],["2208.64000000","0.00770000"],["2208.65000000","17.12450000"],["2214.90000000","0.00800000"],["2230.64000000","0.00230000"]]}
{"type":"depthUpdate","symbol":"ETHUSDT","event_time_ms":1775758311215,"first_update_id":74488286445,"final_update_id":74488286449,"bids":[["1987.44000000","0.15490000"]],"asks":[]}
{"type":"depthUpdate","symbol":"ETHUSDT","event_time_ms":1775758311515,"first_update_id":74488286471,"final_update_id":74488286482,"bids":[["2208.26000000","56.96010000"],["2207.81000000","15.49760000"],["2207.37000000","0.68350000"],["2199.01000000","0.52440000"],["2198.61000000","0.00000000"],["1987.44000000","0.16050000"]],"asks":[["2208.27000000","7.26600000"],["2208.57000000","0.00230000"]]}
{"type":"depthUpdate","symbol":"ETHUSDT","event_time_ms":1775758311615,"first_update_id":74488286483,"final_update_id":74488286495,"bids":[["2208.26000000","57.07610000"],["2207.74000000","0.00230000"],["2206.11000000","4.18810000"],["2206.00000000","16.55880000"],["2205.74000000","0.20000000"],["2198.99000000","0.00230000"],["1987.44000000","0.15490000"]],"asks":[["2208.63000000","0.04160000"],["2209.25000000","0.00000000"]]}
{"type":"depthUpdate","symbol":"ETHUSDT","event_time_ms":1775758311716,"first_update_id":74488286496,"final_update_id":74488286504,"bids":[["2207.43000000","16.53450000"],["2207.09000000","9.54680000"],["2206.28000000","0.00000000"],["1987.44000000","0.16050000"]],"asks":[["2208.27000000","6.16640000"],["2208.57000000","0.00470000"],["2209.25000000","0.08310000"]]}
{"type":"depthUpdate","symbol":"ETHUSDT","event_time_ms":1775758311815,"first_update_id":74488286505,"final_update_id":74488286509,"bids":[["2205.21000000","29.53220000"],["1987.44000000","0.16050000"]],"asks":[]}
{"type":"depthUpdate","symbol":"ETHUSDT","event_time_ms":1775758312015,"first_update_id":74488286535,"final_update_id":74488286542,"bids":[["2205.72000000","11.81300000"],["1987.44000000","0.16620000"],["1324.00000000","0.94370000"]],"asks":[]}
{"type":"depthUpdate","symbol":"ETHUSDT","event_time_ms":1775758312315,"first_update_id":74488286565,"final_update_id":74488286570,"bids":[["2207.45000000","23.84280000"],["2205.00000000","4.20880000"],["1987.44000000","0.16050000"]],"asks":[]}
{"type":"depthUpdate","symbol":"ETHUSDT","event_time_ms":1775758312415,"first_update_id":74488286571,"final_update_id":74488286575,"bids":[["1987.44000000","0.16050000"]],"asks":[["2209.63000000","0.00000000"]]}
{"type":"depthUpdate","symbol":"ETHUSDT","event_time_ms":1775758312515,"first_update_id":74488286576,"final_update_id":74488286596,"bids":[["2208.26000000","57.01800000"],["2208.24000000","0.04650000"],["2208.14000000","0.02940000"],["2208.01000000","0.59820000"],["2206.99000000","8.16920000"],["2206.71000000","0.39200000"],["2199.11000000","0.52440000"],["2199.01000000","0.00000000"],["2174.51000000","0.00500000"],["1987.44000000","0.16620000"]],"asks":[["2208.27000000","7.31390000"],["2208.29000000","0.01200000"],["2208.41000000","0.02100000"],["2208.54000000","0.05180000"],["2209.61000000","10.48950000"],["2210.16000000","8.73750000"]]}
{"type":"depthUpdate","symbol":"ETHUSDT","event_time_ms":1775758312615,"first_update_id":74488286597,"final_update_id":74488286601,"bids":[["1987.44000000","0.17180000"]],"asks":[]}
{"type":"depthUpdate","symbol":"ETHUSDT","event_time_ms":1775758312915,"first_update_id":74488286627,"final_update_id":74488286641,"bids":[["2208.09000000","0.00000000"],["1987.44000000","0.15490000"]],"asks":[["2208.27000000","6.16910000"],["2208.57000000","0.00230000"],["2211.19000000","10.46300000"],["2211.23000000","4.92790000"],["2211.79000000","5.27810000"],["2213.05000000","0.95960000"],["2217.04000000","0.71350000"],["2220.04000000","0.00000000"],["2429.10000000","0.00000000"]]}
{"type":"depthUpdate","symbol":"ETHUSDT","event_time_ms":1775758313415,"first_update_id":74488286684,"final_update_id":74488286705,"bids":[["2208.25000000","7.44140000"],["2208.13000000","18.15020000"],["2208.10000000","29.60730000"],["2207.81000000","15.45230000"],["2204.01000000","0.06620000"],["1987.44000000","0.16050000"],["1324.63000000","0.00460000"],["1324.12000000","0.00000000"],["1323.44000000","0.00460000"],["1323.11000000","0.00000000"],["1321.80000000","0.00000000"],["1320.99000000","0.01380000"],["1320.88000000","0.31090000"]],"asks":[]}
{"type":"depthUpdate","symbol":"ETHUSDT","event_time_ms":1775758313515,"first_update_id":74488286706,"final_update_id":74488286720,"bids":[["2208.25000000","0.00980000"],["2208.21000000","0.00940000"],["2208.20000000","0.56620000"],["2207.94000000","0.09280000"],["2207.81000000","15.45230000"],["2207.37000000","0.00510000"],["2206.75000000","7.85990000"],["2199.11000000","0.00000000"],["2198.61000000","0.52450000"],["2158.19000000","1.55890000"],["1987.44000000","0.16050000"]],"asks":[]}
{"type":"depthUpdate","symbol":"ETHUSDT","event_time_ms":1775758313615,"first_update_id":74488286721,"final_update_id":74488286736,"bids":[["2208.21000000","0.85810000"],["2208.17000000","1.64550000"],["2207.95000000","21.33100000"],["2207.37000000","0.00510000"],["1987.44000000","0.16060000"]],"asks":[["2211.32000000","1.99700000"],["2217.04000000","0.00450000"],["2217.98000000","0.00000000"],["2218.92000000","0.71180000"]]}
{"type":"depthUpdate","symbol":"ETHUSDT","event_time_ms":1775758313815,"first_update_id":74488286751,"final_update_id":74488286764,"bids":[["2207.74000000","0.09270000"],["2199.11000000","0.52440000"],["2198.61000000","0.00000000"],["2150.02000000","0.00500000"],["2025.73000000","0.01860000"],["1987.44000000","0.16050000"],["1324.00000000","0.94370000"]],"asks":[["2208.63000000","0.04160000"]]}
{"type":"depthUpdate","symbol":"ETHUSDT","event_time_ms":1775758313915,"first_update_id":74488286765,"final_update_id":74488286770,"bids":[["2207.71000000","0.59800000"],["2207.37000000","0.68350000"],["1987.44000000","0.16050000"]],"asks":[]}
{"type":"depthUpdate","symbol":"ETHUSDT","event_time_ms":1775758314015,"first_update_id":74488286771,"final_update_id":74488286776,"bids":[["2199.11000000","0.00000000"],["2198.62000000","0.63830000"],["1987.44000000","0.15490000"]],"asks":[]}
{"type":"depthUpdate","symbol":"ETHUSDT","event_time_ms":1775758314116,"first_update_id":74488286777,"final_update_id":74488286782,"bids":[["2207.59000000","2.90530000"],["2207.06000000","0.00000000"],["2141.86000000","0.00240000"],["1987.44000000","0.16050000"]],"asks":[]}
{"type":"depthUpdate","symbol":"ETHUSDT","event_time_ms":1775758314215,"first_update_id":74488286783,"final_update_id":74488286835,"bids":[["2208.26000000","58.41910000"],["2208.19000000","4.65100000"],["2208.07000000","0.00230000"],["2208.03000000","16.64980000"],["2207.91000000","0.31830000"],["2207.81000000","15.79150000"],["2207.69000000","13.64820000"],["2207.37000000","0.00510000"],["2207.19000000","13.61260000"],["2207.09000000","9.52880000"],["2205.23000000","0.11340000"],["2205.08000000","1.36480000"],["1987.44000000","0.16620000"]],"asks":[["2208.27000000","0.14810000"],["2208.47000000","0.00940000"],["2208.69000000","0.04900000"],["2208.70000000","0.00460000"],["2208.72000000","0.00300000"],["2208.77000000","0.00000000"],["2208.82000000","4.15180000"],["2208.83000000","25.49450000"],["2208.84000000","0.00000000"],["2208.85000000","0.00670000"],["2208.86000000","12.75890000"],["2208.87000000","0.05270000"],["2208.88000000","2.49900000"],["2208.89000000","0.72580000"],["2209.01000000","0.80000000"],["2209.03000000","0.76890000"],["2209.16000000","2.35200000"],["2209.21000000","14.71010000"],["2209.25000000","0.00000000"],["2209.33000000","0.12240000"]]}
{"type":"depthUpdate","symbol":"ETHUSDT","event_time_ms":1775758314315,"first_update_id":74488286836,"final_update_id":74488287586,"bids":[["2208.43000000","44.37790000"],["2208.42000000","0.00000000"],["2208.41000000","14.08070000"],["2208.40000000","16.31260000"],["2208.39000000","2.38710000"],["2208.38000000","0.00470000"],["2208.37000000","0.00000000"],["2208.36000000","0.00230000"],["2208.35000000","0.00000000"],["2208.33000000","0.00000000"],["2208.32000000","4.19610000"],["2208.31000000","10.09390000"],["2208.30000000","9.88520000"],["2208.29000000","0.00000000"],["2208.28000000","21.54540000"],["2208.27000000","39.02520000"],["2208.26000000","4.41510000"],["2208.24000000","0.03710000"],["2208.21000000","0.01610000"],["2208.20000000","16.86470000"],["2208.19000000","0.58080000"],["2208.18000000","0.00230000"],["2208.17000000","1.64310000"],["2208.16000000","0.00770000"],["2208.14000000","0.00510000"],["2208.13000000","18.20840000"],["2208.10000000","30.96770000"],["2208.09000000","9.65130000"],["2208.08000000","0.56400000"],["2208.07000000","0.18080000"],["2208.06000000","0.07750000"],["2208.03000000","16.31060000"],["2208.02000000","14.32050000"],["2207.98000000","0.95220000"],["2207.89000000","0.00240000"],["2207.86000000","0.50330000"],["2207.85000000","0.06840000"],["2207.83000000","5.43500000"],["2207.81000000","15.11310000"],["2207.80000000","0.06230000"],["2207.79000000","11.97000000"],["2207.77000000","1.36550000"],["2207.76000000","41.54900000"],["2207.70000000","0.03850000"],["2207.67000000","0.00230000"],["2207.64000000","0.00000000"],["2207.62000000","55.36890000"],["2207.60000000","0.00300000"],["2207.58000000","0.02250000"],["2207.49000000","0.55060000"],["2207.46000000","13.25220000"],["2207.42000000","0.00000000"],["2207.26000000","0.00960000"],["2207.18000000","4.08380000"],["2207.08000000","11.83260000"],["2206.83000000","0.00000000"],["2206.79000000","0.00000000"],["2206.76000000","0.00230000"],["2204.90000000","0.00000000"],["2204.33000000","0.00000000"],["2204.29000000","0.00000000"],["2203.65000000","15.88140000"],["2203.38000000","1.00410000"],["2203.25000000","0.00000000"],["2203.23000000","0.00810000"],["2203.17000000","0.00000000"],["2201.65000000","0.04740000"],["2200.29000000","4.93870000"],["1987.44000000","0.00930000"],["1708.28000000","0.01720000"]],"asks":[["2208.27000000","0.00000000"],["2208.28000000","0.00000000"],["2208.29000000","0.00000000"],["2208.31000000","0.00000000"],["2208.32000000","0.00000000"],["2208.33000000","0.00000000"],["2208.34000000","0.00000000"],["2208.36000000","0.00000000"],["2208.37000000","0.00000000"],["2208.38000000","0.00000000"],["2208.40000000","0.00000000"],["2208.41000000","0.00000000"],["2208.42000000","0.00000000"],["2208.43000000","0.00000000"],["2208.44000000","0.03110000"],["2208.45000000","0.00720000"],["2208.46000000","0.00960000"],["2208.47000000","0.01180000"],["2208.48000000","5.17200000"],["2208.49000000","0.00480000"],["2208.50000000","0.00710000"],["2208.51000000","0.00710000"],["2208.52000000","0.00480000"],["2208.53000000","0.01400000"],["2208.54000000","0.00710000"],["2208.55000000","0.02110000"],["2208.56000000","0.11860000"],["2208.57000000","0.00240000"],["2208.58000000","0.01670000"],["2208.60000000","0.00580000"],["2208.65000000","0.02500000"],["2208.67000000","0.04990000"],["2208.68000000","0.05480000"],["2208.69000000","0.04660000"],["2208.71000000","0.00240000"],["2208.72000000","0.56490000"],["2208.73000000","0.04980000"],["2208.74000000","0.00240000"],["2208.75000000","2.03670000"],["2208.76000000","0.00690000"],["2208.78000000","0.14790000"],["2208.79000000","4.77250000"],["2208.80000000","0.01280000"],["2208.81000000","1.52060000"],["2208.82000000","0.07030000"],["2208.83000000","0.00230000"],["2208.85000000","0.00670000"],["2208.86000000","0.73730000"],["2208.87000000","0.05500000"],["2208.88000000","2.09900000"],["2208.89000000","0.62580000"],["2208.91000000","0.12710000"],["2208.95000000","0.54510000"],["2208.96000000","0.05900000"],["2208.97000000","0.32630000"],["2208.98000000","0.00000000"],["2208.99000000","21.40080000"],["2209.00000000","0.11780000"],["2209.01000000","1.20000000"],["2209.03000000","11.84280000"],["2209.04000000","0.68540000"],["2209.05000000","9.60400000"],["2209.06000000","0.00000000"],["2209.12000000","0.00300000"],["2209.13000000","13.61770000"],["2209.14000000","0.03250000"],["2209.15000000","20.27680000"],["2209.16000000","2.75860000"],["2209.18000000","11.80430000"],["2209.19000000","21.47980000"],["2209.20000000","0.00300000"],["2209.21000000","0.20000000"],["2209.23000000","0.03460000"],["2209.26000000","4.08720000"],["2209.27000000","13.61260000"],["2209.28000000","0.00300000"],["2209.29000000","12.48260000"],["2209.30000000","0.00000000"],["2209.32000000","11.82760000"],["2209.33000000","0.29550000"],["2209.34000000","0.01390000"],["2209.35000000","0.00740000"],["2209.36000000","9.53180000"],["2209.39000000","0.04520000"],["2209.40000000","0.00000000"],["2209.41000000","0.13000000"],["2209.44000000","0.11620000"],["2209.45000000","14.91600000"],["2209.46000000","0.00510000"],["2209.49000000","0.05440000"],["2209.50000000","0.97950000"],["2209.54000000","4.08380000"],["2209.59000000","11.83000000"],["2209.60000000","9.53180000"],["2209.62000000","0.00000000"],["2209.66000000","13.72580000"],["2209.69000000","0.67850000"],["2209.73000000","0.00000000"],["2209.95000000","0.03000000"],["2210.04000000","0.03000000"],["2210.19000000","1.02140000"],["2210.47000000","1.32060000"],["2211.02000000","0.00340000"],["2211.32000000","0.00000000"],["2211.91000000","0.00000000"],["2212.07000000","1.09750000"],["2212.22000000","10.86440000"],["2212.55000000","0.00000000"],["2213.05000000","0.00000000"],["2214.09000000","113.01140000"],["2215.37000000","0.00000000"],["2217.37000000","2.81490000"],["2220.33000000","0.03510000"],["2227.16000000","0.00000000"],["2300.00000000","1199.54010000"]]}
{"type":"depthUpdate","symbol":"ETHUSDT","event_time_ms":1775758314415,"first_update_id":74488287587,"final_update_id":74488287861,"bids":[["2208.47000000","53.22980000"],["2208.46000000","1.41910000"],["2208.45000000","0.00000000"],["2208.44000000","0.00000000"],["2208.43000000","1.94680000"],["2208.42000000","0.03000000"],["2208.41000000","13.38690000"],["2208.40000000","0.01410000"],["2208.39000000","3.42420000"],["2208.38000000","0.00470000"],["2208.36000000","0.00750000"],["2208.33000000","0.25630000"],["2208.32000000","21.92450000"],["2208.31000000","5.90020000"],["2208.30000000","0.00000000"],["2208.28000000","7.46400000"],["2208.26000000","0.35480000"],["2208.25000000","0.00740000"],["2208.24000000","0.07990000"],["2208.23000000","0.04980000"],["2208.22000000","0.40000000"],["2208.21000000","5.72650000"],["2208.19000000","0.03190000"],["2208.17000000","1.66080000"],["2208.14000000","0.00850000"],["2208.13000000","18.20610000"],["2208.12000000","0.00000000"],["2208.09000000","9.65590000"],["2208.07000000","0.20330000"],["2208.02000000","14.77330000"],["2207.98000000","0.00230000"],["2207.97000000","2.84470000"],["2207.95000000","21.32870000"],["2207.92000000","0.01380000"],["2207.91000000","0.31830000"],["2207.90000000","0.47060000"],["2207.88000000","0.45030000"],["2207.87000000","0.00000000"],["2207.86000000","0.50100000"],["2207.85000000","0.06610000"],["2207.83000000","4.98210000"],["2207.80000000","0.10730000"],["2207.77000000","0.00670000"],["2207.74000000","0.09040000"],["2207.63000000","18.67800000"],["2207.52000000","0.09600000"],["2207.50000000","0.12910000"],["2207.33000000","4.13030000"],["2207.08000000","11.82030000"],["2207.07000000","0.00480000"],["2206.98000000","16.31700000"],["2205.79000000","5.29100000"],["2204.92000000","11.66660000"],["2203.73000000","0.49890000"],["2203.43000000","2.47500000"],["2201.31000000","0.00000000"],["2201.20000000","0.04250000"],["2201.14000000","0.00240000"],["2133.70000000","0.00240000"],["1987.63000000","0.08790000"]],"asks":[["2208.44000000","0.00000000"],["2208.45000000","0.00000000"],["2208.46000000","0.00000000"],["2208.47000000","0.00000000"],["2208.48000000","5.18160000"],["2208.49000000","0.00720000"],["2208.54000000","0.00710000"],["2208.55000000","0.02830000"],["2208.56000000","0.11870000"],["2208.57000000","0.00240000"],["2208.58000000","0.01440000"],["2208.59000000","0.00460000"],["2208.63000000","0.03930000"],["2208.71000000","0.00480000"],["2208.72000000","1.70990000"],["2208.73000000","0.05220000"],["2208.74000000","1.80450000"],["2208.75000000","0.00000000"],["2208.78000000","1.17920000"],["2208.79000000","4.77010000"],["2208.80000000","1.65800000"],["2208.81000000","1.51820000"],["2208.82000000","0.07260000"],["2208.85000000","1.04540000"],["2208.88000000","2.10130000"],["2208.91000000","1.27220000"],["2208.93000000","1.41510000"],["2208.97000000","7.81450000"],["2208.98000000","15.21030000"],["2208.99000000","0.00000000"],["2209.01000000","4.08380000"],["2209.03000000","13.20080000"],["2209.04000000","10.21420000"],["2209.05000000","0.07520000"],["2209.06000000","1.20000000"],["2209.15000000","0.00000000"],["2209.28000000","1.10050000"],["2209.29000000","0.72420000"],["2209.30000000","0.03000000"],["2209.33000000","0.02240000"],["2209.46000000","11.25890000"],["2209.48000000","0.00570000"],["2209.57000000","0.30210000"],["2209.58000000","10.49850000"],["2209.61000000","0.00230000"],["2209.94000000","0.29570000"],["2210.16000000","8.39800000"],["2211.00000000","15.17510000"],["2211.40000000","2.00160000"],["2211.79000000","10.36630000"],["2215.03000000","0.00460000"],["2215.14000000","0.00460000"]]}
{"type":"depthUpdate","symbol":"ETHUSDT","event_time_ms":1775758314515,"first_update_id":74488287862,"final_update_id":74488287911,"bids":[["2208.47000000","53.32560000"],["2208.46000000","1.42150000"],["2208.43000000","1.83480000"],["2208.42000000","0.03240000"],["2208.36000000","0.00510000"],["2208.32000000","15.64270000"],["2208.31000000","5.89780000"],["2208.09000000","9.67950000"],["2207.69000000","22.04840000"],["2207.36000000","5.93880000"],["2207.35000000","0.00000000"],["2207.33000000","0.00670000"],["2206.31000000","3.48530000"],["2206.01000000","0.47520000"],["1987.63000000","0.09910000"]],"asks":[["2208.48000000","5.19090000"],["2208.55000000","0.02590000"],["2208.73000000","0.04980000"],["2208.79000000","4.09510000"],["2208.81000000","0.68120000"],["2208.86000000","0.03530000"],["2208.88000000","1.48270000"],["2208.89000000","0.00480000"],["2208.90000000","0.00000000"],["2210.12000000","1.99580000"],["2215.14000000","0.00000000"],["2218.92000000","0.00280000"],["2220.33000000","0.00510000"]]}
{"type":"depthUpdate","symbol":"ETHUSDT","event_time_ms":1775758314715,"first_update_id":74488287930,"final_update_id":74488287940,"bids":[["2208.46000000","1.53510000"],["2208.02000000","15.79090000"],["1987.63000000","0.13280000"]],"asks":[["2208.48000000","5.19090000"],["2208.84000000","0.00000000"],["2208.96000000","0.25900000"],["2209.37000000","11.13510000"]]}
{"type":"depthUpdate","symbol":"ETHUSDT","event_time_ms":1775758314915,"first_update_id":74488287952,"final_update_id":74488287975,"bids":[["2208.43000000","1.84420000"],["2208.40000000","0.00470000"],["2208.31000000","5.92210000"],["2208.26000000","0.21450000"],["2208.17000000","1.69420000"],["2208.13000000","18.15020000"],["1987.63000000","0.15520000"],["1337.06000000","0.00000000"],["1333.89000000","0.00000000"],["1333.43000000","0.01800000"],["1332.15000000","0.00000000"],["1331.64000000","0.01380000"],["1331.21000000","0.04660000"],["1331.11000000","0.03680000"],["1330.97000000","0.00460000"],["1329.89000000","0.00460000"]],"asks":[["2208.50000000","0.01430000"],["2208.55000000","0.00720000"],["2208.59000000","0.02330000"],["2208.68000000","0.01180000"],["2208.72000000","1.75290000"],["2209.11000000","0.29700000"],["2209.18000000","28.10520000"],["2210.72000000","0.29700000"],["2211.19000000","6.46450000"],["2211.39000000","1.99700000"]]}
{"type":"depthUpdate","symbol":"ETHUSDT","event_time_ms":1775758315015,"first_update_id":74488287976,"final_update_id":74488287986,"bids":[["2208.24000000","0.08050000"],["2208.02000000","15.11250000"],["2199.51000000","3.00710000"],["2198.62000000","0.11380000"],["2117.38000000","0.00240000"],["1987.63000000","0.16630000"],["1708.28000000","0.00520000"]],"asks":[["2210.72000000","0.00000000"]]}
{"type":"depthUpdate","symbol":"ETHUSDT","event_time_ms":1775758315115,"first_update_id":74488287987,"final_update_id":74488287996,"bids":[["2208.13000000","18.21020000"],["2208.06000000","0.07990000"],["2207.76000000","41.49940000"],["2207.58000000","0.70090000"],["2207.52000000","0.03600000"],["2207.48000000","4.09230000"],["2207.21000000","17.83050000"],["2206.93000000","15.12700000"],["2206.66000000","0.00000000"],["2206.39000000","0.03310000"],["1987.63000000","0.17190000"]],"asks":[["2208.55000000","0.00960000"],["2208.77000000","0.00240000"],["2208.98000000","14.06520000"],["2209.55000000","16.30090000"],["2209.67000000","0.00000000"],["2211.60000000","0.00460000"],["2211.87000000","0.11310000"],["2212.15000000","0.00000000"],["2212.42000000","0.00000000"],["2212.69000000","0.00000000"],["2212.97000000","0.00000000"],["2213.24000000","1.84290000"],["2213.52000000","0.02260000"],["2213.79000000","0.00230000"],["2214.07000000","0.03690000"],["2214.34000000","0.00000000"],["2214.61000000","0.02140000"]]}
{"type":"depthUpdate","symbol":"ETHUSDT","event_time_ms":1775758315215,"first_update_id":74488287997,"final_update_id":74488288022,"bids":[["1987.63000000","0.18310000"]],"asks":[["2208.77000000","0.00000000"],["2208.91000000","1.15020000"],["2208.97000000","5.88260000"],["2209.03000000","13.87580000"],["2209.05000000","0.91220000"],["2209.09000000","0.46160000"],["2209.11000000","0.62100000"],["2209.12000000","0.62400000"],["2209.13000000","13.88770000"],["2210.82000000","0.33070000"],["2210.83000000","7.25670000"],["2210.85000000","0.85630000"],["2210.89000000","1.77430000"],["2210.91000000","16.71160000"],["2210.92000000","14.23590000"],["2210.93000000","12.06760000"]]}
{"type":"depthUpdate","symbol":"ETHUSDT","event_time_ms":1775758315815,"first_update_id":74488288086,"final_update_id":74488289169,"bids":[["2208.47000000","0.00000000"],["2208.46000000","0.00000000"],["2208.44000000","0.00000000"],["2208.43000000","0.00000000"],["2208.42000000","0.00000000"],["2208.41000000","0.00000000"],["2208.40000000","0.00000000"],["2208.39000000","0.00000000"],["2208.38000000","0.00000000"],["2208.36000000","0.00000000"],["2208.34000000","0.00000000"],["2208.33000000","0.00000000"],["2208.32000000","0.00000000"],["2208.31000000","0.00000000"],["2208.29000000","0.00000000"],["2208.28000000","0.00000000"],["2208.27000000","0.00000000"],["2208.26000000","0.00000000"],["2208.25000000","0.00000000"],["2208.24000000","0.00000000"],["2208.23000000","0.00000000"],["2208.22000000","0.00000000"],["2208.21000000","0.00000000"],["2208.20000000","0.00000000"],["2208.19000000","0.00000000"],["2208.18000000","0.00000000"],["2208.17000000","0.00000000"],["2208.16000000","0.00000000"],["2208.15000000","0.00000000"],["2208.14000000","0.00000000"],["2208.13000000","0.00000000"],["2208.12000000","0.00000000"],["2208.11000000","0.00000000"],["2208.10000000","0.00000000"],["2208.09000000","0.00000000"],["2208.08000000","0.00000000"],["2208.07000000","0.00000000"],["2208.06000000","0.00000000"],["2208.05000000","0.00000000"],["2208.04000000","0.00000000"],["2208.03000000","0.00000000"],["2208.02000000","27.51050000"],["2208.01000000","0.55900000"],["2208.00000000","1.40840000"],["2207.99000000","9.86990000"],["2207.98000000","0.00950000"],["2207.97000000","2.84710000"],["2207.96000000","0.00470000"],["2207.95000000","0.00700000"],["2207.94000000","0.00470000"],["2207.93000000","0.00700000"],["2207.92000000","0.01860000"],["2207.91000000","0.73690000"],["2207.90000000","0.27230000"],["2207.89000000","0.02620000"],["2207.88000000","0.45260000"],["2207.87000000","0.00000000"],["2207.86000000","0.04750000"],["2207.85000000","0.06840000"],["2207.84000000","0.00990000"],["2207.83000000","0.00230000"],["2207.82000000","0.00000000"],["2207.81000000","6.74050000"],["2207.80000000","12.01760000"],["2207.79000000","11.97230000"],["2207.76000000","0.00300000"],["2207.75000000","0.07140000"],["2207.74000000","0.00230000"],["2207.71000000","0.00000000"],["2207.70000000","0.26710000"],["2207.69000000","21.05320000"],["2207.67000000","0.04830000"],["2207.66000000","0.11560000"],["2207.64000000","0.00230000"],["2207.63000000","0.04000000"],["2207.62000000","0.04750000"],["2207.61000000","0.07750000"],["2207.59000000","1.54860000"],["2207.58000000","1.50230000"],["2207.54000000","11.79990000"],["2207.53000000","0.02270000"],["2207.52000000","23.37810000"],["2207.50000000","0.09910000"],["2207.49000000","0.00000000"],["2207.48000000","0.00850000"],["2207.47000000","0.00000000"],["2207.46000000","4.08380000"],["2207.45000000","0.70140000"],["2207.44000000","0.11630000"],["2207.43000000","0.23360000"],["2207.39000000","11.80690000"],["2207.38000000","23.14140000"],["2207.37000000","13.90630000"],["2207.36000000","16.34090000"],["2207.35000000","0.02250000"],["2207.34000000","0.03000000"],["2207.31000000","4.56610000"],["2207.28000000","0.00530000"],["2207.26000000","0.01190000"],["2207.25000000","1.88760000"],["2207.23000000","9.73630000"],["2207.22000000","25.52810000"],["2207.19000000","0.00000000"],["2207.18000000","8.28820000"],["2207.17000000","5.04620000"],["2207.15000000","1.43240000"],["2207.09000000","0.00000000"],["2207.08000000","0.02270000"],["2207.07000000","0.03480000"],["2207.06000000","0.00000000"],["2207.05000000","0.00000000"],["2207.04000000","0.01150000"],["2206.98000000","16.34700000"],["2206.93000000","15.12930000"],["2206.89000000","0.04970000"],["2206.72000000","0.00300000"],["2206.71000000","0.03000000"],["2206.65000000","0.06670000"],["2206.49000000","7.13450000"],["2206.44000000","0.00670000"],["2206.01000000","0.00000000"],["2205.74000000","0.00000000"],["2205.48000000","2.67500000"],["2205.27000000","0.00000000"],["2205.21000000","0.13170000"],["2205.08000000","0.01730000"],["2204.72000000","0.00000000"],["2204.68000000","0.00690000"],["2202.22000000","0.15890000"],["2200.73000000","0.00000000"],["2200.72000000","0.06980000"],["2199.48000000","227.31440000"],["2088.00000000","37.18410000"],["1987.63000000","0.07670000"],["1987.56000000","0.00000000"],["1708.43000000","0.00600000"]],"asks":[["2208.03000000","14.62770000"],["2208.04000000","7.94620000"],["2208.05000000","0.00000000"],["2208.06000000","0.00000000"],["2208.07000000","0.00000000"],["2208.08000000","0.00000000"],["2208.09000000","0.00000000"],["2208.10000000","0.00000000"],["2208.11000000","0.00000000"],["2208.12000000","0.00000000"],["2208.13000000","0.00240000"],["2208.14000000","0.00230000"],["2208.15000000","0.00000000"],["2208.16000000","0.00000000"],["2208.18000000","0.00000000"],["2208.19000000","0.00000000"],["2208.20000000","0.00000000"],["2208.21000000","0.00000000"],["2208.22000000","0.00000000"],["2208.23000000","0.00470000"],["2208.24000000","0.00470000"],["2208.25000000","0.00230000"],["2208.26000000","0.00670000"],["2208.27000000","0.00470000"],["2208.28000000","0.00000000"],["2208.29000000","0.00000000"],["2208.30000000","0.00000000"],["2208.32000000","0.00000000"],["2208.33000000","0.00000000"],["2208.34000000","0.00000000"],["2208.35000000","0.00240000"],["2208.36000000","0.04750000"],["2208.37000000","0.00000000"],["2208.38000000","1.90240000"],["2208.39000000","35.62730000"],["2208.40000000","0.55540000"],["2208.41000000","0.00000000"],["2208.42000000","13.64730000"],["2208.43000000","15.88140000"],["2208.44000000","0.00470000"],["2208.45000000","0.00000000"],["2208.47000000","5.70910000"],["2208.48000000","5.43080000"],["2208.49000000","0.00480000"],["2208.50000000","0.58170000"],["2208.51000000","0.03930000"],["2208.52000000","0.00000000"],["2208.53000000","0.00920000"],["2208.54000000","0.00230000"],["2208.55000000","0.00240000"],["2208.56000000","13.73120000"],["2208.57000000","25.41250000"],["2208.59000000","0.02330000"],["2208.60000000","0.08330000"],["2208.61000000","0.00900000"],["2208.62000000","16.53180000"],["2208.66000000","0.00230000"],["2208.67000000","0.10230000"],["2208.68000000","0.00230000"],["2208.69000000","11.94280000"],["2208.70000000","13.61720000"],["2208.71000000","25.41260000"],["2208.72000000","0.65370000"],["2208.73000000","0.04980000"],["2208.74000000","0.00000000"],["2208.77000000","0.00000000"],["2208.78000000","0.14550000"],["2208.79000000","0.00230000"],["2208.80000000","17.42420000"],["2208.81000000","0.68120000"],["2208.84000000","29.91580000"],["2208.85000000","0.00670000"],["2208.87000000","15.93640000"],["2208.90000000","9.52880000"],["2208.91000000","1.10260000"],["2208.93000000","0.27000000"],["2208.95000000","0.00930000"],["2208.96000000","0.25900000"],["2208.97000000","6.75630000"],["2208.98000000","14.36520000"],["2209.00000000","16.41870000"],["2209.01000000","4.08380000"],["2209.02000000","16.20220000"],["2209.05000000","0.86940000"],["2209.07000000","11.97100000"],["2209.11000000","0.72100000"],["2209.17000000","14.91260000"],["2209.21000000","0.00000000"],["2209.24000000","0.00280000"],["2209.35000000","0.00510000"],["2209.37000000","10.18360000"],["2209.39000000","0.00000000"],["2209.41000000","0.03000000"],["2209.45000000","13.96080000"],["2209.46000000","11.25660000"],["2209.48000000","0.00570000"],["2209.57000000","0.29980000"],["2209.69000000","0.00000000"],["2209.70000000","4.19790000"],["2209.77000000","0.00000000"],["2209.86000000","4.08380000"],["2209.94000000","0.33900000"],["2209.95000000","0.00000000"],["2210.04000000","0.00000000"],["2210.19000000","1.01470000"],["2210.97000000","28.26670000"],["2211.66000000","11.75210000"],["2211.79000000","9.01200000"],["2212.06000000","0.00460000"],["2212.35000000","0.00300000"],["2212.39000000","0.00460000"],["2212.73000000","1.19630000"],["2212.98000000","0.96310000"],["2213.26000000","9.01620000"],["2213.27000000","0.01050000"],["2213.40000000","0.00230000"],["2213.42000000","0.00000000"],["2213.44000000","0.11300000"],["2216.81000000","0.00000000"],["2708.44000000","0.00600000"]]}
{"type":"depthUpdate","symbol":"ETHUSDT","event_time_ms":1775758315915,"first_update_id":74488289170,"final_update_id":74488289372,"bids":[["2208.02000000","38.11920000"],["2208.01000000","2.57990000"],["2208.00000000","0.27540000"],["2207.99000000","0.81240000"],["2207.98000000","0.00470000"],["2207.97000000","1.48840000"],["2207.96000000","0.52730000"],["2207.95000000","0.00470000"],["2207.92000000","0.01380000"],["2207.91000000","0.27230000"],["2207.90000000","0.27460000"],["2207.89000000","0.00240000"],["2207.81000000","10.82430000"],["2207.75000000","1.71240000"],["2207.70000000","35.20610000"],["2207.69000000","0.10230000"],["2207.66000000","0.11790000"],["2207.65000000","4.09280000"],["2207.62000000","0.07100000"],["2207.61000000","0.07750000"],["2207.60000000","4.08680000"],["2207.55000000","17.23010000"],["2207.54000000","0.00230000"],["2207.53000000","25.43290000"],["2207.52000000","9.76550000"],["2207.50000000","0.10140000"],["2207.47000000","1.35850000"],["2207.45000000","1.14080000"],["2207.40000000","0.04990000"],["2207.37000000","0.00510000"],["2207.35000000","0.04500000"],["2207.34000000","0.05250000"],["2207.33000000","1.36590000"],["2207.26000000","0.60970000"],["2207.23000000","10.13230000"],["2207.21000000","0.00000000"],["2207.20000000","16.30620000"],["2207.18000000","18.65540000"],["2207.15000000","2.52990000"],["2207.12000000","0.00970000"],["2206.84000000","5.53550000"],["2206.80000000","0.03760000"],["2206.65000000","0.00670000"],["2206.48000000","18.94550000"],["2206.18000000","0.04460000"],["2205.81000000","0.06820000"],["2205.71000000","4.50820000"],["2204.91000000","13.14120000"],["2201.25000000","0.00460000"],["2201.14000000","0.00700000"],["2201.03000000","0.14430000"],["2200.92000000","0.10400000"],["2200.66000000","70.39350000"],["2198.47000000","0.70900000"],["2197.53000000","0.00340000"],["1987.25000000","0.01470000"],["1987.22000000","0.04220000"]],"asks":[["2208.03000000","4.14890000"],["2208.04000000","4.09980000"],["2208.11000000","0.01850000"],["2208.13000000","0.00240000"],["2208.14000000","0.00470000"],["2208.21000000","0.00480000"],["2208.22000000","0.50230000"],["2208.24000000","0.00470000"],["2208.25000000","0.00470000"],["2208.26000000","0.00910000"],["2208.27000000","0.00470000"],["2208.31000000","0.00460000"],["2208.32000000","0.00240000"],["2208.33000000","0.14330000"],["2208.35000000","0.00480000"],["2208.36000000","0.05260000"],["2208.37000000","16.71620000"],["2208.38000000","0.00340000"],["2208.39000000","3.85800000"],["2208.40000000","0.56030000"],["2208.42000000","0.05730000"],["2208.43000000","0.50230000"],["2208.44000000","0.00230000"],["2208.46000000","0.00000000"],["2208.48000000","5.31190000"],["2208.49000000","0.00240000"],["2208.56000000","23.26000000"],["2208.57000000","16.33640000"],["2208.61000000","0.03270000"],["2208.62000000","17.89010000"],["2208.68000000","0.00230000"],["2208.72000000","0.09120000"],["2208.73000000","0.04750000"],["2208.81000000","0.67890000"],["2208.82000000","0.06800000"],["2208.84000000","29.91350000"],["2208.86000000","0.03300000"],["2208.87000000","15.93410000"],["2208.88000000","1.48040000"],["2208.96000000","0.23530000"],["2208.98000000","13.91260000"],["2209.03000000","12.51780000"],["2209.04000000","10.89270000"],["2209.16000000","14.01400000"],["2209.30000000","0.00000000"],["2209.46000000","0.00280000"],["2209.56000000","0.08610000"],["2209.68000000","0.00580000"],["2209.99000000","0.00000000"],["2210.24000000","9.72630000"],["2210.72000000","0.29700000"],["2210.91000000","16.30090000"],["2214.83000000","0.00230000"],["2214.90000000","0.00340000"],["2215.03000000","0.00000000"]]}
{"type":"depthUpdate","symbol":"ETHUSDT","event_time_ms":1775758316015,"first_update_id":74488289373,"final_update_id":74488289436,"bids":[["2208.02000000","38.68520000"],["2208.01000000","1.48380000"],["2207.99000000","0.81480000"],["2207.81000000","26.28300000"],["2207.75000000","1.71470000"],["2207.72000000","0.02250000"],["2207.71000000","16.30090000"],["2207.61000000","0.07980000"],["2207.27000000","0.02740000"],["2200.76000000","0.00000000"],["2200.32000000","12.19500000"],["2199.51000000","2.48280000"],["2199.29000000","0.52430000"],["1987.25000000","0.02940000"],["1987.22000000","0.04780000"],["1708.43000000","0.00000000"]],"asks":[["2208.03000000","0.13820000"],["2208.04000000","0.00930000"],["2208.11000000","0.02090000"],["2208.14000000","0.00470000"],["2208.17000000","4.09280000"],["2208.21000000","0.00720000"],["2208.22000000","0.50470000"],["2208.26000000","0.00670000"],["2208.27000000","0.00230000"],["2208.33000000","1.28470000"],["2208.35000000","0.00480000"],["2208.36000000","1.19870000"],["2208.37000000","1.49150000"],["2208.38000000","0.57020000"],["2208.40000000","0.59540000"],["2208.43000000","0.50460000"],["2208.46000000","2.05770000"],["2208.47000000","12.87410000"],["2208.48000000","5.16720000"],["2208.49000000","0.00000000"],["2208.51000000","0.03690000"],["2208.55000000","1.14670000"],["2208.73000000","0.04520000"],["2208.76000000","0.00460000"],["2208.78000000","0.14320000"],["2208.79000000","0.00000000"],["2208.80000000","17.42190000"],["2214.75000000","0.00000000"],["2708.44000000","0.00000000"]]}
{"type":"depthUpdate","symbol":"ETHUSDT","event_time_ms":1775758316115,"first_update_id":74488289437,"final_update_id":74488289547,"bids":[["2208.02000000","29.67090000"],["2208.01000000","0.01660000"],["2208.00000000","1.64880000"],["2207.99000000","9.06230000"],["2207.98000000","0.00710000"],["2207.97000000","0.05980000"],["2207.92000000","0.01380000"],["2207.91000000","0.00230000"],["2207.90000000","0.00460000"],["2207.89000000","0.00480000"],["2207.88000000","0.18260000"],["2207.81000000","26.28300000"],["2207.79000000","11.97460000"],["2207.77000000","4.09950000"],["2207.75000000","0.07600000"],["2207.72000000","13.63510000"],["2207.71000000","28.09850000"],["2207.70000000","9.79590000"],["2207.66000000","0.11560000"],["2207.65000000","0.00000000"],["2207.62000000","0.04750000"],["2207.61000000","1.30190000"],["2207.58000000","0.30230000"],["2207.53000000","26.63290000"],["2207.35000000","0.28620000"],["2207.33000000","0.00670000"],["2207.24000000","0.03000000"],["2201.98000000","0.26990000"],["2078.21000000","0.00990000"],["1987.25000000","0.04410000"],["1987.24000000","0.02850000"],["1987.22000000","0.08830000"]],"asks":[["2208.03000000","16.24600000"],["2208.11000000","0.02320000"],["2208.14000000","0.00470000"],["2208.16000000","1.72200000"],["2208.17000000","4.09520000"],["2208.21000000","0.00480000"],["2208.23000000","1.15130000"],["2208.25000000","0.00230000"],["2208.31000000","1.10230000"],["2208.32000000","0.00240000"],["2208.36000000","0.05730000"],["2208.37000000","1.55150000"],["2208.43000000","1.64890000"],["2208.55000000","0.00240000"],["2208.69000000","11.94050000"],["2208.70000000","13.61490000"],["2208.94000000","0.00000000"],["2212.98000000","0.00280000"]]}
{"type":"depthUpdate","symbol":"ETHUSDT","event_time_ms":1775758316215,"first_update_id":74488289548,"final_update_id":74488289726,"bids":[["2208.02000000","25.56010000"],["2208.00000000","4.54970000"],["2207.99000000","0.56920000"],["2207.98000000","0.00470000"],["2207.97000000","0.05740000"],["2207.96000000","9.06230000"],["2207.94000000","0.00710000"],["2207.91000000","0.02660000"],["2207.89000000","0.00240000"],["2207.81000000","6.74050000"],["2207.77000000","0.00900000"],["2207.76000000","0.05890000"],["2207.75000000","0.07370000"],["2207.73000000","39.29980000"],["2207.72000000","16.32340000"],["2207.71000000","0.81000000"],["2207.70000000","0.53710000"],["2207.69000000","0.59630000"],["2207.68000000","0.54300000"],["2207.64000000","4.09510000"],["2207.62000000","0.07120000"],["2207.61000000","0.34980000"],["2207.60000000","0.00300000"],["2207.59000000","17.26520000"],["2207.57000000","0.34380000"],["2207.56000000","16.30090000"],["2207.55000000","0.92920000"],["2207.54000000","39.02510000"],["2207.53000000","1.22270000"],["2207.52000000","0.23670000"],["2207.51000000","0.10460000"],["2207.46000000","0.00000000"],["2207.40000000","39.07270000"],["2207.39000000","0.00930000"],["2207.38000000","0.00000000"],["2207.37000000","0.05050000"],["2207.35000000","0.10500000"],["2207.31000000","0.13860000"],["2207.28000000","1.36450000"],["2207.24000000","0.00000000"],["2207.13000000","0.67840000"],["2206.85000000","0.27000000"],["2206.63000000","1.95520000"],["2206.49000000","6.73190000"],["2206.36000000","0.60000000"],["2206.28000000","0.00000000"],["2206.21000000","0.80000000"],["2205.93000000","0.27000000"],["2205.81000000","0.33820000"],["2205.76000000","6.04760000"],["2205.75000000","0.27000000"],["2205.74000000","1.13400000"],["2205.71000000","2.50210000"],["2202.26000000","0.04960000"],["2202.24000000","0.00300000"],["2199.29000000","0.00000000"],["2198.44000000","0.52450000"],["1987.22000000","0.09950000"]],"asks":[["2208.03000000","18.08760000"],["2208.04000000","0.05460000"],["2208.11000000","0.03270000"],["2208.14000000","0.00470000"],["2208.15000000","0.00240000"],["2208.16000000","1.72440000"],["2208.22000000","0.51400000"],["2208.24000000","0.02330000"],["2208.25000000","0.00510000"],["2208.26000000","0.05200000"],["2208.30000000","2.06680000"],["2208.37000000","2.36980000"],["2208.39000000","3.90100000"],["2208.42000000","30.79560000"],["2208.45000000","16.30090000"],["2208.46000000","0.53580000"],["2208.50000000","0.57450000"],["2208.55000000","0.00000000"],["2208.59000000","0.00460000"],["2208.66000000","0.32630000"],["2208.67000000","0.35330000"],["2208.69000000","12.77290000"],["2208.72000000","0.04820000"],["2208.73000000","0.47720000"],["2208.75000000","0.32400000"],["2208.76000000","0.62560000"],["2208.77000000","0.27000000"],["2208.86000000","0.13300000"],["2208.92000000","0.95150000"],["2209.05000000","0.59940000"],["2209.11000000","0.29700000"],["2210.12000000","0.00280000"],["2212.92000000","1.10210000"]]}
{"type":"depthUpdate","symbol":"ETHUSDT","event_time_ms":1775758316315,"first_update_id":74488289727,"final_update_id":74488289871,"bids":[["2208.02000000","34.61030000"],["2208.01000000","0.01420000"],["2207.99000000","0.56920000"],["2207.97000000","0.05740000"],["2207.96000000","0.00470000"],["2207.90000000","0.00230000"],["2207.89000000","0.00000000"],["2207.86000000","0.37750000"],["2207.82000000","0.00000000"],["2207.81000000","23.35680000"],["2207.75000000","0.07600000"],["2207.74000000","55.32600000"],["2207.73000000","0.27700000"],["2207.72000000","0.02480000"],["2207.71000000","1.08000000"],["2207.69000000","0.59860000"],["2207.66000000","0.11790000"],["2207.65000000","5.95010000"],["2207.58000000","0.00230000"],["2207.57000000","0.00460000"],["2207.56000000","16.30330000"],["2207.53000000","1.52270000"],["2207.28000000","0.00530000"],["2207.24000000","1.35930000"],["2207.03000000","0.31530000"],["2206.92000000","11.82460000"],["2205.84000000","0.82670000"],["2205.77000000","0.30310000"],["2205.75000000","0.00000000"],["2205.48000000","2.67500000"],["2205.42000000","9.52880000"],["2205.22000000","0.00000000"],["2204.91000000","11.79760000"],["2204.87000000","14.79820000"],["2204.71000000","9.14760000"],["2203.73000000","13.05050000"],["2202.53000000","1.01910000"],["2200.27000000","0.01120000"],["1987.22000000","0.11070000"]],"asks":[["2208.03000000","19.03360000"],["2208.04000000","1.29660000"],["2208.05000000","4.09280000"],["2208.10000000","0.00450000"],["2208.14000000","0.00470000"],["2208.15000000","0.00720000"],["2208.16000000","0.00480000"],["2208.17000000","0.00240000"],["2208.21000000","0.00720000"],["2208.22000000","0.51400000"],["2208.23000000","0.00460000"],["2208.24000000","0.05330000"],["2208.26000000","0.00900000"],["2208.28000000","0.00240000"],["2208.29000000","0.00000000"],["2208.30000000","0.00000000"],["2208.31000000","0.00920000"],["2208.32000000","0.22880000"],["2208.33000000","0.14330000"],["2208.36000000","15.15700000"],["2208.37000000","0.06240000"],["2208.40000000","0.58580000"],["2208.41000000","29.49400000"],["2208.42000000","0.15730000"],["2208.43000000","0.50460000"],["2208.45000000","0.00000000"],["2208.53000000","0.00690000"],["2208.54000000","0.00000000"],["2208.55000000","9.52880000"],["2208.56000000","13.73120000"],["2208.58000000","0.05960000"],["2208.62000000","1.36290000"],["2208.67000000","0.35100000"],["2208.68000000","16.30090000"],["2208.74000000","0.27000000"],["2208.88000000","1.47800000"],["2208.92000000","0.27310000"],["2209.03000000","12.16680000"],["2209.05000000","0.03000000"],["2209.09000000","0.02960000"],["2209.14000000","0.07870000"],["2209.59000000","11.80000000"],["2209.76000000","14.76860000"],["2210.11000000","13.61260000"],["2210.37000000","0.27000000"],["2210.90000000","19.67020000"]]}
{"type":"depthUpdate","symbol":"ETHUSDT","event_time_ms":1775758316415,"first_update_id":74488289872,"final_update_id":74488289918,"bids":[["2208.02000000","25.55290000"],["2208.01000000","3.21330000"],["2208.00000000","1.65820000"],["2207.96000000","9.06230000"],["2207.67000000","0.34530000"],["2206.86000000","1.96730000"],["2206.36000000","0.00000000"],["2206.21000000","0.00000000"],["2205.77000000","0.03310000"],["2205.76000000","5.77760000"],["2205.74000000","0.86400000"],["2202.80000000","0.32870000"],["2068.42000000","0.00970000"],["1987.22000000","0.12190000"]],"asks":[["2208.03000000","19.02650000"],["2208.04000000","1.29660000"],["2208.05000000","4.09520000"],["2208.10000000","0.00690000"],["2208.15000000","0.00480000"],["2208.21000000","0.00480000"],["2208.22000000","0.51160000"],["2208.26000000","0.00670000"],["2208.28000000","0.00000000"],["2208.36000000","10.73050000"],["2208.40000000","0.59750000"],["2208.68000000","16.57090000"],["2209.03000000","11.84280000"],["2209.12000000","0.00300000"],["2209.13000000","13.61770000"],["2209.47000000","0.04000000"],["2210.06000000","16.30320000"],["2210.27000000","0.35330000"],["2210.90000000","19.40020000"]]}
{"type":"depthUpdate","symbol":"ETHUSDT","event_time_ms":1775758316516,"first_update_id":74488289919,"final_update_id":74488289940,"bids":[["2208.02000000","34.61270000"],["2207.97000000","0.06220000"],["2207.96000000","0.00470000"],["2207.65000000","1.36310000"],["2205.74000000","0.59400000"],["2203.08000000","0.05240000"],["1987.22000000","0.15910000"]],"asks":[["2208.21000000","0.00480000"],["2208.24000000","0.05630000"],["2208.35000000","1.14900000"],["2208.67000000","5.55910000"],["2208.93000000","0.00000000"],["2209.26000000","12.24490000"],["2211.25000000","0.42880000"]]}
{"type":"depthUpdate","symbol":"ETHUSDT","event_time_ms":1775758316615,"first_update_id":74488289941,"final_update_id":74488289965,"bids":[["2208.02000000","34.59250000"],["2208.01000000","0.01420000"],["2207.97000000","0.05980000"],["2207.57000000","0.34380000"],["2207.55000000","1.19920000"],["2207.15000000","2.55990000"],["2205.93000000","0.00000000"],["2205.81000000","0.06820000"],["2205.76000000","5.23760000"],["2205.74000000","0.00000000"],["2205.67000000","0.38340000"],["2205.61000000","10.17700000"],["2203.35000000","7.64260000"],["1987.22000000","0.17030000"]],"asks":[["2208.21000000","0.00480000"],["2208.63000000","0.33630000"],["2208.92000000","0.95150000"],["2209.33000000","1.98050000"],["2210.01000000","20.59790000"]]}
{"type":"depthUpdate","symbol":"ETHUSDT","event_time_ms":1775758316815,"first_update_id":74488289991,"final_update_id":74488290027,"bids":[["2208.02000000","34.60560000"],["2208.00000000","1.65810000"],["2207.94000000","0.00470000"],["2207.91000000","0.02660000"],["2207.76000000","4.09580000"],["2207.75000000","0.13190000"],["2207.70000000","1.15750000"],["2207.66000000","0.11560000"],["2207.65000000","0.00000000"],["2207.63000000","0.04000000"],["2207.28000000","0.02790000"],["2203.90000000","0.04960000"],["1987.22000000","0.21640000"]],"asks":[["2208.03000000","9.02270000"],["2208.04000000","0.05930000"],["2208.05000000","0.00960000"],["2208.11000000","0.02790000"],["2208.16000000","0.00720000"],["2208.17000000","1.40260000"],["2208.18000000","4.09510000"],["2208.21000000","0.02350000"],["2208.24000000","0.03760000"],["2208.30000000","0.04530000"],["2208.37000000","0.10540000"],["2208.38000000","0.57260000"],["2208.39000000","3.85800000"],["2208.44000000","0.00460000"],["2208.66000000","0.32400000"],["2208.79000000","0.04520000"],["2209.02000000","15.90520000"],["2209.29000000","0.67900000"],["2211.42000000","1.38380000"],["2228.02000000","0.00000000"]]}
{"type":"depthUpdate","symbol":"ETHUSDT","event_time_ms":1775758316915,"first_update_id":74488290028,"final_update_id":74488290049,"bids":[["2208.02000000","34.59840000"],["2208.01000000","0.70470000"],["2207.89000000","0.51930000"],["2207.57000000","0.61380000"],["2207.50000000","0.21490000"],["2205.68000000","1.19170000"],["2205.67000000","0.11340000"],["2204.97000000","29.40370000"],["2204.79000000","1.44300000"],["2204.18000000","8.89180000"],["1987.22000000","0.22760000"]],"asks":[["2208.03000000","8.39150000"],["2208.29000000","0.59740000"],["2208.30000000","1.57100000"],["2208.43000000","0.00460000"],["2208.61000000","0.32970000"],["2210.06000000","16.57320000"],["2241.23000000","0.00000000"]]}
{"type":"depthUpdate","symbol":"ETHUSDT","event_time_ms":1775758317015,"first_update_id":74488290050,"final_update_id":74488290068,"bids":[["2208.02000000","34.60080000"],["2208.00000000","1.66050000"],["2207.91000000","0.02890000"],["2207.50000000","0.21490000"],["2205.68000000","0.92170000"],["2204.45000000","9.20260000"],["2048.83000000","0.02290000"],["1987.22000000","0.24450000"]],"asks":[["2208.03000000","9.47020000"],["2208.21000000","0.02110000"],["2208.29000000","1.93240000"],["2208.35000000","0.00480000"],["2208.39000000","3.85800000"],["2208.65000000","0.02270000"],["2210.72000000","0.00000000"]]}
{"type":"depthUpdate","symbol":"ETHUSDT","event_time_ms":1775758317115,"first_update_id":74488290069,"final_update_id":74488290094,"bids":[["2208.02000000","25.54340000"],["2208.01000000","0.00940000"],["2207.95000000","9.06240000"],["2207.90000000","0.00470000"],["2207.87000000","0.00240000"],["2207.74000000","39.02510000"],["2207.24000000","0.00000000"],["2207.23000000","11.49160000"],["2204.73000000","4.13890000"],["1987.22000000","0.25010000"]],"asks":[["2208.03000000","9.47020000"],["2208.05000000","0.01200000"],["2208.16000000","1.14900000"],["2208.17000000","1.40020000"],["2208.22000000","1.65580000"],["2208.24000000","0.03990000"],["2208.28000000","1.74160000"],["2208.29000000","1.33500000"],["2208.30000000","0.04530000"],["2208.40000000","10.35270000"],["2208.64000000","0.00300000"]]}
{"type":"depthUpdate","symbol":"ETHUSDT","event_time_ms":1775758317215,"first_update_id":74488290095,"final_update_id":74488290324,"bids":[["2208.02000000","0.06800000"],["2208.01000000","0.01900000"],["2208.00000000","0.02190000"],["2207.99000000","0.00480000"],["2207.97000000","0.02980000"],["2207.96000000","0.00950000"],["2207.95000000","0.00470000"],["2207.92000000","0.01100000"],["2207.90000000","0.00470000"],["2207.89000000","0.52170000"],["2207.88000000","0.18260000"],["2207.87000000","0.00240000"],["2207.86000000","0.00230000"],["2207.82000000","0.00480000"],["2207.81000000","0.01220000"],["2207.80000000","0.06700000"],["2207.79000000","0.03460000"],["2207.77000000","0.00230000"],["2207.76000000","0.00300000"],["2207.75000000","0.13430000"],["2207.74000000","0.00230000"],["2207.71000000","1.08000000"],["2207.70000000","0.93120000"],["2207.67000000","9.35810000"],["2207.64000000","0.00230000"],["2207.62000000","0.11640000"],["2207.60000000","0.22940000"],["2207.57000000","0.27460000"],["2207.56000000","0.00240000"],["2207.55000000","1.65210000"],["2207.54000000","0.00230000"],["2207.53000000","0.02270000"],["2207.52000000","0.23670000"],["2207.51000000","0.00460000"],["2207.47000000","0.00000000"],["2207.46000000","0.00000000"],["2207.45000000","1.18680000"],["2207.41000000","4.11860000"],["2207.40000000","0.04990000"],["2207.37000000","51.34500000"],["2207.36000000","0.04000000"],["2207.32000000","1.50000000"],["2207.26000000","0.01190000"],["2207.15000000","13.38540000"],["2207.13000000","1.01760000"],["2207.11000000","0.33080000"],["2207.00000000","16.02380000"],["2206.92000000","11.79760000"],["2206.86000000","0.56730000"],["2206.63000000","0.00230000"],["2206.44000000","0.03670000"],["2206.36000000","0.60000000"],["2206.13000000","0.00670000"],["2206.07000000","0.82260000"],["2205.83000000","13.61260000"],["2204.99000000","9.52880000"],["2204.97000000","0.00000000"],["2203.62000000","28.36100000"],["2202.28000000","0.00000000"],["2200.66000000","2.47500000"],["2200.63000000","1.81770000"],["2200.60000000","68.12280000"],["2199.85000000","0.00750000"],["2198.61000000","0.52450000"],["2198.44000000","0.00000000"],["1987.22000000","0.24440000"]],"asks":[["2208.03000000","20.03630000"],["2208.04000000","0.05690000"],["2208.10000000","1.34190000"],["2208.11000000","0.00940000"],["2208.14000000","0.00750000"],["2208.15000000","0.03240000"],["2208.16000000","1.14660000"],["2208.17000000","1.50020000"],["2208.18000000","0.00230000"],["2208.19000000","0.00000000"],["2208.21000000","0.01870000"],["2208.26000000","1.24990000"],["2208.27000000","29.49630000"],["2208.32000000","0.00300000"],["2208.35000000","0.00240000"],["2208.36000000","10.72810000"],["2208.37000000","0.10300000"],["2208.38000000","1.71680000"],["2208.40000000","10.34330000"],["2208.41000000","31.94990000"],["2208.42000000","0.05730000"],["2208.46000000","16.83670000"],["2208.48000000","5.16720000"],["2208.50000000","0.00230000"],["2208.61000000","0.42970000"],["2208.73000000","0.67720000"],["2208.84000000","29.94350000"],["2208.86000000","0.03300000"],["2208.92000000","0.00000000"],["2208.98000000","13.71260000"],["2209.14000000","0.03250000"],["2209.16000000","12.65590000"],["2209.45000000","13.61600000"],["2209.50000000","0.94950000"],["2209.83000000","0.27000000"],["2210.27000000","0.67730000"],["2210.37000000","0.62100000"],["2210.41000000","63.28800000"],["2214.09000000","0.10340000"]]}
{"type":"depthUpdate","symbol":"ETHUSDT","event_time_ms":1775758317315,"first_update_id":74488290325,"final_update_id":74488290521,"bids":[["2208.02000000","12.96300000"],["2208.01000000","0.01180000"],["2208.00000000","0.01950000"],["2207.96000000","0.00710000"],["2207.92000000","0.00760000"],["2207.90000000","0.00470000"],["2207.89000000","0.00480000"],["2207.88000000","0.15260000"],["2207.84000000","0.00530000"],["2207.82000000","0.00240000"],["2207.81000000","0.00980000"],["2207.80000000","0.06460000"],["2207.79000000","0.00460000"],["2207.77000000","1.10230000"],["2207.76000000","0.00300000"],["2207.75000000","0.13190000"],["2207.74000000","0.00230000"],["2207.72000000","10.62240000"],["2207.71000000","2.22420000"],["2207.70000000","0.93120000"],["2207.69000000","0.59860000"],["2207.68000000","1.66250000"],["2207.67000000","0.29930000"],["2207.62000000","0.07120000"],["2207.60000000","26.55740000"],["2207.59000000","0.00740000"],["2207.55000000","1.19920000"],["2207.52000000","1.38090000"],["2207.50000000","0.32780000"],["2207.49000000","0.00000000"],["2207.45000000","2.52180000"],["2207.42000000","4.09280000"],["2207.41000000","1.67680000"],["2207.39000000","1.15350000"],["2207.38000000","40.08840000"],["2207.37000000","16.40600000"],["2207.35000000","0.08250000"],["2207.32000000","0.30000000"],["2207.31000000","1.49710000"],["2207.27000000","0.00490000"],["2207.24000000","0.04530000"],["2207.23000000","10.13230000"],["2207.16000000","1.23000000"],["2207.13000000","0.33920000"],["2207.10000000","0.00000000"],["2207.09000000","0.18120000"],["2207.04000000","0.60910000"],["2206.72000000","11.27080000"],["2206.64000000","0.02570000"],["2206.63000000","0.00230000"],["2206.57000000","29.49400000"],["2206.53000000","0.03000000"],["2206.36000000","0.20000000"],["2206.29000000","1.53400000"],["2206.26000000","25.44020000"],["2206.23000000","0.37590000"],["2206.09000000","0.21400000"],["2205.92000000","9.53750000"],["2205.48000000","2.47500000"],["2205.00000000","4.25840000"],["2204.95000000","0.20000000"],["2204.79000000","0.11800000"],["2203.51000000","0.00890000"],["2203.16000000","33.96530000"],["2203.15000000","0.04120000"],["2202.64000000","45.50710000"],["2200.60000000","0.19430000"],["2200.32000000","11.48600000"],["2200.01000000","0.70910000"],["2199.77000000","67.96920000"],["2039.04000000","0.04620000"],["1987.22000000","0.25000000"]],"asks":[["2208.03000000","19.44630000"],["2208.04000000","0.01160000"],["2208.05000000","0.01430000"],["2208.06000000","0.03000000"],["2208.09000000","0.00000000"],["2208.10000000","0.00690000"],["2208.15000000","0.92120000"],["2208.17000000","0.10470000"],["2208.18000000","0.00460000"],["2208.21000000","0.24510000"],["2208.22000000","1.15580000"],["2208.25000000","13.23490000"],["2208.26000000","40.13010000"],["2208.27000000","0.00230000"],["2208.28000000","0.00000000"],["2208.29000000","0.00000000"],["2208.30000000","0.00000000"],["2208.38000000","0.57260000"],["2208.40000000","10.11690000"],["2208.41000000","30.59150000"],["2208.45000000","1.35850000"],["2208.46000000","16.75370000"],["2208.48000000","5.16720000"],["2208.51000000","1.39520000"],["2208.57000000","15.88370000"],["2208.61000000","0.40600000"],["2208.62000000","0.00460000"],["2208.63000000","0.33400000"],["2208.94000000","11.25650000"],["2209.07000000","11.94100000"],["2209.16000000","1.40050000"],["2209.28000000","1.11150000"],["2209.41000000","0.00000000"],["2209.51000000","0.21410000"],["2209.94000000","0.12400000"],["2211.39000000","0.00000000"],["2211.42000000","0.08000000"],["2212.61000000","45.28800000"],["2212.71000000","8.37950000"],["2212.93000000","110.63450000"],["2213.30000000","2.96320000"],["2215.48000000","67.92850000"],["2216.45000000","0.13700000"],["2242.00000000","10.10000000"]]}
{"type":"depthUpdate","symbol":"ETHUSDT","event_time_ms":1775758317415,"first_update_id":74488290522,"final_update_id":74488290614,"bids":[["2208.02000000","0.05600000"],["2208.00000000","0.01950000"],["2207.91000000","0.02890000"],["2207.79000000","0.06040000"],["2207.78000000","0.00000000"],["2207.77000000","0.00230000"],["2207.75000000","0.07600000"],["2207.74000000","4.38170000"],["2207.73000000","0.00700000"],["2207.72000000","0.00470000"],["2207.71000000","0.00240000"],["2207.70000000","0.66120000"],["2207.69000000","0.00460000"],["2207.68000000","0.00300000"],["2207.67000000","0.00230000"],["2207.61000000","9.56340000"],["2207.60000000","0.00300000"],["2207.52000000","0.23670000"],["2207.45000000","1.18680000"],["2207.39000000","0.00930000"],["2207.38000000","39.06810000"],["2207.16000000","0.03000000"],["2207.10000000","1.20000000"],["2206.35000000","0.03000000"],["2206.26000000","25.41020000"],["2205.28000000","0.05230000"],["2200.81000000","0.00460000"],["2200.70000000","0.03470000"],["1987.24000000","0.04320000"],["1987.22000000","0.27940000"],["1324.00000000","0.94370000"]],"asks":[["2208.03000000","19.44630000"],["2208.05000000","0.01430000"],["2208.06000000","0.03470000"],["2208.10000000","1.34190000"],["2208.17000000","0.10230000"],["2208.18000000","0.02100000"],["2208.21000000","0.00000000"],["2208.24000000","0.03760000"],["2208.32000000","0.22940000"],["2208.36000000","17.62300000"],["2208.37000000","0.10300000"],["2208.55000000","9.53120000"],["2210.39000000","21.80640000"],["2210.74000000","2.00610000"],["2212.93000000","109.67410000"]]}
{"type":"depthUpdate","symbol":"ETHUSDT","event_time_ms":1775758317515,"first_update_id":74488290615,"final_update_id":74488290651,"bids":[["2207.75000000","0.07600000"],["2207.74000000","0.00230000"],["2207.72000000","0.00230000"],["2207.70000000","2.89060000"],["2207.65000000","0.00240000"],["2207.64000000","1.23630000"],["2207.63000000","0.04240000"],["2207.62000000","13.01300000"],["2207.56000000","0.54020000"],["2207.45000000","2.52180000"],["2207.43000000","1.37780000"],["2207.34000000","0.03000000"],["2206.98000000","16.37700000"],["2206.63000000","0.00690000"],["2205.55000000","0.04950000"],["2200.81000000","0.00000000"],["2200.01000000","0.00000000"],["2199.67000000","0.71230000"],["2029.24000000","0.00550000"],["1987.22000000","0.27940000"],["1332.86000000","0.05520000"],["1332.57000000","0.00460000"],["1331.57000000","0.08880000"],["1331.37000000","0.00000000"],["1331.29000000","0.00000000"],["1331.12000000","0.00920000"],["1330.53000000","0.00000000"],["1329.52000000","0.00000000"],["1328.78000000","0.00000000"],["1328.57000000","0.00000000"]],"asks":[["2208.06000000","0.03700000"]]}
{"type":"depthUpdate","symbol":"ETHUSDT","event_time_ms":1775758317715,"first_update_id":74488290680,"final_update_id":74488290702,"bids":[["2207.79000000","0.06280000"],["2207.78000000","4.23160000"],["2207.72000000","0.00470000"],["2207.71000000","0.00240000"],["2207.70000000","10.90550000"],["2207.66000000","0.11560000"],["2207.65000000","0.00000000"],["2207.64000000","0.00230000"],["2207.45000000","1.18680000"],["2207.37000000","16.30600000"],["2207.30000000","0.16610000"],["2206.63000000","0.00230000"],["2200.82000000","0.21100000"],["2200.71000000","0.21930000"],["1987.22000000","0.29070000"]],"asks":[["2208.57000000","15.93320000"],["2209.00000000","16.75200000"]]}
{"type":"depthUpdate","symbol":"ETHUSDT","event_time_ms":1775758317815,"first_update_id":74488290703,"final_update_id":74488290739,"bids":[["2207.80000000","0.63540000"],["2207.72000000","0.00230000"],["2207.70000000","0.04080000"],["2207.63000000","21.36640000"],["2207.62000000","0.07120000"],["2207.61000000","0.03460000"],["2207.48000000","1.11160000"],["2207.43000000","1.37780000"],["2207.41000000","0.03480000"],["2207.40000000","1.09780000"],["2207.33000000","0.60740000"],["2207.11000000","0.00000000"],["2207.09000000","0.00000000"],["2207.07000000","0.21600000"],["2206.67000000","0.11320000"],["2203.96000000","0.00510000"],["2200.71000000","0.21470000"],["2199.67000000","0.00320000"],["2019.45000000","0.00980000"],["1987.22000000","0.27660000"]],"asks":[["2208.24000000","21.36400000"],["2208.26000000","18.80370000"],["2208.35000000","1.49940000"],["2208.40000000","9.54600000"],["2208.85000000","0.05620000"],["2208.88000000","0.00300000"],["2211.23000000","6.27310000"],["2212.89000000","38.64920000"]]}
{"type":"depthUpdate","symbol":"ETHUSDT","event_time_ms":1775758317915,"first_update_id":74488290740,"final_update_id":74488290845,"bids":[["2208.02000000","0.04290000"],["2207.81000000","0.00940000"],["2207.80000000","0.06460000"],["2207.79000000","0.06510000"],["2207.78000000","0.00240000"],["2207.77000000","0.00230000"],["2207.72000000","0.00000000"],["2207.71000000","0.00000000"],["2207.67000000","0.00470000"],["2207.66000000","1.75160000"],["2207.64000000","0.00470000"],["2207.63000000","0.04000000"],["2207.62000000","9.13020000"],["2207.57000000","0.00460000"],["2207.55000000","0.92250000"],["2207.48000000","0.00850000"],["2207.43000000","0.53060000"],["2207.40000000","11.84750000"],["2207.39000000","34.26470000"],["2207.38000000","9.57410000"],["2207.37000000","0.00510000"],["2207.35000000","0.35250000"],["2207.32000000","0.00000000"],["2207.27000000","0.30490000"],["2207.20000000","0.00530000"],["2207.19000000","16.30090000"],["2207.10000000","1.24540000"],["2206.98000000","16.34700000"],["2206.36000000","0.00000000"],["2206.29000000","1.13400000"],["2206.19000000","9.52880000"],["2206.14000000","0.60000000"],["2206.07000000","0.02260000"],["2206.04000000","11.01690000"],["2206.00000000","17.35880000"],["2205.97000000","0.01130000"],["2205.76000000","5.23760000"],["2205.68000000","1.19170000"],["2203.88000000","0.00890000"],["2203.46000000","0.17970000"],["2203.21000000","0.13730000"],["2202.85000000","0.97490000"],["2202.63000000","0.97030000"],["2202.53000000","0.05670000"],["2202.37000000","1.01490000"],["2198.47000000","0.00000000"],["2197.33000000","0.72150000"],["1987.22000000","0.26820000"]],"asks":[["2208.03000000","21.35330000"],["2208.09000000","0.56640000"],["2208.15000000","7.36440000"],["2208.23000000","1.72100000"],["2208.25000000","6.27720000"],["2208.35000000","1.76940000"],["2208.37000000","0.40000000"],["2208.68000000","16.30090000"],["2208.69000000","12.97290000"],["2208.80000000","18.62190000"],["2208.96000000","0.03530000"],["2209.06000000","0.00000000"],["2209.12000000","0.05250000"],["2210.06000000","16.30320000"],["2210.33000000","6.55880000"],["2212.94000000","0.96040000"],["2213.16000000","0.00650000"],["2220.36000000","0.00000000"]]}
{"type":"depthUpdate","symbol":"ETHUSDT","event_time_ms":1775758318015,"first_update_id":74488290846,"final_update_id":74488291275,"bids":[["2208.02000000","0.00000000"],["2208.01000000","0.00000000"],["2208.00000000","0.00000000"],["2207.99000000","0.00000000"],["2207.98000000","0.00000000"],["2207.97000000","0.00000000"],["2207.96000000","0.00000000"],["2207.95000000","0.00000000"],["2207.94000000","0.00000000"],["2207.93000000","0.00000000"],["2207.92000000","0.00000000"],["2207.91000000","0.00000000"],["2207.90000000","0.00000000"],["2207.89000000","0.00000000"],["2207.88000000","0.00000000"],["2207.87000000","0.00000000"],["2207.86000000","0.00000000"],["2207.85000000","6.93690000"],["2207.84000000","0.01250000"],["2207.83000000","0.00470000"],["2207.82000000","0.00480000"],["2207.81000000","0.00940000"],["2207.80000000","0.06700000"],["2207.79000000","0.06510000"],["2207.78000000","0.00240000"],["2207.77000000","0.00470000"],["2207.76000000","0.00540000"],["2207.75000000","0.07370000"],["2207.73000000","0.00240000"],["2207.68000000","9.06170000"],["2207.67000000","2.53880000"],["2207.64000000","0.00230000"],["2207.63000000","0.04240000"],["2207.62000000","0.07120000"],["2207.61000000","1.18120000"],["2207.57000000","0.00700000"],["2207.56000000","0.54260000"],["2207.55000000","2.06910000"],["2207.53000000","0.02740000"],["2207.52000000","0.03830000"],["2207.51000000","0.00700000"],["2207.50000000","0.10370000"],["2207.48000000","1.34360000"],["2207.46000000","0.00000000"],["2207.45000000","2.10740000"],["2207.44000000","0.11860000"],["2207.43000000","0.51030000"],["2207.42000000","20.71390000"],["2207.41000000","16.31550000"],["2207.40000000","12.07390000"],["2207.39000000","17.70570000"],["2207.33000000","0.60970000"],["2207.25000000","1.84230000"],["2207.23000000","9.92480000"],["2207.18000000","18.56490000"],["2207.13000000","0.00000000"],["2207.11000000","0.02250000"],["2207.10000000","1.26800000"],["2207.07000000","0.03480000"],["2207.01000000","0.21430000"],["2206.96000000","0.34680000"],["2206.86000000","0.61260000"],["2206.82000000","16.30940000"],["2206.74000000","11.82380000"],["2206.48000000","16.07050000"],["2206.38000000","0.00920000"],["2205.94000000","2.48120000"],["2205.71000000","2.47500000"],["2205.68000000","0.92170000"],["2205.50000000","5.08640000"],["2205.49000000","6.87420000"],["2204.54000000","1.34990000"],["2203.61000000","16.30090000"],["2203.51000000","0.19000000"],["2201.93000000","1.39360000"],["2200.75000000","0.00460000"],["2200.64000000","0.00460000"],["2199.04000000","0.02790000"],["2198.05000000","0.02280000"],["2197.83000000","0.02280000"],["2197.61000000","0.02280000"],["1987.22000000","0.12820000"],["1987.07000000","0.00560000"]],"asks":[["2207.86000000","33.95490000"],["2207.87000000","0.00240000"],["2207.88000000","3.07280000"],["2207.89000000","0.00230000"],["2207.90000000","0.00000000"],["2207.91000000","0.00000000"],["2207.92000000","0.00750000"],["2207.93000000","0.00000000"],["2207.94000000","0.00000000"],["2207.95000000","0.00000000"],["2207.96000000","0.00000000"],["2207.97000000","0.03000000"],["2207.98000000","0.00240000"],["2207.99000000","0.00000000"],["2208.00000000","0.00000000"],["2208.01000000","0.00000000"],["2208.02000000","3.85570000"],["2208.03000000","1.22000000"],["2208.05000000","0.01430000"],["2208.06000000","0.04160000"],["2208.08000000","0.00300000"],["2208.09000000","0.57120000"],["2208.10000000","0.00690000"],["2208.11000000","0.12500000"],["2208.14000000","0.01210000"],["2208.15000000","7.36200000"],["2208.16000000","0.02210000"],["2208.17000000","0.10460000"],["2208.18000000","0.00230000"],["2208.19000000","0.04750000"],["2208.20000000","0.02270000"],["2208.22000000","0.01390000"],["2208.23000000","0.00460000"],["2208.24000000","21.36630000"],["2208.25000000","6.28180000"],["2208.26000000","18.23890000"],["2208.31000000","0.68760000"],["2208.33000000","0.14560000"],["2208.35000000","1.81240000"],["2208.37000000","0.35700000"],["2208.38000000","0.00580000"],["2208.39000000","3.85570000"],["2208.40000000","9.54120000"],["2208.42000000","0.05960000"],["2208.48000000","5.16720000"],["2208.53000000","0.00000000"],["2208.56000000","13.72890000"],["2208.59000000","0.00000000"],["2208.60000000","0.08100000"],["2208.61000000","0.40370000"],["2208.70000000","13.70540000"],["2208.73000000","0.63200000"],["2208.75000000","0.59710000"],["2208.85000000","0.10140000"],["2209.02000000","15.90290000"],["2209.03000000","11.79760000"],["2209.13000000","13.61540000"],["2209.32000000","11.79760000"],["2209.40000000","0.04950000"],["2209.57000000","0.29700000"],["2210.16000000","8.10100000"],["2210.30000000","0.00000000"],["2210.41000000","63.28560000"],["2211.61000000","0.02710000"],["2211.82000000","0.00000000"],["2211.96000000","15.11250000"],["2212.56000000","0.00910000"],["2212.98000000","0.00000000"],["2213.03000000","0.00670000"],["2213.26000000","9.01620000"],["2213.35000000","0.00000000"],["2213.40000000","0.00230000"],["2214.52000000","0.00280000"],["2214.59000000","0.00000000"],["2214.67000000","0.00000000"],["2218.88000000","0.00000000"],["2708.03000000","0.00000000"]]}
{"type":"depthUpdate","symbol":"ETHUSDT","event_time_ms":1775758318115,"first_update_id":74488291276,"final_update_id":74488291371,"bids":[["2207.85000000","6.93550000"],["2207.84000000","0.01490000"],["2207.80000000","0.00700000"],["2207.75000000","0.07600000"],["2207.73000000","0.00480000"],["2207.72000000","0.57680000"],["2207.70000000","0.04320000"],["2207.69000000","2.79870000"],["2207.68000000","0.00300000"],["2207.67000000","0.00470000"],["2207.66000000","0.11560000"],["2207.63000000","0.04240000"],["2207.62000000","0.07120000"],["2207.61000000","0.03690000"],["2207.55000000","0.92480000"],["2207.30000000","0.06610000"],["2207.21000000","0.10000000"],["2207.18000000","18.62490000"],["2207.10000000","0.46800000"],["2207.01000000","0.03310000"],["2206.97000000","2.30840000"],["2206.96000000","1.02520000"],["2206.89000000","0.84970000"],["2206.30000000","7.23340000"],["2206.14000000","0.20000000"],["2206.07000000","0.42260000"],["2202.20000000","0.02930000"],["2201.54000000","0.03440000"],["2200.64000000","0.00000000"],["2197.39000000","0.22570000"],["2197.17000000","0.02850000"],["2196.95000000","0.03980000"],["2196.73000000","0.03220000"],["2196.51000000","0.02280000"],["2196.29000000","0.02280000"],["2196.07000000","0.02680000"],["2189.94000000","0.25500000"],["2145.29000000","0.01400000"],["2145.15000000","0.23610000"],["2007.70000000","2.00610000"],["1987.07000000","0.02240000"]],"asks":[["2207.86000000","35.87690000"],["2207.87000000","0.00480000"],["2207.88000000","1.53240000"],["2207.89000000","0.00470000"],["2207.92000000","0.00990000"],["2207.97000000","0.03240000"],["2207.98000000","0.00480000"],["2208.02000000","3.85810000"],["2208.03000000","1.10800000"],["2208.05000000","0.01190000"],["2208.06000000","0.03690000"],["2208.09000000","0.56880000"],["2208.10000000","0.00000000"],["2208.11000000","0.12260000"],["2208.13000000","0.00000000"],["2208.14000000","0.00970000"],["2208.22000000","0.03750000"],["2208.51000000","1.39290000"],["2208.53000000","0.06000000"],["2208.61000000","0.10670000"],["2208.82000000","0.00800000"],["2209.67000000","0.04950000"],["2254.99000000","0.00600000"]]}
{"type":"depthUpdate","symbol":"ETHUSDT","event_time_ms":1775758318215,"first_update_id":74488291372,"final_update_id":74488291443,"bids":[["2207.81000000","0.01180000"],["2207.71000000","0.00240000"],["2207.70000000","0.04080000"],["2207.69000000","0.00460000"],["2207.62000000","0.04750000"],["2207.56000000","1.47740000"],["2207.55000000","2.01130000"],["2207.52000000","1.66830000"],["2207.45000000","2.37740000"],["2207.44000000","0.38860000"],["2207.43000000","1.05030000"],["2207.42000000","20.98390000"],["2207.41000000","17.44950000"],["2207.34000000","0.30000000"],["2207.24000000","0.06930000"],["2205.93000000","0.27000000"],["2205.81000000","0.33820000"],["2205.76000000","6.04760000"],["2205.75000000","0.27000000"],["2205.74000000","1.13400000"],["2198.61000000","0.00000000"],["2197.73000000","0.52470000"],["2195.85000000","0.02670000"],["2195.63000000","0.02880000"],["2195.41000000","0.02530000"],["2195.19000000","0.02280000"],["2194.97000000","0.02280000"],["2189.97000000","0.11300000"],["2189.94000000","0.14110000"],["1987.07000000","0.03930000"]],"asks":[["2207.86000000","34.10920000"],["2207.94000000","0.04530000"],["2208.05000000","0.00950000"],["2208.22000000","0.01390000"],["2208.23000000","1.08340000"],["2208.28000000","0.67500000"],["2208.30000000","0.27000000"],["2208.31000000","1.25460000"],["2208.35000000","2.24440000"],["2208.37000000","0.68100000"],["2208.38000000","0.62680000"],["2208.39000000","4.12570000"],["2208.52000000","0.00250000"],["2208.66000000","0.00000000"],["2208.69000000","12.70290000"],["2208.75000000","0.27310000"],["2209.14000000","0.03000000"],["2209.17000000","14.99950000"],["2209.28000000","1.10050000"],["2209.56000000","0.00000000"],["2209.95000000","0.04940000"],["2254.99000000","0.14900000"]]}
{"type":"depthUpdate","symbol":"ETHUSDT","event_time_ms":1775758318315,"first_update_id":74488291444,"final_update_id":74488291589,"bids":[["2207.85000000","6.94250000"],["2207.72000000","0.00000000"],["2207.71000000","0.00000000"],["2207.70000000","0.03800000"],["2207.69000000","9.06330000"],["2207.61000000","1.16920000"],["2207.58000000","14.33980000"],["2207.57000000","9.53580000"],["2207.56000000","11.80240000"],["2207.55000000","0.92480000"],["2207.54000000","0.00230000"],["2207.53000000","17.72380000"],["2207.52000000","0.03830000"],["2207.48000000","0.00850000"],["2207.46000000","16.30090000"],["2207.45000000","0.99640000"],["2207.41000000","1.14860000"],["2207.31000000","1.76710000"],["2207.28000000","0.42220000"],["2207.27000000","0.00490000"],["2207.23000000","33.51250000"],["2207.17000000","4.08380000"],["2207.15000000","11.95810000"],["2207.13000000","0.74600000"],["2207.10000000","0.06800000"],["2206.99000000","9.12970000"],["2206.97000000","2.12140000"],["2206.88000000","0.31610000"],["2206.32000000","0.00300000"],["2205.84000000","0.00000000"],["2205.77000000","0.30310000"],["2205.75000000","0.00000000"],["2205.69000000","9.52880000"],["2205.68000000","0.00000000"],["2205.56000000","13.61720000"],["2205.45000000","12.73790000"],["2205.31000000","7.17860000"],["2205.17000000","1.29140000"],["2204.87000000","0.00000000"],["2204.54000000","0.00000000"],["2202.94000000","0.96570000"],["2202.93000000","0.00000000"],["2202.73000000","0.00000000"],["2202.66000000","0.98770000"],["2202.43000000","0.96050000"],["2202.42000000","0.00000000"],["2202.37000000","0.05450000"],["2202.16000000","0.96050000"],["2199.85000000","0.00000000"],["2189.89000000","0.00000000"],["2145.15000000","0.11980000"],["1987.07000000","0.05050000"]],"asks":[["2207.86000000","34.10920000"],["2207.87000000","0.00240000"],["2207.92000000","0.00990000"],["2207.94000000","0.00240000"],["2208.04000000","0.00920000"],["2208.10000000","0.00000000"],["2208.11000000","0.12260000"],["2208.14000000","1.15400000"],["2208.23000000","26.49360000"],["2208.24000000","0.03990000"],["2208.25000000","6.28180000"],["2208.26000000","0.54250000"],["2208.35000000","2.51440000"],["2208.37000000","1.77850000"],["2208.41000000","29.49400000"],["2208.44000000","1.50460000"],["2208.45000000","18.61980000"],["2208.46000000","0.45280000"],["2208.55000000","21.48420000"],["2208.59000000","0.03000000"],["2208.67000000","5.20810000"],["2208.69000000","12.13590000"],["2208.73000000","0.00000000"],["2208.75000000","0.00000000"],["2208.97000000","9.50440000"],["2208.98000000","13.61260000"],["2209.03000000","11.82280000"],["2209.19000000","9.52880000"],["2209.76000000","0.00300000"],["2209.94000000","0.12630000"],["2209.95000000","0.05170000"],["2209.96000000","0.00230000"],["2210.05000000","11.79760000"],["2210.06000000","16.30090000"],["2210.07000000","9.52880000"],["2210.19000000","0.04020000"],["2210.22000000","0.04940000"],["2210.37000000","0.27000000"],["2211.23000000","4.92790000"],["2213.02000000","1.68910000"]]}
{"type":"depthUpdate","symbol":"ETHUSDT","event_time_ms":1775758318415,"first_update_id":74488291590,"final_update_id":74488291644,"bids":[["2207.76000000","0.00780000"],["2207.75000000","0.07370000"],["2207.73000000","0.00240000"],["2207.71000000","0.67100000"],["2207.70000000","0.04040000"],["2207.62000000","0.04750000"],["2207.61000000","0.03690000"],["2207.57000000","0.00700000"],["2207.56000000","0.00480000"],["2207.55000000","0.92710000"],["2207.54000000","39.02510000"],["2207.53000000","0.02740000"],["2207.50000000","0.10600000"],["2207.42000000","4.36510000"],["2207.41000000","2.77960000"],["2207.03000000","0.04530000"],["2206.88000000","0.04610000"],["2205.77000000","0.03310000"],["2205.76000000","5.77760000"],["2205.74000000","0.86400000"],["2199.62000000","5.01600000"],["1995.95000000","0.00270000"],["1987.07000000","0.05600000"]],"asks":[["2207.86000000","34.08510000"],["2208.01000000","0.00000000"],["2208.08000000","0.55390000"],["2208.11000000","0.12020000"],["2208.14000000","0.54550000"],["2208.23000000","25.41480000"],["2208.25000000","0.00970000"],["2208.26000000","0.00670000"],["2208.30000000","1.60490000"],["2208.31000000","1.52770000"],["2208.50000000","0.00000000"],["2208.74000000","0.00000000"],["2208.76000000","0.00460000"],["2208.77000000","0.00000000"],["2208.84000000","29.91350000"],["2209.71000000","6.15610000"],["2210.06000000","16.57090000"],["2210.35000000","0.00000000"],["2211.74000000","0.02500000"],["2213.02000000","0.72870000"],["2517.54000000","0.00000000"]]}
{"type":"depthUpdate","symbol":"ETHUSDT","event_time_ms":1775758318515,"first_update_id":74488291645,"final_update_id":74488291921,"bids":[["2207.85000000","19.76650000"],["2207.84000000","0.00770000"],["2207.82000000","0.00240000"],["2207.81000000","0.00940000"],["2207.79000000","0.09510000"],["2207.78000000","0.00240000"],["2207.76000000","0.23420000"],["2207.75000000","0.07600000"],["2207.73000000","1.14660000"],["2207.72000000","4.65990000"],["2207.71000000","12.88900000"],["2207.70000000","41.02310000"],["2207.69000000","0.00460000"],["2207.67000000","0.52450000"],["2207.63000000","0.04000000"],["2207.61000000","0.03690000"],["2207.58000000","13.19550000"],["2207.57000000","0.00460000"],["2207.56000000","0.00910000"],["2207.55000000","0.92710000"],["2207.53000000","0.02500000"],["2207.51000000","0.00460000"],["2207.50000000","0.10830000"],["2207.47000000","19.47410000"],["2207.45000000","1.09640000"],["2207.42000000","0.27230000"],["2207.40000000","12.52590000"],["2207.39000000","17.70810000"],["2207.35000000","0.80550000"],["2207.29000000","1.36370000"],["2207.26000000","1.10940000"],["2207.24000000","0.04530000"],["2207.22000000","26.12580000"],["2207.21000000","0.00000000"],["2207.10000000","0.02260000"],["2207.09000000","0.02260000"],["2207.04000000","0.01150000"],["2206.96000000","0.00760000"],["2206.93000000","15.13210000"],["2206.88000000","0.00300000"],["2206.80000000","0.38390000"],["2206.62000000","2.88920000"],["2206.44000000","0.00670000"],["2206.35000000","0.00000000"],["2206.05000000","12.22890000"],["2205.97000000","0.00460000"],["2205.74000000","0.59400000"],["2205.60000000","17.19600000"],["2204.66000000","17.30040000"],["2202.23000000","1.18880000"],["1987.07000000","0.07280000"]],"asks":[["2207.86000000","8.80080000"],["2207.87000000","0.00480000"],["2207.88000000","0.00470000"],["2207.92000000","0.00750000"],["2207.97000000","0.00240000"],["2207.98000000","0.00480000"],["2208.01000000","0.00240000"],["2208.02000000","0.00710000"],["2208.03000000","0.02170000"],["2208.06000000","0.03690000"],["2208.07000000","0.00240000"],["2208.08000000","0.00540000"],["2208.09000000","0.00240000"],["2208.10000000","0.00480000"],["2208.11000000","0.12490000"],["2208.12000000","4.09280000"],["2208.13000000","0.00240000"],["2208.14000000","0.01210000"],["2208.15000000","0.03000000"],["2208.16000000","0.05980000"],["2208.17000000","0.00460000"],["2208.22000000","1.15820000"],["2208.23000000","0.02840000"],["2208.24000000","0.04220000"],["2208.28000000","1.81930000"],["2208.30000000","0.97600000"],["2208.31000000","0.57620000"],["2208.32000000","0.00300000"],["2208.34000000","1.33500000"],["2208.35000000","1.55320000"],["2208.36000000","6.94980000"],["2208.37000000","0.68100000"],["2208.40000000","25.42260000"],["2208.41000000","0.22640000"],["2208.42000000","0.05730000"],["2208.43000000","0.00230000"],["2208.44000000","0.00230000"],["2208.45000000","0.00000000"],["2208.47000000","5.70910000"],["2208.48000000","5.26490000"],["2208.54000000","15.88140000"],["2208.55000000","0.00240000"],["2208.56000000","1.47470000"],["2208.57000000","0.05180000"],["2208.61000000","0.00670000"],["2208.67000000","25.82970000"],["2208.68000000","0.00000000"],["2208.70000000","14.66590000"],["2208.71000000","15.88140000"],["2208.74000000","0.80000000"],["2208.75000000","0.95150000"],["2208.83000000","16.30320000"],["2208.84000000","14.31260000"],["2208.91000000","0.00510000"],["2208.92000000","0.10000000"],["2209.02000000","10.25860000"],["2209.03000000","11.79760000"],["2209.07000000","0.00000000"],["2209.21000000","11.94000000"],["2209.28000000","0.00300000"],["2209.33000000","0.02240000"],["2209.50000000","0.97950000"],["2209.55000000","31.06790000"],["2209.63000000","0.00670000"],["2210.67000000","12.03070000"],["2210.81000000","1.99250000"],["2211.19000000","4.46750000"],["2211.40000000","0.00460000"],["2211.96000000","4.90560000"],["2211.99000000","9.50320000"],["2212.94000000","0.00000000"],["2214.55000000","0.00000000"]]}
{"type":"depthUpdate","symbol":"ETHUSDT","event_time_ms":1775758318615,"first_update_id":74488291922,"final_update_id":74488291966,"bids":[["2207.83000000","0.01410000"],["2207.79000000","0.03930000"],["2207.74000000","0.02660000"],["2207.71000000","29.18990000"],["2207.61000000","0.09270000"],["2207.33000000","1.34510000"],["2207.29000000","1.63370000"],["2207.18000000","18.64740000"],["2207.10000000","0.04510000"],["2206.20000000","1.93740000"],["2206.00000000","17.36180000"],["2205.76000000","5.23760000"],["2205.74000000","0.00000000"],["2205.67000000","0.38340000"],["1987.07000000","0.08400000"]],"asks":[["2207.86000000","8.91480000"],["2207.88000000","0.01190000"],["2207.98000000","0.00480000"],["2208.01000000","0.00480000"],["2208.03000000","0.01930000"],["2208.04000000","0.02790000"],["2208.05000000","0.00230000"],["2208.06000000","0.03920000"],["2208.09000000","0.00480000"],["2208.10000000","1.04270000"],["2208.11000000","1.35090000"],["2208.15000000","0.78940000"],["2208.16000000","1.23140000"],["2208.28000000","1.82160000"],["2208.35000000","2.65450000"],["2208.42000000","0.05500000"],["2208.43000000","0.00000000"],["2208.59000000","1.53700000"],["2208.85000000","12.05440000"],["2209.72000000","18.82410000"],["2210.48000000","1.09750000"]]}
{"type":"depthUpdate","symbol":"ETHUSDT","event_time_ms":1775758319215,"first_update_id":74488292064,"final_update_id":74488292098,"bids":[["2207.83000000","0.01410000"],["2207.74000000","0.02660000"],["2207.69000000","1.63760000"],["2207.61000000","0.09270000"],["2207.41000000","1.14860000"],["2204.89000000","29.40590000"],["2198.37000000","0.52450000"],["2197.73000000","0.00000000"],["1987.07000000","0.14560000"],["1324.00000000","0.94370000"]],"asks":[["2207.88000000","0.01190000"],["2207.89000000","0.00710000"],["2208.03000000","0.03800000"],["2208.04000000","0.05450000"],["2208.09000000","0.00480000"],["2208.10000000","1.04270000"],["2208.11000000","1.35090000"],["2208.15000000","0.83240000"],["2208.16000000","1.18840000"],["2208.92000000","0.77500000"],["2208.95000000","0.84630000"],["2208.99000000","0.43200000"],["2209.01000000","4.40780000"],["2209.02000000","10.87960000"],["2209.03000000","12.06760000"],["2210.37000000","0.62100000"]]}
{"type":"depthUpdate","symbol":"ETHUSDT","event_time_ms":1775758319415,"first_update_id":74488292121,"final_update_id":74488292134,"bids":[["2207.56000000","0.00910000"],["2206.67000000","0.00000000"],["2204.03000000","2.47730000"],["2100.00000000","1229.45550000"],["1987.07000000","0.15690000"]],"asks":[["2208.09000000","0.00480000"],["2208.10000000","1.04270000"],["2208.11000000","1.35090000"],["2210.27000000","0.35330000"],["2210.29000000","0.54000000"]]}
{"type":"depthUpdate","symbol":"ETHUSDT","event_time_ms":1775758319615,"first_update_id":74488292146,"final_update_id":74488292161,"bids":[["2203.63000000","23.69900000"],["1987.07000000","0.15120000"]],"asks":[["2207.86000000","6.92140000"],["2208.14000000","0.01450000"],["2209.46000000","0.34240000"],["2210.27000000","0.00230000"],["2210.29000000","0.00000000"],["2210.34000000","0.00280000"],["2210.36000000","0.05180000"],["2210.37000000","0.00000000"],["2210.38000000","0.00000000"],["2210.61000000","0.00460000"]]}
{"type":"depthUpdate","symbol":"ETHUSDT","event_time_ms":1775758319815,"first_update_id":74488292185,"final_update_id":74488292205,"bids":[["2207.83000000","0.01410000"],["2207.74000000","0.02660000"],["2207.61000000","0.13790000"],["2207.24000000","0.00000000"],["2204.29000000","0.00230000"],["1987.07000000","0.16590000"],["1937.19000000","0.03510000"]],"asks":[["2207.87000000","0.00720000"],["2207.88000000","0.01190000"],["2208.03000000","0.02840000"],["2208.15000000","0.83480000"],["2208.19000000","0.04750000"],["2213.94000000","0.00000000"],["2214.53000000","0.00460000"],["2214.64000000","0.09880000"]]}
{"type":"depthUpdate","symbol":"ETHUSDT","event_time_ms":1775758320015,"first_update_id":74488292226,"final_update_id":74488292249,"bids":[["2207.46000000","17.65940000"],["2207.31000000","0.40860000"],["2107.85000000","0.00000000"],["1987.07000000","0.17720000"],["1324.35000000","0.75960000"],["1324.01000000","0.00680000"],["1323.50000000","0.00000000"],["1323.48000000","0.00920000"],["1323.30000000","0.00460000"],["1322.76000000","0.00000000"],["1319.75000000","0.00460000"],["1318.35000000","0.00460000"],["1318.05000000","0.01360000"],["1317.01000000","0.00000000"]],"asks":[["2208.27000000","4.47530000"],["2208.30000000","0.50600000"],["2208.36000000","22.19750000"],["2208.37000000","0.68100000"],["2208.41000000","0.00000000"],["2209.82000000","0.00000000"],["2517.54000000","0.13850000"]]}
{"type":"depthUpdate","symbol":"ETHUSDT","event_time_ms":1775758320115,"first_update_id":74488292250,"final_update_id":74488292267,"bids":[["2207.75000000","0.03890000"],["2207.40000000","12.86510000"],["2207.36000000","1.13310000"],["2207.33000000","0.00900000"],["2207.31000000","0.37150000"],["2206.96000000","0.00760000"],["2206.87000000","0.83700000"],["2206.43000000","20.53840000"],["2205.99000000","11.79760000"],["2203.81000000","1.36770000"],["1987.07000000","0.17150000"],["1925.43000000","0.00270000"]],"asks":[["2208.22000000","1.15820000"],["2208.30000000","0.27960000"],["2208.32000000","0.22940000"],["2208.63000000","0.29700000"],["2209.94000000","0.08930000"],["2211.70000000","29.49630000"],["2212.14000000","0.00000000"],["2212.57000000","0.00930000"],["2213.01000000","0.00000000"],["2213.45000000","3.89890000"],["2213.49000000","0.00460000"],["2213.89000000","1.80860000"],["2214.33000000","0.00000000"],["2214.77000000","0.12290000"]]}
{"type":"depthUpdate","symbol":"ETHUSDT","event_time_ms":1775758320215,"first_update_id":74488292268,"final_update_id":74488292290,"bids":[["2207.73000000","0.00230000"],["2206.87000000","0.84310000"],["2201.72000000","0.00620000"],["1987.07000000","0.16030000"]],"asks":[["2208.11000000","1.88670000"],["2208.26000000","0.05200000"],["2208.40000000","15.89150000"],["2208.93000000","14.72610000"],["2208.97000000","0.00000000"],["2216.38000000","2.47500000"],["2217.37000000","2.47770000"]]}
{"type":"depthUpdate","symbol":"ETHUSDT","event_time_ms":1775758320415,"first_update_id":74488292324,"final_update_id":74488292376,"bids":[["2207.85000000","27.71030000"],["2207.83000000","0.01410000"],["2207.74000000","0.02660000"],["2207.73000000","0.00230000"],["2207.72000000","4.65990000"],["2207.67000000","0.52450000"],["2207.64000000","0.22870000"],["2207.62000000","0.10330000"],["2207.61000000","0.08210000"],["2207.46000000","16.30090000"],["2207.43000000","2.23020000"],["2207.40000000","12.18670000"],["2206.96000000","0.68600000"],["2200.76000000","0.70910000"],["1987.07000000","0.17160000"],["1987.06000000","0.05230000"],["1913.68000000","0.01000000"]],"asks":[["2207.86000000","12.94240000"],["2207.88000000","0.01190000"],["2208.03000000","0.02840000"],["2208.10000000","1.04270000"],["2208.11000000","1.35090000"],["2208.14000000","0.01210000"],["2208.15000000","0.83240000"],["2208.16000000","0.04410000"],["2208.19000000","0.04750000"],["2208.20000000","1.17920000"],["2208.21000000","0.00240000"],["2208.26000000","16.46920000"],["2208.27000000","2.05310000"],["2208.29000000","0.22640000"],["2208.32000000","0.00300000"],["2208.35000000","0.97440000"],["2208.50000000","1.35840000"],["2208.56000000","0.11630000"],["2208.61000000","0.20670000"],["2208.84000000","14.11260000"],["2210.35000000","0.00000000"],["2428.65000000","0.00230000"]]}
{"type":"depthUpdate","symbol":"ETHUSDT","event_time_ms":1775758320515,"first_update_id":74488292377,"final_update_id":74488292393,"bids":[["1987.07000000","0.17160000"],["1987.06000000","0.04950000"]],"asks":[["2208.09000000","0.00240000"],["2208.10000000","0.00480000"],["2208.14000000","0.01450000"],["2208.25000000","2.28240000"],["2208.26000000","4.67160000"],["2208.27000000","0.00230000"],["2208.28000000","0.67960000"],["2208.34000000","0.00000000"],["2428.65000000","0.00000000"]]}
{"type":"depthUpdate","symbol":"ETHUSDT","event_time_ms":1775758320715,"first_update_id":74488292406,"final_update_id":74488292415,"bids":[["2206.73000000","13.61490000"],["1987.07000000","0.16030000"],["1901.93000000","0.13740000"]],"asks":[["2208.25000000","1.46180000"],["2208.26000000","0.05200000"],["2208.35000000","2.84520000"],["2209.07000000","0.00000000"]]}
{"type":"depthUpdate","symbol":"ETHUSDT","event_time_ms":1775758320815,"first_update_id":74488292416,"final_update_id":74488292427,"bids":[["2207.85000000","27.69870000"],["1987.07000000","0.16590000"]],"asks":[["2207.86000000","6.92140000"],["2208.14000000","0.01210000"],["2208.28000000","1.82390000"],["2208.29000000","0.00000000"],["2208.32000000","0.22940000"],["2208.50000000","0.00000000"],["2208.53000000","15.03110000"]]}
{"type":"depthUpdate","symbol":"ETHUSDT","event_time_ms":1775758321015,"first_update_id":74488292436,"final_update_id":74488293172,"bids":[["2207.85000000","0.00000000"],["2207.84000000","0.00000000"],["2207.83000000","0.00000000"],["2207.82000000","0.00000000"],["2207.81000000","0.00000000"],["2207.80000000","0.00000000"],["2207.79000000","0.00000000"],["2207.78000000","0.00000000"],["2207.77000000","0.00000000"],["2207.76000000","0.00000000"],["2207.75000000","0.00000000"],["2207.74000000","0.00000000"],["2207.73000000","0.00000000"],["2207.72000000","0.00000000"],["2207.71000000","0.00000000"],["2207.70000000","0.00000000"],["2207.69000000","0.00000000"],["2207.68000000","0.00000000"],["2207.67000000","0.04080000"],["2207.66000000","0.12510000"],["2207.65000000","0.00480000"],["2207.64000000","0.55940000"],["2207.63000000","0.04020000"],["2207.62000000","0.06050000"],["2207.61000000","0.03930000"],["2207.60000000","0.00540000"],["2207.59000000","0.52910000"],["2207.58000000","3.05130000"],["2207.57000000","0.00000000"],["2207.56000000","0.00480000"],["2207.55000000","10.45590000"],["2207.54000000","0.00230000"],["2207.51000000","0.00700000"],["2207.50000000","0.10600000"],["2207.49000000","0.00000000"],["2207.48000000","0.01090000"],["2207.47000000","0.00000000"],["2207.46000000","0.00000000"],["2207.45000000","0.31750000"],["2207.44000000","0.41280000"],["2207.43000000","0.87180000"],["2207.41000000","1.14860000"],["2207.40000000","51.29210000"],["2207.39000000","4.09780000"],["2207.38000000","0.00000000"],["2207.37000000","0.00740000"],["2207.36000000","1.13540000"],["2207.35000000","0.78530000"],["2207.34000000","0.30230000"],["2207.33000000","0.00230000"],["2207.32000000","0.04530000"],["2207.31000000","0.41910000"],["2207.30000000","0.06840000"],["2207.29000000","1.63600000"],["2207.28000000","4.10040000"],["2207.26000000","0.01420000"],["2207.25000000","1.84460000"],["2207.24000000","55.32370000"],["2207.23000000","0.00000000"],["2207.22000000","0.11790000"],["2207.21000000","0.10000000"],["2207.20000000","0.23170000"],["2207.19000000","0.00000000"],["2207.18000000","0.08250000"],["2207.17000000","0.00000000"],["2207.16000000","0.03000000"],["2207.13000000","0.04600000"],["2207.11000000","0.12250000"],["2207.10000000","0.43960000"],["2207.09000000","0.02260000"],["2207.08000000","29.51670000"],["2207.06000000","0.60000000"],["2207.05000000","0.00000000"],["2207.04000000","1.37030000"],["2207.02000000","9.53110000"],["2207.00000000","11.96250000"],["2206.96000000","0.00760000"],["2206.95000000","0.09910000"],["2206.94000000","29.53070000"],["2206.93000000","0.00510000"],["2206.92000000","0.00000000"],["2206.91000000","0.08930000"],["2206.90000000","0.00000000"],["2206.85000000","0.94890000"],["2206.84000000","1.45170000"],["2206.83000000","8.30180000"],["2206.81000000","0.59750000"],["2206.79000000","4.08380000"],["2206.78000000","14.14160000"],["2206.73000000","13.61260000"],["2206.72000000","11.27080000"],["2206.71000000","0.03230000"],["2206.68000000","0.04530000"],["2206.44000000","0.03670000"],["2206.42000000","0.02270000"],["2206.36000000","0.04500000"],["2206.27000000","16.79700000"],["2206.26000000","25.44020000"],["2206.14000000","0.00000000"],["2206.07000000","0.62260000"],["2206.04000000","0.00000000"],["2206.00000000","17.36850000"],["2205.84000000","0.00300000"],["2205.77000000","0.30980000"],["2205.50000000","5.08980000"],["2205.46000000","15.72570000"],["2205.33000000","0.00230000"],["2205.08000000","11.03370000"],["2205.06000000","1.10030000"],["2204.95000000","0.00000000"],["2204.90000000","0.03000000"],["2204.89000000","0.00000000"],["2204.69000000","0.20000000"],["2204.57000000","1.04050000"],["2203.89000000","0.00000000"],["2203.62000000","28.37030000"],["2203.35000000","0.07130000"],["2203.16000000","0.00000000"],["2202.69000000","34.17490000"],["2202.24000000","9.02980000"],["2202.13000000","0.51720000"],["2201.71000000","0.91490000"],["2201.67000000","0.00230000"],["2201.65000000","0.14740000"],["2200.64000000","0.00460000"],["2200.53000000","1.01860000"],["2200.29000000","5.03870000"],["2197.62000000","0.00000000"],["2196.98000000","7.41600000"],["2196.70000000","0.00230000"],["2196.42000000","6.06850000"],["1997.26000000","0.01550000"],["1987.07000000","0.01470000"],["1707.67000000","0.00000000"],["1324.00000000","0.94370000"]],"asks":[["2207.68000000","41.22110000"],["2207.69000000","6.52440000"],["2207.70000000","0.00700000"],["2207.71000000","0.00000000"],["2207.72000000","0.00000000"],["2207.73000000","4.09280000"],["2207.74000000","0.00000000"],["2207.75000000","0.00000000"],["2207.76000000","0.00000000"],["2207.77000000","0.00000000"],["2207.78000000","0.00000000"],["2207.79000000","0.00000000"],["2207.80000000","0.00000000"],["2207.81000000","0.00510000"],["2207.82000000","0.00000000"],["2207.83000000","0.00000000"],["2207.84000000","0.00300000"],["2207.85000000","0.22640000"],["2207.86000000","0.68050000"],["2207.87000000","0.00240000"],["2207.88000000","0.04420000"],["2207.89000000","1.93730000"],["2207.90000000","0.00230000"],["2207.92000000","0.01220000"],["2207.94000000","0.00580000"],["2207.97000000","0.03470000"],["2207.98000000","0.02510000"],["2208.01000000","0.04520000"],["2208.02000000","0.02100000"],["2208.03000000","0.00970000"],["2208.04000000","0.01590000"],["2208.05000000","0.00460000"],["2208.07000000","0.00000000"],["2208.08000000","0.00300000"],["2208.10000000","0.00000000"],["2208.11000000","0.12020000"],["2208.12000000","0.00000000"],["2208.13000000","0.00000000"],["2208.14000000","1.36850000"],["2208.15000000","1.56780000"],["2208.16000000","0.00640000"],["2208.17000000","0.04760000"],["2208.20000000","1.28100000"],["2208.22000000","0.01390000"],["2208.23000000","0.02840000"],["2208.24000000","39.06500000"],["2208.26000000","0.00670000"],["2208.28000000","0.67730000"],["2208.30000000","0.27000000"],["2208.31000000","0.57620000"],["2208.32000000","0.00300000"],["2208.34000000","0.00000000"],["2208.35000000","2.16770000"],["2208.38000000","23.81340000"],["2208.48000000","5.16490000"],["2208.50000000","1.09750000"],["2208.51000000","17.69380000"],["2208.52000000","9.62180000"],["2208.53000000","13.67260000"],["2208.56000000","0.16150000"],["2208.59000000","1.63700000"],["2208.67000000","25.82970000"],["2208.72000000","0.68250000"],["2208.75000000","0.00000000"],["2208.79000000","0.00000000"],["2208.81000000","0.00000000"],["2208.85000000","12.00920000"],["2208.90000000","9.52880000"],["2208.91000000","0.00280000"],["2208.92000000","0.67500000"],["2209.00000000","17.07200000"],["2209.07000000","1.87940000"],["2209.23000000","0.00460000"],["2209.24000000","0.34250000"],["2209.32000000","11.79760000"],["2209.35000000","0.00230000"],["2209.39000000","0.09980000"],["2209.41000000","0.00000000"],["2209.50000000","0.27000000"],["2209.54000000","23.92560000"],["2209.63000000","0.00000000"],["2209.80000000","0.32400000"],["2209.82000000","0.89220000"],["2209.92000000","17.57780000"],["2210.16000000","6.89360000"],["2210.40000000","16.30800000"],["2210.47000000","0.98090000"],["2210.50000000","10.51550000"],["2210.67000000","10.63020000"],["2210.83000000","0.00000000"],["2210.88000000","0.05460000"],["2210.89000000","0.00000000"],["2211.03000000","0.00000000"],["2211.35000000","25.50910000"],["2211.66000000","1.02270000"],["2211.70000000","15.88370000"],["2211.74000000","0.02270000"],["2211.76000000","0.00460000"],["2212.34000000","0.00230000"],["2212.55000000","0.03000000"],["2212.70000000","0.97440000"],["2212.86000000","0.00000000"],["2212.92000000","1.11300000"],["2213.03000000","0.00670000"],["2213.40000000","0.00230000"],["2215.37000000","0.10000000"],["2215.45000000","0.00000000"],["2217.15000000","0.10000000"],["2219.74000000","10.54550000"],["2221.01000000","0.02160000"],["2227.16000000","0.10000000"],["2240.48000000","39.64690000"],["2240.86000000","0.00000000"]]}
{"type":"depthUpdate","symbol":"ETHUSDT","event_time_ms":1775758321115,"first_update_id":74488293173,"final_update_id":74488293596,"bids":[["2207.67000000","4.06290000"],["2207.66000000","0.12510000"],["2207.65000000","0.00950000"],["2207.64000000","0.00470000"],["2207.62000000","0.06050000"],["2207.61000000","0.00930000"],["2207.60000000","0.01020000"],["2207.59000000","0.01180000"],["2207.58000000","0.00470000"],["2207.56000000","0.00720000"],["2207.55000000","0.92710000"],["2207.54000000","0.00470000"],["2207.53000000","0.58130000"],["2207.52000000","0.00830000"],["2207.50000000","0.10370000"],["2207.48000000","0.01230000"],["2207.46000000","0.00000000"],["2207.45000000","0.04750000"],["2207.44000000","0.11860000"],["2207.43000000","0.03480000"],["2207.42000000","0.00470000"],["2207.41000000","0.01460000"],["2207.40000000","0.05220000"],["2207.39000000","0.01400000"],["2207.37000000","0.00980000"],["2207.36000000","0.04230000"],["2207.35000000","0.00230000"],["2207.34000000","0.03230000"],["2207.32000000","0.00000000"],["2207.31000000","0.07030000"],["2207.29000000","0.00690000"],["2207.28000000","0.00760000"],["2207.26000000","0.01420000"],["2207.25000000","1.84460000"],["2207.24000000","9.06290000"],["2207.21000000","0.02390000"],["2207.20000000","0.00530000"],["2207.18000000","0.06000000"],["2207.13000000","0.00000000"],["2207.12000000","0.23610000"],["2207.11000000","0.02250000"],["2207.10000000","0.41710000"],["2207.09000000","39.04540000"],["2207.08000000","0.02270000"],["2207.06000000","0.45300000"],["2207.04000000","0.05680000"],["2207.03000000","16.34620000"],["2207.02000000","0.00230000"],["2207.01000000","0.03310000"],["2207.00000000","17.47460000"],["2206.99000000","0.11330000"],["2206.98000000","0.04610000"],["2206.97000000","0.67900000"],["2206.96000000","0.10760000"],["2206.95000000","0.09910000"],["2206.94000000","0.00670000"],["2206.93000000","0.00510000"],["2206.91000000","0.00000000"],["2206.89000000","0.09570000"],["2206.86000000","0.71260000"],["2206.85000000","2.30770000"],["2206.84000000","0.90110000"],["2206.83000000","9.70180000"],["2206.80000000","10.32580000"],["2206.74000000","13.96770000"],["2206.72000000","0.00300000"],["2206.71000000","0.03510000"],["2206.65000000","0.00670000"],["2206.62000000","2.89380000"],["2206.49000000","0.00000000"],["2206.47000000","0.00000000"],["2206.27000000","16.70770000"],["2206.23000000","0.28960000"],["2206.21000000","0.55060000"],["2206.12000000","2.74480000"],["2206.08000000","0.03300000"],["2206.05000000","11.83680000"],["2205.99000000","11.82760000"],["2205.87000000","0.00000000"],["2205.81000000","0.42320000"],["2205.62000000","0.00000000"],["2205.60000000","16.30090000"],["2205.57000000","0.98290000"],["2205.27000000","0.00000000"],["2205.26000000","0.00300000"],["2205.00000000","6.25990000"],["2204.92000000","13.66810000"],["2204.66000000","2.50080000"],["2204.61000000","13.61260000"],["2203.73000000","12.05050000"],["2203.63000000","23.70130000"],["2203.09000000","0.02810000"],["2203.04000000","28.38630000"],["2202.85000000","0.01450000"],["2202.64000000","0.22140000"],["2202.63000000","0.00990000"],["2202.62000000","0.58680000"],["2202.59000000","45.30100000"],["2202.23000000","0.22830000"],["2202.06000000","0.97150000"],["2201.79000000","0.99430000"],["2201.75000000","1.42520000"],["2201.31000000","0.00460000"],["2200.68000000","0.18890000"],["2200.54000000","0.00500000"],["2200.53000000","1.01400000"],["2199.78000000","0.17310000"],["2199.62000000","5.00770000"],["2199.50000000","105.15580000"],["2199.34000000","0.00700000"],["2198.85000000","0.95600000"],["2197.32000000","3.09370000"],["2192.33000000","0.00000000"],["2169.66000000","0.00000000"],["1997.26000000","0.00000000"],["1986.91000000","0.01120000"]],"asks":[["2207.68000000","45.19720000"],["2207.69000000","5.09470000"],["2207.70000000","0.03980000"],["2207.72000000","0.00000000"],["2207.73000000","4.09980000"],["2207.79000000","0.03000000"],["2207.81000000","0.00750000"],["2207.84000000","0.00540000"],["2207.85000000","0.22880000"],["2207.86000000","0.03270000"],["2207.88000000","0.60450000"],["2207.89000000","0.00470000"],["2207.92000000","0.00980000"],["2207.93000000","13.61260000"],["2207.94000000","11.80100000"],["2207.95000000","9.52880000"],["2207.96000000","5.70220000"],["2207.97000000","1.39110000"],["2207.98000000","0.70050000"],["2208.00000000","0.55480000"],["2208.01000000","1.57410000"],["2208.02000000","0.08100000"],["2208.03000000","1.10720000"],["2208.04000000","0.01360000"],["2208.06000000","0.03690000"],["2208.07000000","0.00460000"],["2208.08000000","1.26500000"],["2208.09000000","13.61730000"],["2208.10000000","25.86300000"],["2208.11000000","0.12250000"],["2208.13000000","0.00000000"],["2208.14000000","0.00970000"],["2208.15000000","13.38200000"],["2208.18000000","1.17460000"],["2208.19000000","0.04750000"],["2208.22000000","0.01160000"],["2208.23000000","0.00460000"],["2208.24000000","39.06270000"],["2208.27000000","0.00000000"],["2208.28000000","0.67730000"],["2208.29000000","0.80000000"],["2208.33000000","0.87330000"],["2208.34000000","16.30090000"],["2208.36000000","12.66410000"],["2208.37000000","0.62100000"],["2208.39000000","4.12340000"],["2208.40000000","15.88920000"],["2208.42000000","0.83120000"],["2208.46000000","0.00000000"],["2208.47000000","18.20290000"],["2208.51000000","16.33550000"],["2208.53000000","14.35160000"],["2208.59000000","1.53700000"],["2208.61000000","0.00670000"],["2208.70000000","26.17750000"],["2208.74000000","0.00000000"],["2208.84000000","13.61260000"],["2208.94000000","0.27000000"],["2209.00000000","16.73870000"],["2209.04000000","10.21420000"],["2209.05000000","0.00000000"],["2209.09000000","0.24590000"],["2209.14000000","0.00000000"],["2209.29000000","0.00000000"],["2209.51000000","0.00000000"],["2209.54000000","21.16390000"],["2209.55000000","16.30090000"],["2210.02000000","0.00000000"],["2211.11000000","1.34090000"],["2211.25000000","0.42880000"],["2211.49000000","0.03700000"],["2211.55000000","15.88140000"],["2211.85000000","0.00000000"],["2212.04000000","43.66770000"],["2212.10000000","0.05990000"],["2212.80000000","0.51720000"],["2212.99000000","1.19470000"],["2214.35000000","0.00000000"],["2214.41000000","0.24870000"],["2214.53000000","0.00000000"],["2215.28000000","0.00250000"]]}
{"type":"depthUpdate","symbol":"ETHUSDT","event_time_ms":1775758321215,"first_update_id":74488293597,"final_update_id":74488293694,"bids":[["2207.60000000","0.00780000"],["2207.53000000","1.14350000"],["2207.43000000","0.00480000"],["2207.42000000","0.00230000"],["2207.37000000","0.00740000"],["2207.36000000","1.18900000"],["2207.34000000","3.47510000"],["2207.33000000","0.00000000"],["2207.31000000","9.13060000"],["2207.30000000","1.21510000"],["2207.26000000","1.16090000"],["2207.25000000","8.19010000"],["2207.24000000","0.00230000"],["2207.22000000","0.12020000"],["2207.19000000","1.63200000"],["2207.18000000","1.20670000"],["2207.16000000","1.17670000"],["2207.15000000","11.96040000"],["2207.04000000","0.32680000"],["2207.00000000","17.45210000"],["2206.92000000","0.27000000"],["2206.73000000","13.61260000"],["2206.51000000","0.00000000"],["2206.09000000","0.00000000"],["2205.92000000","9.57750000"],["2205.90000000","0.03000000"],["2205.76000000","6.04760000"],["2205.75000000","0.27000000"],["2205.74000000","1.13400000"],["2205.71000000","2.69130000"],["2205.38000000","0.29000000"],["2205.26000000","0.27300000"],["2204.92000000","11.66660000"],["2204.79000000","28.46390000"],["2204.19000000","14.79100000"],["2203.81000000","0.00000000"],["2203.56000000","0.00000000"],["2200.64000000","0.00000000"],["2198.54000000","2.31070000"],["2188.27000000","4.33330000"],["1986.91000000","0.02800000"],["1873.72000000","0.00570000"]],"asks":[["2207.68000000","45.28780000"],["2207.69000000","5.09240000"],["2207.73000000","4.09980000"],["2207.76000000","0.14240000"],["2207.79000000","0.03240000"],["2207.88000000","0.60440000"],["2207.91000000","4.10640000"],["2207.92000000","13.75670000"],["2207.93000000","13.61490000"],["2207.94000000","11.80330000"],["2207.95000000","9.53110000"],["2207.96000000","4.08840000"],["2208.01000000","0.04520000"],["2208.04000000","0.01590000"],["2208.08000000","16.30390000"],["2208.11000000","0.12020000"],["2208.20000000","0.70160000"],["2208.22000000","0.00930000"],["2208.31000000","0.57390000"],["2208.59000000","1.50700000"],["2209.08000000","14.75830000"],["2209.63000000","0.03000000"],["2209.65000000","0.04710000"],["2210.36000000","0.00340000"],["2211.50000000","0.00000000"],["2211.54000000","0.00000000"],["2212.71000000","3.44000000"],["2212.72000000","0.00340000"],["2212.79000000","0.00000000"],["2212.99000000","0.22230000"]]}
